Workbook
Name Attended: #REF!

Sheet Pal Group
D1: January | L1: February | S1: March | AD1: April | AK1: May | AS1: June | BC1: July | BJ1: August | BR1: September | CC1: October | CK1: November | CR1: December
B3: Members | C3: Contact | D3: Week 1 | E3: Week 2 | F3: Week 3 | G3: Week 4 | H3: Week 5 | L3: Week 6 | M3: Week 7 | N3: Week 8 | O3: Week 9 | S3: Week 10 | T3: Week 11 | U3: Week 12 | V3: Week 13 | AD3: Week 14 | AE3: Week 15 | AF3: Week 16 | AG3: Week 17 | AK3: Week 18 | AL3: Week 19 | AM3: Week 20 | AN3: Week 21 | AO3: Week 22 | AS3: Week 23 | AT3: Week 24 | AU3: Week 25 | AV3: Week 26 | BC3: Week 27 | BD3: Week 28 | BE3: Week 29 | BF3: Week 30 | BJ3: Week 31 | BK3: Week 32 | BL3: Week 33 | BM3: Week 34 | BN3: Week 35 | BR3: Week 36 | BS3: Week 37 | BT3: Week 38 | BU3: Week 39 | CC3: Week 40 | CD3: Week 41 | CE3: Week 42 | CF3: Week 43 | CG3: Week 44 | CK3: Week 45 | CL3: Week 46 | CM3: Week 47 | CN3: Week 48 | CR3: Week 49 | CS3: Week 50 | CT3: Week 51 | CU3: Week 52
B4: Leaders | I4: Present | J4: Absent | K4: PA | P4: Present | Q4: Absent | R4: PA | W4: Present | X4: Absent | Y4: PA | Z4: TOTAL PA | AA4: Qtr Att | AB4: Qtr % | AC4: Comments | AH4: Present | AI4: Absent | AJ4: PA | AP4: Present | AQ4: Absent | AR4: PA | AW4: Present | AX4: Absent | AY4: PA | AZ4: TOTAL PA | BA4: Qtr Att | BB4: Qtr % | BG4: Present | BH4: Absent | BI4: PA | BO4: Present | BP4: Absent | BQ4: PA | BV4: Present | BW4: Absent | BX4: PA | BY4: TOTAL PA | BZ4: Qtr Att | CA4: Qtr % | CB4: Comments | CH4: Present | CI4: Absent | CJ4: PA | CO4: Present | CP4: Absent | CQ4: PA | CV4: Present | CW4: Absent | CX4: PA | CY4: TOTAL ATT | CZ4: Qtr Att | DA4: Qtr % | DB4: Comments
B5: Min Sylvester Sesay | D5: PR | E5: PR | F5: PR | I5: =COUNTIF(D5:H5,"PR") -> 3 | J5: =COUNTIF(D5:H5,"AB") -> 0 | K5: =I5+J5 -> 3 | P5: =COUNTIF(L5:O5,"PR") -> 0 | Q5: =COUNTIF(L5:O5,"AB") -> 0 | R5: =P5+Q5 -> 0 | W5: =COUNTIF(S5:V5,"PR") -> 0 | X5: =COUNTIF(S5:V5,"AB") -> 0 | Y5: =W5+X5 -> 0 | Z5: =K5+R5+Y5 -> 3 | AA5: =SUM(I5,P5,W5) -> 3 | AB5: =AA5/Z5*100 -> 100 | AH5: =COUNTIF(AD5:AG5,"PR") -> 0 | AI5: =COUNTIF(AD5:AG5,"AB") -> 0 | AJ5: =AH5+AI5 -> 0 | AP5: =COUNTIF(AK5:AO5,"PR") -> 0 | AQ5: =COUNTIF(AK5:AO5,"AB") -> 0 | AR5: =AP5+AQ5 -> 0 | AW5: =COUNTIF(AS5:AV5,"PR") -> 0 | AX5: =COUNTIF(AS5:AV5,"AB") -> 0 | AY5: =AW5+AX5 -> 0 | AZ5: =AJ5+AR5+AY5 -> 0 | BA5: =SUM(AH5,AP5,AW5) -> 0 | BB5: =BA5/AZ5*100 -> #DIV/0! | BG5: =COUNTIF(BC5:BF5,"PR") -> 0 | BH5: =COUNTIF(BC5:BF5,"AB") -> 0 | BI5: =BG5+BH5 -> 0 | BO5: =COUNTIF(BJ5:BN5,"PR") -> 0 | BP5: =COUNTIF(BJ5:BN5,"AB") -> 0 | BQ5: =BO5+BP5 -> 0 | BV5: =COUNTIF(BR5:BU5,"PR") -> 0 | BW5: =COUNTIF(BR5:BU5,"AB") -> 0 | BX5: =BV5+BW5 -> 0 | BY5: =BI5+BQ5+BX5 -> 0 | BZ5: =SUM(BG5,BO5,BV5) -> 0 | CA5: =BZ5/BY5*100 -> #DIV/0! | CH5: =COUNTIF(CC5:CG5,"PR") -> 0 | CI5: =COUNTIF(CC5:CG5,"AB") -> 0 | CJ5: =CH5+CI5 -> 0 | CO5: =COUNTIF(CK5:CN5,"PR") -> 0 | CP5: =COUNTIF(CK5:CN5,"AB") -> 0 | CQ5: =CO5+CP5 -> 0 | CV5: =COUNTIF(CR5:CU5,"PR") -> 0 | CW5: =COUNTIF(CR5:CU5,"AB") -> 0 | CX5: =CV5+CW5 -> 0 | CY5: =CH5+CO5+CV5 -> 0 | CZ5: =SUM(CF5,#REF!,CT5) -> #REF! | DA5: =CZ5/CY5*100 -> #REF!
B6: Min Soriba | D6: PR | E6: PR | F6: AB | I6: =COUNTIF(D6:H6,"PR") -> 2 | J6: =COUNTIF(D6:H6,"AB") -> 1 | K6: =I6+J6 -> 3 | P6: =COUNTIF(L6:O6,"PR") -> 0 | Q6: =COUNTIF(L6:O6,"AB") -> 0 | R6: =P6+Q6 -> 0 | W6: =COUNTIF(S6:V6,"PR") -> 0 | X6: =COUNTIF(S6:V6,"AB") -> 0 | Y6: =W6+X6 -> 0 | Z6: =K6+R6+Y6 -> 3 | AA6: =SUM(I6,P6,W6) -> 2 | AB6: =AA6/Z6*100 -> 66.666667 | AH6: =COUNTIF(AD6:AG6,"PR") -> 0 | AI6: =COUNTIF(AD6:AG6,"AB") -> 0 | AJ6: =AH6+AI6 -> 0 | AP6: =COUNTIF(AK6:AO6,"PR") -> 0 | AQ6: =COUNTIF(AK6:AO6,"AB") -> 0 | AR6: =AP6+AQ6 -> 0 | AW6: =COUNTIF(AS6:AV6,"PR") -> 0 | AX6: =COUNTIF(AS6:AV6,"AB") -> 0 | AY6: =AW6+AX6 -> 0 | AZ6: =AJ6+AR6+AY6 -> 0 | BA6: =SUM(AH6,AP6,AW6) -> 0 | BB6: =BA6/AZ6*100 -> #DIV/0! | BG6: =COUNTIF(BC6:BF6,"PR") -> 0 | BH6: =COUNTIF(BC6:BF6,"AB") -> 0 | BI6: =BG6+BH6 -> 0 | BO6: =COUNTIF(BJ6:BN6,"PR") -> 0 | BP6: =COUNTIF(BJ6:BN6,"AB") -> 0 | BQ6: =BO6+BP6 -> 0 | BV6: =COUNTIF(BR6:BU6,"PR") -> 0 | BW6: =COUNTIF(BR6:BU6,"AB") -> 0 | BX6: =BV6+BW6 -> 0 | BY6: =BI6+BQ6+BX6 -> 0 | BZ6: =SUM(BG6,BO6,BV6) -> 0 | CA6: =BZ6/BY6*100 -> #DIV/0! | CH6: =COUNTIF(CC6:CG6,"PR") -> 0 | CI6: =COUNTIF(CC6:CG6,"AB") -> 0 | CJ6: =CH6+CI6 -> 0 | CO6: =COUNTIF(CK6:CN6,"PR") -> 0 | CP6: =COUNTIF(CK6:CN6,"AB") -> 0 | CQ6: =CO6+CP6 -> 0 | CV6: =COUNTIF(CR6:CU6,"PR") -> 0 | CW6: =COUNTIF(CR6:CU6,"AB") -> 0 | CX6: =CV6+CW6 -> 0 | CY6: =CH6+CO6+CV6 -> 0 | CZ6: =SUM(CF6,#REF!,CT6) -> #REF! | DA6: =CZ6/CY6*100 -> #REF!
B7: Divine Emmanuel Sahr Dauda | D7: PR | E7: PR | F7: PR | I7: =COUNTIF(D7:H7,"PR") -> 3 | J7: =COUNTIF(D7:H7,"AB") -> 0 | K7: =I7+J7 -> 3 | P7: =COUNTIF(L7:O7,"PR") -> 0 | Q7: =COUNTIF(L7:O7,"AB") -> 0 | R7: =P7+Q7 -> 0 | W7: =COUNTIF(S7:V7,"PR") -> 0 | X7: =COUNTIF(S7:V7,"AB") -> 0 | Y7: =W7+X7 -> 0 | Z7: =K7+R7+Y7 -> 3 | AA7: =SUM(I7,P7,W7) -> 3 | AB7: =AA7/Z7*100 -> 100 | AH7: =COUNTIF(AD7:AG7,"PR") -> 0 | AI7: =COUNTIF(AD7:AG7,"AB") -> 0 | AJ7: =AH7+AI7 -> 0 | AP7: =COUNTIF(AK7:AO7,"PR") -> 0 | AQ7: =COUNTIF(AK7:AO7,"AB") -> 0 | AR7: =AP7+AQ7 -> 0 | AW7: =COUNTIF(AS7:AV7,"PR") -> 0 | AX7: =COUNTIF(AS7:AV7,"AB") -> 0 | AY7: =AW7+AX7 -> 0 | AZ7: =AJ7+AR7+AY7 -> 0 | BA7: =SUM(AH7,AP7,AW7) -> 0 | BB7: =BA7/AZ7*100 -> #DIV/0! | BG7: =COUNTIF(BC7:BF7,"PR") -> 0 | BH7: =COUNTIF(BC7:BF7,"AB") -> 0 | BI7: =BG7+BH7 -> 0 | BO7: =COUNTIF(BJ7:BN7,"PR") -> 0 | BP7: =COUNTIF(BJ7:BN7,"AB") -> 0 | BQ7: =BO7+BP7 -> 0 | BV7: =COUNTIF(BR7:BU7,"PR") -> 0 | BW7: =COUNTIF(BR7:BU7,"AB") -> 0 | BX7: =BV7+BW7 -> 0 | BY7: =BI7+BQ7+BX7 -> 0 | BZ7: =SUM(BG7,BO7,BV7) -> 0 | CA7: =BZ7/BY7*100 -> #DIV/0! | CH7: =COUNTIF(CC7:CG7,"PR") -> 0 | CI7: =COUNTIF(CC7:CG7,"AB") -> 0 | CJ7: =CH7+CI7 -> 0 | CO7: =COUNTIF(CK7:CN7,"PR") -> 0 | CP7: =COUNTIF(CK7:CN7,"AB") -> 0 | CQ7: =CO7+CP7 -> 0 | CV7: =COUNTIF(CR7:CU7,"PR") -> 0 | CW7: =COUNTIF(CR7:CU7,"AB") -> 0 | CX7: =CV7+CW7 -> 0 | CY7: =CH7+CO7+CV7 -> 0 | CZ7: =SUM(CF7,#REF!,CT7) -> #REF! | DA7: =CZ7/CY7*100 -> #REF!
I8: =COUNTIF(D8:H8,"PR") -> 0 | J8: =COUNTIF(D8:H8,"AB") -> 0 | K8: =I8+J8 -> 0 | P8: =COUNTIF(L8:O8,"PR") -> 0 | Q8: =COUNTIF(L8:O8,"AB") -> 0 | R8: =P8+Q8 -> 0 | W8: =COUNTIF(S8:V8,"PR") -> 0 | X8: =COUNTIF(S8:V8,"AB") -> 0 | Y8: =W8+X8 -> 0 | Z8: =K8+R8+Y8 -> 0 | AA8: =SUM(I8,P8,W8) -> 0 | AB8: =AA8/Z8*100 -> #DIV/0! | AH8: =COUNTIF(AD8:AG8,"PR") -> 0 | AI8: =COUNTIF(AD8:AG8,"AB") -> 0 | AJ8: =AH8+AI8 -> 0 | AP8: =COUNTIF(AK8:AO8,"PR") -> 0 | AQ8: =COUNTIF(AK8:AO8,"AB") -> 0 | AR8: =AP8+AQ8 -> 0 | AW8: =COUNTIF(AS8:AV8,"PR") -> 0 | AX8: =COUNTIF(AS8:AV8,"AB") -> 0 | AY8: =AW8+AX8 -> 0 | AZ8: =AJ8+AR8+AY8 -> 0 | BA8: =SUM(AH8,AP8,AW8) -> 0 | BB8: =BA8/AZ8*100 -> #DIV/0! | BG8: =COUNTIF(BC8:BF8,"PR") -> 0 | BH8: =COUNTIF(BC8:BF8,"AB") -> 0 | BI8: =BG8+BH8 -> 0 | BO8: =COUNTIF(BJ8:BN8,"PR") -> 0 | BP8: =COUNTIF(BJ8:BN8,"AB") -> 0 | BQ8: =BO8+BP8 -> 0 | BV8: =COUNTIF(BR8:BU8,"PR") -> 0 | BW8: =COUNTIF(BR8:BU8,"AB") -> 0 | BX8: =BV8+BW8 -> 0 | BY8: =BI8+BQ8+BX8 -> 0 | BZ8: =SUM(BG8,BO8,BV8) -> 0 | CA8: =BZ8/BY8*100 -> #DIV/0! | CH8: =COUNTIF(CC8:CG8,"PR") -> 0 | CI8: =COUNTIF(CC8:CG8,"AB") -> 0 | CJ8: =CH8+CI8 -> 0 | CO8: =COUNTIF(CK8:CN8,"PR") -> 0 | CP8: =COUNTIF(CK8:CN8,"AB") -> 0 | CQ8: =CO8+CP8 -> 0 | CV8: =COUNTIF(CR8:CU8,"PR") -> 0 | CW8: =COUNTIF(CR8:CU8,"AB") -> 0 | CX8: =CV8+CW8 -> 0 | CY8: =CH8+CO8+CV8 -> 0 | CZ8: =SUM(CF8,#REF!,CT8) -> #REF! | DA8: =CZ8/CY8*100 -> #REF!
I9: =COUNTIF(D9:H9,"PR") -> 0 | J9: =COUNTIF(D9:H9,"AB") -> 0 | K9: =I9+J9 -> 0 | P9: =COUNTIF(L9:O9,"PR") -> 0 | Q9: =COUNTIF(L9:O9,"AB") -> 0 | R9: =P9+Q9 -> 0 | W9: =COUNTIF(S9:V9,"PR") -> 0 | X9: =COUNTIF(S9:V9,"AB") -> 0 | Y9: =W9+X9 -> 0 | Z9: =K9+R9+Y9 -> 0 | AA9: =SUM(I9,P9,W9) -> 0 | AB9: =AA9/Z9*100 -> #DIV/0! | AH9: =COUNTIF(AD9:AG9,"PR") -> 0 | AI9: =COUNTIF(AD9:AG9,"AB") -> 0 | AJ9: =AH9+AI9 -> 0 | AP9: =COUNTIF(AK9:AO9,"PR") -> 0 | AQ9: =COUNTIF(AK9:AO9,"AB") -> 0 | AR9: =AP9+AQ9 -> 0 | AW9: =COUNTIF(AS9:AV9,"PR") -> 0 | AX9: =COUNTIF(AS9:AV9,"AB") -> 0 | AY9: =AW9+AX9 -> 0 | AZ9: =AJ9+AR9+AY9 -> 0 | BA9: =SUM(AH9,AP9,AW9) -> 0 | BB9: =BA9/AZ9*100 -> #DIV/0! | BG9: =COUNTIF(BC9:BF9,"PR") -> 0 | BH9: =COUNTIF(BC9:BF9,"AB") -> 0 | BI9: =BG9+BH9 -> 0 | BO9: =COUNTIF(BJ9:BN9,"PR") -> 0 | BP9: =COUNTIF(BJ9:BN9,"AB") -> 0 | BQ9: =BO9+BP9 -> 0 | BV9: =COUNTIF(BR9:BU9,"PR") -> 0 | BW9: =COUNTIF(BR9:BU9,"AB") -> 0 | BX9: =BV9+BW9 -> 0 | BY9: =BI9+BQ9+BX9 -> 0 | BZ9: =SUM(BG9,BO9,BV9) -> 0 | CA9: =BZ9/BY9*100 -> #DIV/0! | CH9: =COUNTIF(CC9:CG9,"PR") -> 0 | CI9: =COUNTIF(CC9:CG9,"AB") -> 0 | CJ9: =CH9+CI9 -> 0 | CO9: =COUNTIF(CK9:CN9,"PR") -> 0 | CP9: =COUNTIF(CK9:CN9,"AB") -> 0 | CQ9: =CO9+CP9 -> 0 | CV9: =COUNTIF(CR9:CU9,"PR") -> 0 | CW9: =COUNTIF(CR9:CU9,"AB") -> 0 | CX9: =CV9+CW9 -> 0 | CY9: =CH9+CO9+CV9 -> 0 | CZ9: =SUM(CF9,#REF!,CT9) -> #REF! | DA9: =CZ9/CY9*100 -> #REF!
I10: =COUNTIF(D10:H10,"PR") -> 0 | J10: =COUNTIF(D10:H10,"AB") -> 0 | K10: =I10+J10 -> 0 | P10: =COUNTIF(L10:O10,"PR") -> 0 | Q10: =COUNTIF(L10:O10,"AB") -> 0 | R10: =P10+Q10 -> 0 | W10: =COUNTIF(S10:V10,"PR") -> 0 | X10: =COUNTIF(S10:V10,"AB") -> 0 | Y10: =W10+X10 -> 0 | Z10: =K10+R10+Y10 -> 0 | AA10: =SUM(I10,P10,W10) -> 0 | AB10: =AA10/Z10*100 -> #DIV/0! | AH10: =COUNTIF(AD10:AG10,"PR") -> 0 | AI10: =COUNTIF(AD10:AG10,"AB") -> 0 | AJ10: =AH10+AI10 -> 0 | AP10: =COUNTIF(AK10:AO10,"PR") -> 0 | AQ10: =COUNTIF(AK10:AO10,"AB") -> 0 | AR10: =AP10+AQ10 -> 0 | AW10: =COUNTIF(AS10:AV10,"PR") -> 0 | AX10: =COUNTIF(AS10:AV10,"AB") -> 0 | AY10: =AW10+AX10 -> 0 | AZ10: =AJ10+AR10+AY10 -> 0 | BA10: =SUM(AH10,AP10,AW10) -> 0 | BB10: =BA10/AZ10*100 -> #DIV/0! | BG10: =COUNTIF(BC10:BF10,"PR") -> 0 | BH10: =COUNTIF(BC10:BF10,"AB") -> 0 | BI10: =BG10+BH10 -> 0 | BO10: =COUNTIF(BJ10:BN10,"PR") -> 0 | BP10: =COUNTIF(BJ10:BN10,"AB") -> 0 | BQ10: =BO10+BP10 -> 0 | BV10: =COUNTIF(BR10:BU10,"PR") -> 0 | BW10: =COUNTIF(BR10:BU10,"AB") -> 0 | BX10: =BV10+BW10 -> 0 | BY10: =BI10+BQ10+BX10 -> 0 | BZ10: =SUM(BG10,BO10,BV10) -> 0 | CA10: =BZ10/BY10*100 -> #DIV/0! | CH10: =COUNTIF(CC10:CG10,"PR") -> 0 | CI10: =COUNTIF(CC10:CG10,"AB") -> 0 | CJ10: =CH10+CI10 -> 0 | CO10: =COUNTIF(CK10:CN10,"PR") -> 0 | CP10: =COUNTIF(CK10:CN10,"AB") -> 0 | CQ10: =CO10+CP10 -> 0 | CV10: =COUNTIF(CR10:CU10,"PR") -> 0 | CW10: =COUNTIF(CR10:CU10,"AB") -> 0 | CX10: =CV10+CW10 -> 0 | CY10: =CH10+CO10+CV10 -> 0 | CZ10: =SUM(CF10,#REF!,CT10) -> #REF! | DA10: =CZ10/CY10*100 -> #REF!
I11: =COUNTIF(D11:H11,"PR") -> 0 | J11: =COUNTIF(D11:H11,"AB") -> 0 | K11: =I11+J11 -> 0 | P11: =COUNTIF(L11:O11,"PR") -> 0 | Q11: =COUNTIF(L11:O11,"AB") -> 0 | R11: =P11+Q11 -> 0 | W11: =COUNTIF(S11:V11,"PR") -> 0 | X11: =COUNTIF(S11:V11,"AB") -> 0 | Y11: =W11+X11 -> 0 | Z11: =K11+R11+Y11 -> 0 | AA11: =SUM(I11,P11,W11) -> 0 | AB11: =AA11/Z11*100 -> #DIV/0! | AH11: =COUNTIF(AD11:AG11,"PR") -> 0 | AI11: =COUNTIF(AD11:AG11,"AB") -> 0 | AJ11: =AH11+AI11 -> 0 | AP11: =COUNTIF(AK11:AO11,"PR") -> 0 | AQ11: =COUNTIF(AK11:AO11,"AB") -> 0 | AR11: =AP11+AQ11 -> 0 | AW11: =COUNTIF(AS11:AV11,"PR") -> 0 | AX11: =COUNTIF(AS11:AV11,"AB") -> 0 | AY11: =AW11+AX11 -> 0 | AZ11: =AJ11+AR11+AY11 -> 0 | BA11: =SUM(AH11,AP11,AW11) -> 0 | BB11: =BA11/AZ11*100 -> #DIV/0! | BG11: =COUNTIF(BC11:BF11,"PR") -> 0 | BH11: =COUNTIF(BC11:BF11,"AB") -> 0 | BI11: =BG11+BH11 -> 0 | BO11: =COUNTIF(BJ11:BN11,"PR") -> 0 | BP11: =COUNTIF(BJ11:BN11,"AB") -> 0 | BQ11: =BO11+BP11 -> 0 | BV11: =COUNTIF(BR11:BU11,"PR") -> 0 | BW11: =COUNTIF(BR11:BU11,"AB") -> 0 | BX11: =BV11+BW11 -> 0 | BY11: =BI11+BQ11+BX11 -> 0 | BZ11: =SUM(BG11,BO11,BV11) -> 0 | CA11: =BZ11/BY11*100 -> #DIV/0! | CH11: =COUNTIF(CC11:CG11,"PR") -> 0 | CI11: =COUNTIF(CC11:CG11,"AB") -> 0 | CJ11: =CH11+CI11 -> 0 | CO11: =COUNTIF(CK11:CN11,"PR") -> 0 | CP11: =COUNTIF(CK11:CN11,"AB") -> 0 | CQ11: =CO11+CP11 -> 0 | CV11: =COUNTIF(CR11:CU11,"PR") -> 0 | CW11: =COUNTIF(CR11:CU11,"AB") -> 0 | CX11: =CV11+CW11 -> 0 | CY11: =CH11+CO11+CV11 -> 0 | CZ11: =SUM(CF11,#REF!,CT11) -> #REF! | DA11: =CZ11/CY11*100 -> #REF!
I12: =COUNTIF(D12:H12,"PR") -> 0 | J12: =COUNTIF(D12:H12,"AB") -> 0 | K12: =I12+J12 -> 0 | P12: =COUNTIF(L12:O12,"PR") -> 0 | Q12: =COUNTIF(L12:O12,"AB") -> 0 | R12: =P12+Q12 -> 0 | W12: =COUNTIF(S12:V12,"PR") -> 0 | X12: =COUNTIF(S12:V12,"AB") -> 0 | Y12: =W12+X12 -> 0 | Z12: =K12+R12+Y12 -> 0 | AA12: =SUM(I12,P12,W12) -> 0 | AB12: =AA12/Z12*100 -> #DIV/0! | AH12: =COUNTIF(AD12:AG12,"PR") -> 0 | AI12: =COUNTIF(AD12:AG12,"AB") -> 0 | AJ12: =AH12+AI12 -> 0 | AP12: =COUNTIF(AK12:AO12,"PR") -> 0 | AQ12: =COUNTIF(AK12:AO12,"AB") -> 0 | AR12: =AP12+AQ12 -> 0 | AW12: =COUNTIF(AS12:AV12,"PR") -> 0 | AX12: =COUNTIF(AS12:AV12,"AB") -> 0 | AY12: =AW12+AX12 -> 0 | AZ12: =AJ12+AR12+AY12 -> 0 | BA12: =SUM(AH12,AP12,AW12) -> 0 | BB12: =BA12/AZ12*100 -> #DIV/0! | BG12: =COUNTIF(BC12:BF12,"PR") -> 0 | BH12: =COUNTIF(BC12:BF12,"AB") -> 0 | BI12: =BG12+BH12 -> 0 | BO12: =COUNTIF(BJ12:BN12,"PR") -> 0 | BP12: =COUNTIF(BJ12:BN12,"AB") -> 0 | BQ12: =BO12+BP12 -> 0 | BV12: =COUNTIF(BR12:BU12,"PR") -> 0 | BW12: =COUNTIF(BR12:BU12,"AB") -> 0 | BX12: =BV12+BW12 -> 0 | BY12: =BI12+BQ12+BX12 -> 0 | BZ12: =SUM(BG12,BO12,BV12) -> 0 | CA12: =BZ12/BY12*100 -> #DIV/0! | CH12: =COUNTIF(CC12:CG12,"PR") -> 0 | CI12: =COUNTIF(CC12:CG12,"AB") -> 0 | CJ12: =CH12+CI12 -> 0 | CO12: =COUNTIF(CK12:CN12,"PR") -> 0 | CP12: =COUNTIF(CK12:CN12,"AB") -> 0 | CQ12: =CO12+CP12 -> 0 | CV12: =COUNTIF(CR12:CU12,"PR") -> 0 | CW12: =COUNTIF(CR12:CU12,"AB") -> 0 | CX12: =CV12+CW12 -> 0 | CY12: =CH12+CO12+CV12 -> 0 | CZ12: =SUM(CF12,#REF!,CT12) -> #REF! | DA12: =CZ12/CY12*100 -> #REF!
I13: =SUM(I5:I12) -> 8 | K13: =SUM(K5:K12) -> 9 | P13: =SUM(P5:P12) -> 0 | R13: =SUM(R5:R12) -> 0 | W13: =SUM(W5:W12) -> 0 | Y13: =SUM(Y5:Y12) -> 0 | Z13: =SUM(Z5:Z12) -> 9 | AH13: =SUM(AH5:AH12) -> 0 | AJ13: =SUM(AJ5:AJ12) -> 0 | AP13: =SUM(AP5:AP12) -> 0 | AR13: =SUM(AR5:AR12) -> 0 | AW13: =SUM(AW5:AW12) -> 0 | AY13: =SUM(AY5:AY12) -> 0 | AZ13: =SUM(AZ5:AZ12) -> 0 | BA13: =SUM(AH13,AP13,AW13) -> 0 | BG13: =SUM(BG5:BG12) -> 0 | BI13: =SUM(BI5:BI12) -> 0 | BO13: =SUM(BO5:BO12) -> 0 | BQ13: =SUM(BQ5:BQ12) -> 0 | BV13: =SUM(BV5:BV12) -> 0 | BX13: =SUM(BX5:BX12) -> 0 | BY13: =SUM(BY5:BY12) -> 0 | CH13: =SUM(CH5:CH12) -> 0 | CJ13: =SUM(CJ5:CJ12) -> 0 | CO13: =SUM(CO5:CO12) -> 0 | CQ13: =SUM(CQ5:CQ12) -> 0 | CV13: =SUM(CV5:CV12) -> 0 | CX13: =SUM(CX5:CX12) -> 0 | CY13: =SUM(CY5:CY12) -> 0
B14: Intense
B15: Celina John | D15: PR | E15: PR | F15: AB | I15: =COUNTIF(D15:H15,"PR") -> 2 | J15: =COUNTIF(D15:H15,"AB") -> 1 | K15: =I15+J15 -> 3 | P15: =COUNTIF(L15:O15,"PR") -> 0 | Q15: =COUNTIF(L15:O15,"AB") -> 0 | R15: =P15+Q15 -> 0 | W15: =COUNTIF(S15:V15,"PR") -> 0 | X15: =COUNTIF(S15:V15,"AB") -> 0 | Y15: =W15+X15 -> 0 | Z15: =K15+R15+Y15 -> 3 | AA15: =SUM(I15,P15,W15) -> 2 | AB15: =AA15/Z15*100 -> 66.666667 | AH15: =COUNTIF(AD15:AG15,"PR") -> 0 | AI15: =COUNTIF(AD15:AG15,"AB") -> 0 | AJ15: =AH15+AI15 -> 0 | AP15: =COUNTIF(AK15:AO15,"PR") -> 0 | AQ15: =COUNTIF(AK15:AO15,"AB") -> 0 | AR15: =AP15+AQ15 -> 0 | AW15: =COUNTIF(AS15:AV15,"PR") -> 0 | AX15: =COUNTIF(AS15:AV15,"AB") -> 0 | AY15: =AW15+AX15 -> 0 | AZ15: =AJ15+AR15+AY15 -> 0 | BA15: =SUM(AH15,AP15,AW15) -> 0 | BB15: =BA15/AZ15*100 -> #DIV/0! | BG15: =COUNTIF(BC15:BF15,"PR") -> 0 | BH15: =COUNTIF(BC15:BF15,"AB") -> 0 | BI15: =BG15+BH15 -> 0 | BO15: =COUNTIF(BJ15:BN15,"PR") -> 0 | BP15: =COUNTIF(BJ15:BN15,"AB") -> 0 | BQ15: =BO15+BP15 -> 0 | BV15: =COUNTIF(BR15:BU15,"PR") -> 0 | BW15: =COUNTIF(BR15:BU15,"AB") -> 0 | BX15: =BV15+BW15 -> 0 | BY15: =BI15+BQ15+BX15 -> 0 | BZ15: =SUM(BG15,BO15,BV15) -> 0 | CA15: =BZ15/BY15*100 -> #DIV/0! | CH15: =COUNTIF(CC15:CG15,"PR") -> 0 | CI15: =COUNTIF(CC15:CG15,"AB") -> 0 | CJ15: =CH15+CI15 -> 0 | CO15: =COUNTIF(CK15:CN15,"PR") -> 0 | CP15: =COUNTIF(CK15:CN15,"AB") -> 0 | CQ15: =CO15+CP15 -> 0 | CV15: =COUNTIF(CR15:CU15,"PR") -> 0 | CW15: =COUNTIF(CR15:CU15,"AB") -> 0 | CX15: =CV15+CW15 -> 0 | CY15: =CH15+CO15+CV15 -> 0 | CZ15: =SUM(CF15,#REF!,CT15) -> #REF! | DA15: =CZ15/CY15*100 -> #REF!
B16: Charles J M Yamba | D16: PR | E16: PR | F16: AB | I16: =COUNTIF(D16:H16,"PR") -> 2 | J16: =COUNTIF(D16:H16,"AB") -> 1 | K16: =I16+J16 -> 3 | P16: =COUNTIF(L16:O16,"PR") -> 0 | Q16: =COUNTIF(L16:O16,"AB") -> 0 | R16: =P16+Q16 -> 0 | W16: =COUNTIF(S16:V16,"PR") -> 0 | X16: =COUNTIF(S16:V16,"AB") -> 0 | Y16: =W16+X16 -> 0 | Z16: =K16+R16+Y16 -> 3 | AA16: =SUM(I16,P16,W16) -> 2 | AB16: =AA16/Z16*100 -> 66.666667 | AH16: =COUNTIF(AD16:AG16,"PR") -> 0 | AI16: =COUNTIF(AD16:AG16,"AB") -> 0 | AJ16: =AH16+AI16 -> 0 | AP16: =COUNTIF(AK16:AO16,"PR") -> 0 | AQ16: =COUNTIF(AK16:AO16,"AB") -> 0 | AR16: =AP16+AQ16 -> 0 | AW16: =COUNTIF(AS16:AV16,"PR") -> 0 | AX16: =COUNTIF(AS16:AV16,"AB") -> 0 | AY16: =AW16+AX16 -> 0 | AZ16: =AJ16+AR16+AY16 -> 0 | BA16: =SUM(AH16,AP16,AW16) -> 0 | BB16: =BA16/AZ16*100 -> #DIV/0! | BG16: =COUNTIF(BC16:BF16,"PR") -> 0 | BH16: =COUNTIF(BC16:BF16,"AB") -> 0 | BI16: =BG16+BH16 -> 0 | BO16: =COUNTIF(BJ16:BN16,"PR") -> 0 | BP16: =COUNTIF(BJ16:BN16,"AB") -> 0 | BQ16: =BO16+BP16 -> 0 | BV16: =COUNTIF(BR16:BU16,"PR") -> 0 | BW16: =COUNTIF(BR16:BU16,"AB") -> 0 | BX16: =BV16+BW16 -> 0 | BY16: =BI16+BQ16+BX16 -> 0 | BZ16: =SUM(BG16,BO16,BV16) -> 0 | CA16: =BZ16/BY16*100 -> #DIV/0! | CH16: =COUNTIF(CC16:CG16,"PR") -> 0 | CI16: =COUNTIF(CC16:CG16,"AB") -> 0 | CJ16: =CH16+CI16 -> 0 | CO16: =COUNTIF(CK16:CN16,"PR") -> 0 | CP16: =COUNTIF(CK16:CN16,"AB") -> 0 | CQ16: =CO16+CP16 -> 0 | CV16: =COUNTIF(CR16:CU16,"PR") -> 0 | CW16: =COUNTIF(CR16:CU16,"AB") -> 0 | CX16: =CV16+CW16 -> 0 | CY16: =CH16+CO16+CV16 -> 0 | CZ16: =SUM(CF16,#REF!,CT16) -> #REF! | DA16: =CZ16/CY16*100 -> #REF!
B17: Emmanuella Johnny | D17: AB | E17: PR | F17: PR | I17: =COUNTIF(D16:H16,"PR") -> 2 | K17: =I16+J16 -> 3 | P17: =COUNTIF(L16:O16,"PR") -> 0
B18: John S Beloved | D18: PR | E18: PR | F18: PR | I18: =COUNTIF(D16:H16,"PR") -> 2 | K18: =I16+J16 -> 3 | P18: =COUNTIF(L16:O16,"PR") -> 0
B19: Alfred Foday Kargbo | D19: PR | E19: PR | F19: PR | I19: =COUNTIF(D19:H19,"PR") -> 3 | J19: =COUNTIF(D19:H19,"AB") -> 0 | K19: =I19+J19 -> 3 | P19: =COUNTIF(L19:O19,"PR") -> 0 | Q19: =COUNTIF(L19:O19,"AB") -> 0 | R19: =P19+Q19 -> 0 | W19: =COUNTIF(S19:V19,"PR") -> 0 | X19: =COUNTIF(S19:V19,"AB") -> 0 | Y19: =W19+X19 -> 0 | Z19: =K19+R19+Y19 -> 3 | AA19: =SUM(I19,P19,W19) -> 3 | AB19: =AA19/Z19*100 -> 100 | AH19: =COUNTIF(AD19:AG19,"PR") -> 0 | AI19: =COUNTIF(AD19:AG19,"AB") -> 0 | AJ19: =AH19+AI19 -> 0 | AP19: =COUNTIF(AK19:AO19,"PR") -> 0 | AQ19: =COUNTIF(AK19:AO19,"AB") -> 0 | AR19: =AP19+AQ19 -> 0 | AW19: =COUNTIF(AS19:AV19,"PR") -> 0 | AX19: =COUNTIF(AS19:AV19,"AB") -> 0 | AY19: =AW19+AX19 -> 0 | AZ19: =AJ19+AR19+AY19 -> 0 | BA19: =SUM(AH19,AP19,AW19) -> 0 | BB19: =BA19/AZ19*100 -> #DIV/0! | BG19: =COUNTIF(BC19:BF19,"PR") -> 0 | BH19: =COUNTIF(BC19:BF19,"AB") -> 0 | BI19: =BG19+BH19 -> 0 | BO19: =COUNTIF(BJ19:BN19,"PR") -> 0 | BP19: =COUNTIF(BJ19:BN19,"AB") -> 0 | BQ19: =BO19+BP19 -> 0 | BV19: =COUNTIF(BR19:BU19,"PR") -> 0 | BW19: =COUNTIF(BR19:BU19,"AB") -> 0 | BX19: =BV19+BW19 -> 0 | BY19: =BI19+BQ19+BX19 -> 0 | BZ19: =SUM(BG19,BO19,BV19) -> 0 | CA19: =BZ19/BY19*100 -> #DIV/0! | CH19: =COUNTIF(CC19:CG19,"PR") -> 0 | CI19: =COUNTIF(CC19:CG19,"AB") -> 0 | CJ19: =CH19+CI19 -> 0 | CO19: =COUNTIF(CK19:CN19,"PR") -> 0 | CP19: =COUNTIF(CK19:CN19,"AB") -> 0 | CQ19: =CO19+CP19 -> 0 | CV19: =COUNTIF(CR19:CU19,"PR") -> 0 | CW19: =COUNTIF(CR19:CU19,"AB") -> 0 | CX19: =CV19+CW19 -> 0 | CY19: =CH19+CO19+CV19 -> 0 | CZ19: =SUM(CF19,#REF!,CT19) -> #REF! | DA19: =CZ19/CY19*100 -> #REF!
B20: Samuella Pratt | D20: AB | E20: PR | F20: PR | I20: =COUNTIF(D20:H20,"PR") -> 2 | J20: =COUNTIF(D20:H20,"AB") -> 1 | K20: =I20+J20 -> 3 | P20: =COUNTIF(L20:O20,"PR") -> 0 | Q20: =COUNTIF(L20:O20,"AB") -> 0 | R20: =P20+Q20 -> 0 | W20: =COUNTIF(S20:V20,"PR") -> 0 | X20: =COUNTIF(S20:V20,"AB") -> 0 | Y20: =W20+X20 -> 0 | Z20: =K20+R20+Y20 -> 3 | AA20: =SUM(I20,P20,W20) -> 2 | AB20: =AA20/Z20*100 -> 66.666667 | AH20: =COUNTIF(AD20:AG20,"PR") -> 0 | AI20: =COUNTIF(AD20:AG20,"AB") -> 0 | AJ20: =AH20+AI20 -> 0 | AP20: =COUNTIF(AK20:AO20,"PR") -> 0 | AQ20: =COUNTIF(AK20:AO20,"AB") -> 0 | AR20: =AP20+AQ20 -> 0 | AW20: =COUNTIF(AS20:AV20,"PR") -> 0 | AX20: =COUNTIF(AS20:AV20,"AB") -> 0 | AY20: =AW20+AX20 -> 0 | AZ20: =AJ20+AR20+AY20 -> 0 | BA20: =SUM(AH20,AP20,AW20) -> 0 | BB20: =BA20/AZ20*100 -> #DIV/0! | BG20: =COUNTIF(BC20:BF20,"PR") -> 0 | BH20: =COUNTIF(BC20:BF20,"AB") -> 0 | BI20: =BG20+BH20 -> 0 | BO20: =COUNTIF(BJ20:BN20,"PR") -> 0 | BP20: =COUNTIF(BJ20:BN20,"AB") -> 0 | BQ20: =BO20+BP20 -> 0 | BV20: =COUNTIF(BR20:BU20,"PR") -> 0 | BW20: =COUNTIF(BR20:BU20,"AB") -> 0 | BX20: =BV20+BW20 -> 0 | BY20: =BI20+BQ20+BX20 -> 0 | BZ20: =SUM(BG20,BO20,BV20) -> 0 | CA20: =BZ20/BY20*100 -> #DIV/0! | CH20: =COUNTIF(CC20:CG20,"PR") -> 0 | CI20: =COUNTIF(CC20:CG20,"AB") -> 0 | CJ20: =CH20+CI20 -> 0 | CO20: =COUNTIF(CK20:CN20,"PR") -> 0 | CP20: =COUNTIF(CK20:CN20,"AB") -> 0 | CQ20: =CO20+CP20 -> 0 | CV20: =COUNTIF(CR20:CU20,"PR") -> 0 | CW20: =COUNTIF(CR20:CU20,"AB") -> 0 | CX20: =CV20+CW20 -> 0 | CY20: =CH20+CO20+CV20 -> 0 | CZ20: =SUM(CF20,#REF!,CT20) -> #REF! | DA20: =CZ20/CY20*100 -> #REF!
B21: Hawanatu Kamara | D21: PR | E21: PR | F21: AB | I21: =COUNTIF(D21:H21,"PR") -> 2 | J21: =COUNTIF(D21:H21,"AB") -> 1 | K21: =I21+J21 -> 3 | P21: =COUNTIF(L21:O21,"PR") -> 0 | Q21: =COUNTIF(L21:O21,"AB") -> 0 | R21: =P21+Q21 -> 0 | W21: =COUNTIF(S21:V21,"PR") -> 0 | X21: =COUNTIF(S21:V21,"AB") -> 0 | Y21: =W21+X21 -> 0 | Z21: =K21+R21+Y21 -> 3 | AA21: =SUM(I21,P21,W21) -> 2 | AB21: =AA21/Z21*100 -> 66.666667 | AH21: =COUNTIF(AD21:AG21,"PR") -> 0 | AI21: =COUNTIF(AD21:AG21,"AB") -> 0 | AJ21: =AH21+AI21 -> 0 | AP21: =COUNTIF(AK21:AO21,"PR") -> 0 | AQ21: =COUNTIF(AK21:AO21,"AB") -> 0 | AR21: =AP21+AQ21 -> 0 | AW21: =COUNTIF(AS21:AV21,"PR") -> 0 | AX21: =COUNTIF(AS21:AV21,"AB") -> 0 | AY21: =AW21+AX21 -> 0 | AZ21: =AJ21+AR21+AY21 -> 0 | BA21: =SUM(AH21,AP21,AW21) -> 0 | BB21: =BA21/AZ21*100 -> #DIV/0! | BG21: =COUNTIF(BC21:BF21,"PR") -> 0 | BH21: =COUNTIF(BC21:BF21,"AB") -> 0 | BI21: =BG21+BH21 -> 0 | BO21: =COUNTIF(BJ21:BN21,"PR") -> 0 | BP21: =COUNTIF(BJ21:BN21,"AB") -> 0 | BQ21: =BO21+BP21 -> 0 | BV21: =COUNTIF(BR21:BU21,"PR") -> 0 | BW21: =COUNTIF(BR21:BU21,"AB") -> 0 | BX21: =BV21+BW21 -> 0 | BY21: =BI21+BQ21+BX21 -> 0 | BZ21: =SUM(BG21,BO21,BV21) -> 0 | CA21: =BZ21/BY21*100 -> #DIV/0! | CH21: =COUNTIF(CC21:CG21,"PR") -> 0 | CI21: =COUNTIF(CC21:CG21,"AB") -> 0 | CJ21: =CH21+CI21 -> 0 | CO21: =COUNTIF(CK21:CN21,"PR") -> 0 | CP21: =COUNTIF(CK21:CN21,"AB") -> 0 | CQ21: =CO21+CP21 -> 0 | CV21: =COUNTIF(CR21:CU21,"PR") -> 0 | CW21: =COUNTIF(CR21:CU21,"AB") -> 0 | CX21: =CV21+CW21 -> 0 | CY21: =CH21+CO21+CV21 -> 0 | CZ21: =SUM(CF21,#REF!,CT21) -> #REF! | DA21: =CZ21/CY21*100 -> #REF!
I22: =SUM(I15:I21) -> 15 | K22: =SUM(K15:K21) -> 21 | P22: =SUM(P15:P21) -> 0 | R22: =SUM(R15:R21) -> 0 | W22: =SUM(W15:W21) -> 0 | Y22: =SUM(Y15:Y21) -> 0 | Z22: =SUM(Z15:Z21) -> 15 | AH22: =SUM(AH15:AH21) -> 0 | AJ22: =SUM(AJ15:AJ21) -> 0 | AP22: =SUM(AP15:AP21) -> 0 | AR22: =SUM(AR15:AR21) -> 0 | AW22: =SUM(AW15:AW21) -> 0 | AY22: =SUM(AY15:AY21) -> 0 | AZ22: =SUM(AZ15:AZ21) -> 0 | BG22: =SUM(BG15:BG21) -> 0 | BI22: =SUM(BI15:BI21) -> 0 | BO22: =SUM(BO15:BO21) -> 0 | BQ22: =SUM(BQ15:BQ21) -> 0 | BV22: =SUM(BV15:BV21) -> 0 | BX22: =SUM(BX15:BX21) -> 0 | BY22: =SUM(BY15:BY21) -> 0 | CH22: =SUM(CH15:CH21) -> 0 | CJ22: =SUM(CJ15:CJ21) -> 0 | CO22: =SUM(CO15:CO21) -> 0 | CQ22: =SUM(CQ15:CQ21) -> 0 | CV22: =SUM(CV15:CV21) -> 0 | CX22: =SUM(CX15:CX21) -> 0 | CY22: =SUM(CY15:CY21) -> 0
B23: Consistent
B24: Patrick S J Koroma | D24: PR | E24: AB | F24: AB | I24: =COUNTIF(D24:H24,"PR") -> 1 | J24: =COUNTIF(D24:H24,"AB") -> 2 | K24: =I24+J24 -> 3 | P24: =COUNTIF(L24:O24,"PR") -> 0 | Q24: =COUNTIF(L24:O24,"AB") -> 0 | R24: =P24+Q24 -> 0 | W24: =COUNTIF(S24:V24,"PR") -> 0 | X24: =COUNTIF(S24:V24,"AB") -> 0 | Y24: =W24+X24 -> 0 | Z24: =K24+R24+Y24 -> 3 | AA24: =SUM(I24,P24,W24) -> 1 | AB24: =AA24/Z24*100 -> 33.333333 | AH24: =COUNTIF(AD24:AG24,"PR") -> 0 | AI24: =COUNTIF(AD24:AG24,"AB") -> 0 | AJ24: =AH24+AI24 -> 0 | AP24: =COUNTIF(AK24:AO24,"PR") -> 0 | AQ24: =COUNTIF(AK24:AO24,"AB") -> 0 | AR24: =AP24+AQ24 -> 0 | AW24: =COUNTIF(AS24:AV24,"PR") -> 0 | AX24: =COUNTIF(AS24:AV24,"AB") -> 0 | AY24: =AW24+AX24 -> 0 | AZ24: =AJ24+AR24+AY24 -> 0 | BA24: =SUM(AH24,AP24,AW24) -> 0 | BB24: =BA24/AZ24*100 -> #DIV/0! | BG24: =COUNTIF(BC24:BF24,"PR") -> 0 | BH24: =COUNTIF(BC24:BF24,"AB") -> 0 | BI24: =BG24+BH24 -> 0 | BO24: =COUNTIF(BJ24:BN24,"PR") -> 0 | BP24: =COUNTIF(BJ24:BN24,"AB") -> 0 | BQ24: =BO24+BP24 -> 0 | BV24: =COUNTIF(BR24:BU24,"PR") -> 0 | BW24: =COUNTIF(BR24:BU24,"AB") -> 0 | BX24: =BV24+BW24 -> 0 | BY24: =BI24+BQ24+BX24 -> 0 | BZ24: =SUM(BG24,BO24,BV24) -> 0 | CA24: =BZ24/BY24*100 -> #DIV/0! | CH24: =COUNTIF(CC24:CG24,"PR") -> 0 | CI24: =COUNTIF(CC24:CG24,"AB") -> 0 | CJ24: =CH24+CI24 -> 0 | CO24: =COUNTIF(CK24:CN24,"PR") -> 0 | CP24: =COUNTIF(CK24:CN24,"AB") -> 0 | CQ24: =CO24+CP24 -> 0 | CV24: =COUNTIF(CR24:CU24,"PR") -> 0 | CW24: =COUNTIF(CR24:CU24,"AB") -> 0 | CX24: =CV24+CW24 -> 0 | CY24: =CH24+CO24+CV24 -> 0 | CZ24: =SUM(CF24,#REF!,CT24) -> #REF! | DA24: =CZ24/CY24*100 -> #REF!
B25: Edmond Lebbie | D25: PR | E25: AB | F25: AB | I25: =COUNTIF(D25:H25,"PR") -> 1 | J25: =COUNTIF(D25:H25,"AB") -> 2 | K25: =I25+J25 -> 3 | P25: =COUNTIF(L25:O25,"PR") -> 0 | Q25: =COUNTIF(L25:O25,"AB") -> 0 | R25: =P25+Q25 -> 0 | W25: =COUNTIF(S25:V25,"PR") -> 0 | X25: =COUNTIF(S25:V25,"AB") -> 0 | Y25: =W25+X25 -> 0 | Z25: =K25+R25+Y25 -> 3 | AA25: =SUM(I25,P25,W25) -> 1 | AB25: =AA25/Z25*100 -> 33.333333 | AH25: =COUNTIF(AD25:AG25,"PR") -> 0 | AI25: =COUNTIF(AD25:AG25,"AB") -> 0 | AJ25: =AH25+AI25 -> 0 | AP25: =COUNTIF(AK25:AO25,"PR") -> 0 | AQ25: =COUNTIF(AK25:AO25,"AB") -> 0 | AR25: =AP25+AQ25 -> 0 | AW25: =COUNTIF(AS25:AV25,"PR") -> 0 | AX25: =COUNTIF(AS25:AV25,"AB") -> 0 | AY25: =AW25+AX25 -> 0 | AZ25: =AJ25+AR25+AY25 -> 0 | BA25: =SUM(AH25,AP25,AW25) -> 0 | BB25: =BA25/AZ25*100 -> #DIV/0! | BG25: =COUNTIF(BC25:BF25,"PR") -> 0 | BH25: =COUNTIF(BC25:BF25,"AB") -> 0 | BI25: =BG25+BH25 -> 0 | BO25: =COUNTIF(BJ25:BN25,"PR") -> 0 | BP25: =COUNTIF(BJ25:BN25,"AB") -> 0 | BQ25: =BO25+BP25 -> 0 | BV25: =COUNTIF(BR25:BU25,"PR") -> 0 | BW25: =COUNTIF(BR25:BU25,"AB") -> 0 | BX25: =BV25+BW25 -> 0 | BY25: =BI25+BQ25+BX25 -> 0 | BZ25: =SUM(BG25,BO25,BV25) -> 0 | CA25: =BZ25/BY25*100 -> #DIV/0! | CH25: =COUNTIF(CC25:CG25,"PR") -> 0 | CI25: =COUNTIF(CC25:CG25,"AB") -> 0 | CJ25: =CH25+CI25 -> 0 | CO25: =COUNTIF(CK25:CN25,"PR") -> 0 | CP25: =COUNTIF(CK25:CN25,"AB") -> 0 | CQ25: =CO25+CP25 -> 0 | CV25: =COUNTIF(CR25:CU25,"PR") -> 0 | CW25: =COUNTIF(CR25:CU25,"AB") -> 0 | CX25: =CV25+CW25 -> 0 | CY25: =CH25+CO25+CV25 -> 0 | CZ25: =SUM(CF25,#REF!,CT25) -> #REF! | DA25: =CZ25/CY25*100 -> #REF!
B26: Marian I. Peterson | D26: AB | E26: PR | F26: AB | I26: =COUNTIF(D26:H26,"PR") -> 1 | J26: =COUNTIF(D26:H26,"AB") -> 2 | K26: =I26+J26 -> 3 | P26: =COUNTIF(L26:O26,"PR") -> 0 | Q26: =COUNTIF(L26:O26,"AB") -> 0 | R26: =P26+Q26 -> 0 | W26: =COUNTIF(S26:V26,"PR") -> 0 | X26: =COUNTIF(S26:V26,"AB") -> 0 | Y26: =W26+X26 -> 0 | Z26: =K26+R26+Y26 -> 3 | AA26: =SUM(I26,P26,W26) -> 1 | AB26: =AA26/Z26*100 -> 33.333333 | AH26: =COUNTIF(AD26:AG26,"PR") -> 0 | AI26: =COUNTIF(AD26:AG26,"AB") -> 0 | AJ26: =AH26+AI26 -> 0 | AP26: =COUNTIF(AK26:AO26,"PR") -> 0 | AQ26: =COUNTIF(AK26:AO26,"AB") -> 0 | AR26: =AP26+AQ26 -> 0 | AW26: =COUNTIF(AS26:AV26,"PR") -> 0 | AX26: =COUNTIF(AS26:AV26,"AB") -> 0 | AY26: =AW26+AX26 -> 0 | AZ26: =AJ26+AR26+AY26 -> 0 | BA26: =SUM(AH26,AP26,AW26) -> 0 | BB26: =BA26/AZ26*100 -> #DIV/0! | BG26: =COUNTIF(BC26:BF26,"PR") -> 0 | BH26: =COUNTIF(BC26:BF26,"AB") -> 0 | BI26: =BG26+BH26 -> 0 | BO26: =COUNTIF(BJ26:BN26,"PR") -> 0 | BP26: =COUNTIF(BJ26:BN26,"AB") -> 0 | BQ26: =BO26+BP26 -> 0 | BV26: =COUNTIF(BR26:BU26,"PR") -> 0 | BW26: =COUNTIF(BR26:BU26,"AB") -> 0 | BX26: =BV26+BW26 -> 0 | BY26: =BI26+BQ26+BX26 -> 0 | BZ26: =SUM(BG26,BO26,BV26) -> 0 | CA26: =BZ26/BY26*100 -> #DIV/0! | CH26: =COUNTIF(CC26:CG26,"PR") -> 0 | CI26: =COUNTIF(CC26:CG26,"AB") -> 0 | CJ26: =CH26+CI26 -> 0 | CO26: =COUNTIF(CK26:CN26,"PR") -> 0 | CP26: =COUNTIF(CK26:CN26,"AB") -> 0 | CQ26: =CO26+CP26 -> 0 | CV26: =COUNTIF(CR26:CU26,"PR") -> 0 | CW26: =COUNTIF(CR26:CU26,"AB") -> 0 | CX26: =CV26+CW26 -> 0 | CY26: =CH26+CO26+CV26 -> 0 | CZ26: =SUM(CF26,#REF!,CT26) -> #REF! | DA26: =CZ26/CY26*100 -> #REF!
B27: Rebecca Jansie | D27: AB | E27: PR | F27: AB | I27: =COUNTIF(D27:H27,"PR") -> 1 | J27: =COUNTIF(D27:H27,"AB") -> 2 | K27: =I27+J27 -> 3 | P27: =COUNTIF(L27:O27,"PR") -> 0 | Q27: =COUNTIF(L27:O27,"AB") -> 0 | R27: =P27+Q27 -> 0 | W27: =COUNTIF(S27:V27,"PR") -> 0 | X27: =COUNTIF(S27:V27,"AB") -> 0 | Y27: =W27+X27 -> 0 | Z27: =K27+R27+Y27 -> 3 | AA27: =SUM(I27,P27,W27) -> 1 | AB27: =AA27/Z27*100 -> 33.333333 | AH27: =COUNTIF(AD27:AG27,"PR") -> 0 | AI27: =COUNTIF(AD27:AG27,"AB") -> 0 | AJ27: =AH27+AI27 -> 0 | AP27: =COUNTIF(AK27:AO27,"PR") -> 0 | AQ27: =COUNTIF(AK27:AO27,"AB") -> 0 | AR27: =AP27+AQ27 -> 0 | AW27: =COUNTIF(AS27:AV27,"PR") -> 0 | AX27: =COUNTIF(AS27:AV27,"AB") -> 0 | AY27: =AW27+AX27 -> 0 | AZ27: =AJ27+AR27+AY27 -> 0 | BA27: =SUM(AH27,AP27,AW27) -> 0 | BB27: =BA27/AZ27*100 -> #DIV/0! | BG27: =COUNTIF(BC27:BF27,"PR") -> 0 | BH27: =COUNTIF(BC27:BF27,"AB") -> 0 | BI27: =BG27+BH27 -> 0 | BO27: =COUNTIF(BJ27:BN27,"PR") -> 0 | BP27: =COUNTIF(BJ27:BN27,"AB") -> 0 | BQ27: =BO27+BP27 -> 0 | BV27: =COUNTIF(BR27:BU27,"PR") -> 0 | BW27: =COUNTIF(BR27:BU27,"AB") -> 0 | BX27: =BV27+BW27 -> 0 | BY27: =BI27+BQ27+BX27 -> 0 | BZ27: =SUM(BG27,BO27,BV27) -> 0 | CA27: =BZ27/BY27*100 -> #DIV/0! | CH27: =COUNTIF(CC27:CG27,"PR") -> 0 | CI27: =COUNTIF(CC27:CG27,"AB") -> 0 | CJ27: =CH27+CI27 -> 0 | CO27: =COUNTIF(CK27:CN27,"PR") -> 0 | CP27: =COUNTIF(CK27:CN27,"AB") -> 0 | CQ27: =CO27+CP27 -> 0 | CV27: =COUNTIF(CR27:CU27,"PR") -> 0 | CW27: =COUNTIF(CR27:CU27,"AB") -> 0 | CX27: =CV27+CW27 -> 0 | CY27: =CH27+CO27+CV27 -> 0 | CZ27: =SUM(CF27,#REF!,CT27) -> #REF! | DA27: =CZ27/CY27*100 -> #REF!
B28: Esther Kapindi | D28: AB | E28: PR | F28: PR | I28: =COUNTIF(D28:H28,"PR") -> 2 | J28: =COUNTIF(D28:H28,"AB") -> 1 | K28: =I28+J28 -> 3 | P28: =COUNTIF(L28:O28,"PR") -> 0 | Q28: =COUNTIF(L28:O28,"AB") -> 0 | R28: =P28+Q28 -> 0 | W28: =COUNTIF(S28:V28,"PR") -> 0 | X28: =COUNTIF(S28:V28,"AB") -> 0 | Y28: =W28+X28 -> 0 | Z28: =K28+R28+Y28 -> 3 | AA28: =SUM(I28,P28,W28) -> 2 | AB28: =AA28/Z28*100 -> 66.666667 | AH28: =COUNTIF(AD28:AG28,"PR") -> 0 | AI28: =COUNTIF(AD28:AG28,"AB") -> 0 | AJ28: =AH28+AI28 -> 0 | AP28: =COUNTIF(AK28:AO28,"PR") -> 0 | AQ28: =COUNTIF(AK28:AO28,"AB") -> 0 | AR28: =AP28+AQ28 -> 0 | AW28: =COUNTIF(AS28:AV28,"PR") -> 0 | AX28: =COUNTIF(AS28:AV28,"AB") -> 0 | AY28: =AW28+AX28 -> 0 | AZ28: =AJ28+AR28+AY28 -> 0 | BA28: =SUM(AH28,AP28,AW28) -> 0 | BB28: =BA28/AZ28*100 -> #DIV/0! | BG28: =COUNTIF(BC28:BF28,"PR") -> 0 | BH28: =COUNTIF(BC28:BF28,"AB") -> 0 | BI28: =BG28+BH28 -> 0 | BO28: =COUNTIF(BJ28:BN28,"PR") -> 0 | BP28: =COUNTIF(BJ28:BN28,"AB") -> 0 | BQ28: =BO28+BP28 -> 0 | BV28: =COUNTIF(BR28:BU28,"PR") -> 0 | BW28: =COUNTIF(BR28:BU28,"AB") -> 0 | BX28: =BV28+BW28 -> 0 | BY28: =BI28+BQ28+BX28 -> 0 | BZ28: =SUM(BG28,BO28,BV28) -> 0 | CA28: =BZ28/BY28*100 -> #DIV/0! | CH28: =COUNTIF(CC28:CG28,"PR") -> 0 | CI28: =COUNTIF(CC28:CG28,"AB") -> 0 | CJ28: =CH28+CI28 -> 0 | CO28: =COUNTIF(CK28:CN28,"PR") -> 0 | CP28: =COUNTIF(CK28:CN28,"AB") -> 0 | CQ28: =CO28+CP28 -> 0 | CV28: =COUNTIF(CR28:CU28,"PR") -> 0 | CW28: =COUNTIF(CR28:CU28,"AB") -> 0 | CX28: =CV28+CW28 -> 0 | CY28: =CH28+CO28+CV28 -> 0 | CZ28: =SUM(CF28,#REF!,CT28) -> #REF! | DA28: =CZ28/CY28*100 -> #REF!
B29: Sarah N. Abu | D29: AB | E29: PR | F29: AB | I29: =COUNTIF(D29:H29,"PR") -> 1 | J29: =COUNTIF(D29:H29,"AB") -> 2 | K29: =I29+J29 -> 3 | P29: =COUNTIF(L29:O29,"PR") -> 0 | Q29: =COUNTIF(L29:O29,"AB") -> 0 | R29: =P29+Q29 -> 0 | W29: =COUNTIF(S29:V29,"PR") -> 0 | X29: =COUNTIF(S29:V29,"AB") -> 0 | Y29: =W29+X29 -> 0 | Z29: =K29+R29+Y29 -> 3 | AA29: =SUM(I29,P29,W29) -> 1 | AB29: =AA29/Z29*100 -> 33.333333 | AH29: =COUNTIF(AD29:AG29,"PR") -> 0 | AI29: =COUNTIF(AD29:AG29,"AB") -> 0 | AJ29: =AH29+AI29 -> 0 | AP29: =COUNTIF(AK29:AO29,"PR") -> 0 | AQ29: =COUNTIF(AK29:AO29,"AB") -> 0 | AR29: =AP29+AQ29 -> 0 | AW29: =COUNTIF(AS29:AV29,"PR") -> 0 | AX29: =COUNTIF(AS29:AV29,"AB") -> 0 | AY29: =AW29+AX29 -> 0 | AZ29: =AJ29+AR29+AY29 -> 0 | BA29: =SUM(AH29,AP29,AW29) -> 0 | BB29: =BA29/AZ29*100 -> #DIV/0! | BG29: =COUNTIF(BC29:BF29,"PR") -> 0 | BH29: =COUNTIF(BC29:BF29,"AB") -> 0 | BI29: =BG29+BH29 -> 0 | BO29: =COUNTIF(BJ29:BN29,"PR") -> 0 | BP29: =COUNTIF(BJ29:BN29,"AB") -> 0 | BQ29: =BO29+BP29 -> 0 | BV29: =COUNTIF(BR29:BU29,"PR") -> 0 | BW29: =COUNTIF(BR29:BU29,"AB") -> 0 | BX29: =BV29+BW29 -> 0 | BY29: =BI29+BQ29+BX29 -> 0 | BZ29: =SUM(BG29,BO29,BV29) -> 0 | CA29: =BZ29/BY29*100 -> #DIV/0! | CH29: =COUNTIF(CC29:CG29,"PR") -> 0 | CI29: =COUNTIF(CC29:CG29,"AB") -> 0 | CJ29: =CH29+CI29 -> 0 | CO29: =COUNTIF(CK29:CN29,"PR") -> 0 | CP29: =COUNTIF(CK29:CN29,"AB") -> 0 | CQ29: =CO29+CP29 -> 0 | CV29: =COUNTIF(CR29:CU29,"PR") -> 0 | CW29: =COUNTIF(CR29:CU29,"AB") -> 0 | CX29: =CV29+CW29 -> 0 | CY29: =CH29+CO29+CV29 -> 0 | CZ29: =SUM(CF29,#REF!,CT29) -> #REF! | DA29: =CZ29/CY29*100 -> #REF!
B30: Jessica Jaka | D30: AB | E30: PR | F30: AB | I30: =COUNTIF(D30:H30,"PR") -> 1 | J30: =COUNTIF(D30:H30,"AB") -> 2 | K30: =I30+J30 -> 3 | P30: =COUNTIF(L30:O30,"PR") -> 0 | Q30: =COUNTIF(L30:O30,"AB") -> 0 | R30: =P30+Q30 -> 0 | W30: =COUNTIF(S30:V30,"PR") -> 0 | X30: =COUNTIF(S30:V30,"AB") -> 0 | Y30: =W30+X30 -> 0 | Z30: =K30+R30+Y30 -> 3 | AA30: =SUM(I30,P30,W30) -> 1 | AB30: =AA30/Z30*100 -> 33.333333 | AH30: =COUNTIF(AD30:AG30,"PR") -> 0 | AI30: =COUNTIF(AD30:AG30,"AB") -> 0 | AJ30: =AH30+AI30 -> 0 | AP30: =COUNTIF(AK30:AO30,"PR") -> 0 | AQ30: =COUNTIF(AK30:AO30,"AB") -> 0 | AR30: =AP30+AQ30 -> 0 | AW30: =COUNTIF(AS30:AV30,"PR") -> 0 | AX30: =COUNTIF(AS30:AV30,"AB") -> 0 | AY30: =AW30+AX30 -> 0 | AZ30: =AJ30+AR30+AY30 -> 0 | BA30: =SUM(AH30,AP30,AW30) -> 0 | BB30: =BA30/AZ30*100 -> #DIV/0! | BG30: =COUNTIF(BC30:BF30,"PR") -> 0 | BH30: =COUNTIF(BC30:BF30,"AB") -> 0 | BI30: =BG30+BH30 -> 0 | BO30: =COUNTIF(BJ30:BN30,"PR") -> 0 | BP30: =COUNTIF(BJ30:BN30,"AB") -> 0 | BQ30: =BO30+BP30 -> 0 | BV30: =COUNTIF(BR30:BU30,"PR") -> 0 | BW30: =COUNTIF(BR30:BU30,"AB") -> 0 | BX30: =BV30+BW30 -> 0 | BY30: =BI30+BQ30+BX30 -> 0 | BZ30: =SUM(BG30,BO30,BV30) -> 0 | CA30: =BZ30/BY30*100 -> #DIV/0! | CH30: =COUNTIF(CC30:CG30,"PR") -> 0 | CI30: =COUNTIF(CC30:CG30,"AB") -> 0 | CJ30: =CH30+CI30 -> 0 | CO30: =COUNTIF(CK30:CN30,"PR") -> 0 | CP30: =COUNTIF(CK30:CN30,"AB") -> 0 | CQ30: =CO30+CP30 -> 0 | CV30: =COUNTIF(CR30:CU30,"PR") -> 0 | CW30: =COUNTIF(CR30:CU30,"AB") -> 0 | CX30: =CV30+CW30 -> 0 | CY30: =CH30+CO30+CV30 -> 0 | CZ30: =SUM(CF30,#REF!,CT30) -> #REF! | DA30: =CZ30/CY30*100 -> #REF!
I31: =COUNTIF(D31:H31,"PR") -> 0 | J31: =COUNTIF(D31:H31,"AB") -> 0 | K31: =I31+J31 -> 0 | P31: =COUNTIF(L31:O31,"PR") -> 0 | Q31: =COUNTIF(L31:O31,"AB") -> 0 | R31: =P31+Q31 -> 0 | W31: =COUNTIF(S31:V31,"PR") -> 0 | X31: =COUNTIF(S31:V31,"AB") -> 0 | Y31: =W31+X31 -> 0 | Z31: =K31+R31+Y31 -> 0 | AA31: =SUM(I31,P31,W31) -> 0 | AB31: =AA31/Z31*100 -> #DIV/0! | AH31: =COUNTIF(AD31:AG31,"PR") -> 0 | AI31: =COUNTIF(AD31:AG31,"AB") -> 0 | AJ31: =AH31+AI31 -> 0 | AP31: =COUNTIF(AK31:AO31,"PR") -> 0 | AQ31: =COUNTIF(AK31:AO31,"AB") -> 0 | AR31: =AP31+AQ31 -> 0 | AW31: =COUNTIF(AS31:AV31,"PR") -> 0 | AX31: =COUNTIF(AS31:AV31,"AB") -> 0 | AY31: =AW31+AX31 -> 0 | AZ31: =AJ31+AR31+AY31 -> 0 | BA31: =SUM(AH31,AP31,AW31) -> 0 | BB31: =BA31/AZ31*100 -> #DIV/0! | BG31: =COUNTIF(BC31:BF31,"PR") -> 0 | BH31: =COUNTIF(BC31:BF31,"AB") -> 0 | BI31: =BG31+BH31 -> 0 | BO31: =COUNTIF(BJ31:BN31,"PR") -> 0 | BP31: =COUNTIF(BJ31:BN31,"AB") -> 0 | BQ31: =BO31+BP31 -> 0 | BV31: =COUNTIF(BR31:BU31,"PR") -> 0 | BW31: =COUNTIF(BR31:BU31,"AB") -> 0 | BX31: =BV31+BW31 -> 0 | BY31: =BI31+BQ31+BX31 -> 0 | BZ31: =SUM(BG31,BO31,BV31) -> 0 | CA31: =BZ31/BY31*100 -> #DIV/0! | CH31: =COUNTIF(CC31:CG31,"PR") -> 0 | CI31: =COUNTIF(CC31:CG31,"AB") -> 0 | CJ31: =CH31+CI31 -> 0 | CO31: =COUNTIF(CK31:CN31,"PR") -> 0 | CP31: =COUNTIF(CK31:CN31,"AB") -> 0 | CQ31: =CO31+CP31 -> 0 | CV31: =COUNTIF(CR31:CU31,"PR") -> 0 | CW31: =COUNTIF(CR31:CU31,"AB") -> 0 | CX31: =CV31+CW31 -> 0 | CY31: =CH31+CO31+CV31 -> 0 | CZ31: =SUM(CF31,#REF!,CT31) -> #REF! | DA31: =CZ31/CY31*100 -> #REF!
I32: =COUNTIF(D32:H32,"PR") -> 0 | J32: =COUNTIF(D32:H32,"AB") -> 0 | K32: =I32+J32 -> 0 | P32: =COUNTIF(L32:O32,"PR") -> 0 | Q32: =COUNTIF(L32:O32,"AB") -> 0 | R32: =P32+Q32 -> 0 | W32: =COUNTIF(S32:V32,"PR") -> 0 | X32: =COUNTIF(S32:V32,"AB") -> 0 | Y32: =W32+X32 -> 0 | Z32: =K32+R32+Y32 -> 0 | AA32: =SUM(I32,P32,W32) -> 0 | AB32: =AA32/Z32*100 -> #DIV/0! | AH32: =COUNTIF(AD32:AG32,"PR") -> 0 | AI32: =COUNTIF(AD32:AG32,"AB") -> 0 | AJ32: =AH32+AI32 -> 0 | AP32: =COUNTIF(AK32:AO32,"PR") -> 0 | AQ32: =COUNTIF(AK32:AO32,"AB") -> 0 | AR32: =AP32+AQ32 -> 0 | AW32: =COUNTIF(AS32:AV32,"PR") -> 0 | AX32: =COUNTIF(AS32:AV32,"AB") -> 0 | AY32: =AW32+AX32 -> 0 | AZ32: =AJ32+AR32+AY32 -> 0 | BA32: =SUM(AH32,AP32,AW32) -> 0 | BB32: =BA32/AZ32*100 -> #DIV/0! | BG32: =COUNTIF(BC32:BF32,"PR") -> 0 | BH32: =COUNTIF(BC32:BF32,"AB") -> 0 | BI32: =BG32+BH32 -> 0 | BO32: =COUNTIF(BJ32:BN32,"PR") -> 0 | BP32: =COUNTIF(BJ32:BN32,"AB") -> 0 | BQ32: =BO32+BP32 -> 0 | BV32: =COUNTIF(BR32:BU32,"PR") -> 0 | BW32: =COUNTIF(BR32:BU32,"AB") -> 0 | BX32: =BV32+BW32 -> 0 | BY32: =BI32+BQ32+BX32 -> 0 | BZ32: =SUM(BG32,BO32,BV32) -> 0 | CA32: =BZ32/BY32*100 -> #DIV/0! | CH32: =COUNTIF(CC32:CG32,"PR") -> 0 | CI32: =COUNTIF(CC32:CG32,"AB") -> 0 | CJ32: =CH32+CI32 -> 0 | CO32: =COUNTIF(CK32:CN32,"PR") -> 0 | CP32: =COUNTIF(CK32:CN32,"AB") -> 0 | CQ32: =CO32+CP32 -> 0 | CV32: =COUNTIF(CR32:CU32,"PR") -> 0 | CW32: =COUNTIF(CR32:CU32,"AB") -> 0 | CX32: =CV32+CW32 -> 0 | CY32: =CH32+CO32+CV32 -> 0 | CZ32: =SUM(CF32,#REF!,CT32) -> #REF! | DA32: =CZ32/CY32*100 -> #REF!
I33: =COUNTIF(D33:H33,"PR") -> 0 | J33: =COUNTIF(D33:H33,"AB") -> 0 | K33: =I33+J33 -> 0 | P33: =COUNTIF(L33:O33,"PR") -> 0 | Q33: =COUNTIF(L33:O33,"AB") -> 0 | R33: =P33+Q33 -> 0 | W33: =COUNTIF(S33:V33,"PR") -> 0 | X33: =COUNTIF(S33:V33,"AB") -> 0 | Y33: =W33+X33 -> 0 | Z33: =K33+R33+Y33 -> 0 | AA33: =SUM(I33,P33,W33) -> 0 | AB33: =AA33/Z33*100 -> #DIV/0! | AH33: =COUNTIF(AD33:AG33,"PR") -> 0 | AI33: =COUNTIF(AD33:AG33,"AB") -> 0 | AJ33: =AH33+AI33 -> 0 | AP33: =COUNTIF(AK33:AO33,"PR") -> 0 | AQ33: =COUNTIF(AK33:AO33,"AB") -> 0 | AR33: =AP33+AQ33 -> 0 | AW33: =COUNTIF(AS33:AV33,"PR") -> 0 | AX33: =COUNTIF(AS33:AV33,"AB") -> 0 | AY33: =AW33+AX33 -> 0 | AZ33: =AJ33+AR33+AY33 -> 0 | BA33: =SUM(AH33,AP33,AW33) -> 0 | BB33: =BA33/AZ33*100 -> #DIV/0! | BG33: =COUNTIF(BC33:BF33,"PR") -> 0 | BH33: =COUNTIF(BC33:BF33,"AB") -> 0 | BI33: =BG33+BH33 -> 0 | BO33: =COUNTIF(BJ33:BN33,"PR") -> 0 | BP33: =COUNTIF(BJ33:BN33,"AB") -> 0 | BQ33: =BO33+BP33 -> 0 | BV33: =COUNTIF(BR33:BU33,"PR") -> 0 | BW33: =COUNTIF(BR33:BU33,"AB") -> 0 | BX33: =BV33+BW33 -> 0 | BY33: =BI33+BQ33+BX33 -> 0 | BZ33: =SUM(BG33,BO33,BV33) -> 0 | CA33: =BZ33/BY33*100 -> #DIV/0! | CH33: =COUNTIF(CC33:CG33,"PR") -> 0 | CI33: =COUNTIF(CC33:CG33,"AB") -> 0 | CJ33: =CH33+CI33 -> 0 | CO33: =COUNTIF(CK33:CN33,"PR") -> 0 | CP33: =COUNTIF(CK33:CN33,"AB") -> 0 | CQ33: =CO33+CP33 -> 0 | CV33: =COUNTIF(CR33:CU33,"PR") -> 0 | CW33: =COUNTIF(CR33:CU33,"AB") -> 0 | CX33: =CV33+CW33 -> 0 | CY33: =CH33+CO33+CV33 -> 0 | CZ33: =SUM(CF33,#REF!,CT33) -> #REF! | DA33: =CZ33/CY33*100 -> #REF!
I34: =COUNTIF(D34:H34,"PR") -> 0 | J34: =COUNTIF(D34:H34,"AB") -> 0 | K34: =I34+J34 -> 0 | P34: =COUNTIF(L34:O34,"PR") -> 0 | Q34: =COUNTIF(L34:O34,"AB") -> 0 | R34: =P34+Q34 -> 0 | W34: =COUNTIF(S34:V34,"PR") -> 0 | X34: =COUNTIF(S34:V34,"AB") -> 0 | Y34: =W34+X34 -> 0 | Z34: =K34+R34+Y34 -> 0 | AA34: =SUM(I34,P34,W34) -> 0 | AB34: =AA34/Z34*100 -> #DIV/0! | AH34: =COUNTIF(AD34:AG34,"PR") -> 0 | AI34: =COUNTIF(AD34:AG34,"AB") -> 0 | AJ34: =AH34+AI34 -> 0 | AP34: =COUNTIF(AK34:AO34,"PR") -> 0 | AQ34: =COUNTIF(AK34:AO34,"AB") -> 0 | AR34: =AP34+AQ34 -> 0 | AW34: =COUNTIF(AS34:AV34,"PR") -> 0 | AX34: =COUNTIF(AS34:AV34,"AB") -> 0 | AY34: =AW34+AX34 -> 0 | AZ34: =AJ34+AR34+AY34 -> 0 | BA34: =SUM(AH34,AP34,AW34) -> 0 | BB34: =BA34/AZ34*100 -> #DIV/0! | BG34: =COUNTIF(BC34:BF34,"PR") -> 0 | BH34: =COUNTIF(BC34:BF34,"AB") -> 0 | BI34: =BG34+BH34 -> 0 | BO34: =COUNTIF(BJ34:BN34,"PR") -> 0 | BP34: =COUNTIF(BJ34:BN34,"AB") -> 0 | BQ34: =BO34+BP34 -> 0 | BV34: =COUNTIF(BR34:BU34,"PR") -> 0 | BW34: =COUNTIF(BR34:BU34,"AB") -> 0 | BX34: =BV34+BW34 -> 0 | BY34: =BI34+BQ34+BX34 -> 0 | BZ34: =SUM(BG34,BO34,BV34) -> 0 | CA34: =BZ34/BY34*100 -> #DIV/0! | CH34: =COUNTIF(CC34:CG34,"PR") -> 0 | CI34: =COUNTIF(CC34:CG34,"AB") -> 0 | CJ34: =CH34+CI34 -> 0 | CO34: =COUNTIF(CK34:CN34,"PR") -> 0 | CP34: =COUNTIF(CK34:CN34,"AB") -> 0 | CQ34: =CO34+CP34 -> 0 | CV34: =COUNTIF(CR34:CU34,"PR") -> 0 | CW34: =COUNTIF(CR34:CU34,"AB") -> 0 | CX34: =CV34+CW34 -> 0 | CY34: =CH34+CO34+CV34 -> 0 | CZ34: =SUM(CF34,#REF!,CT34) -> #REF! | DA34: =CZ34/CY34*100 -> #REF!
I35: =COUNTIF(D35:H35,"PR") -> 0 | J35: =COUNTIF(D35:H35,"AB") -> 0 | K35: =I35+J35 -> 0 | P35: =COUNTIF(L35:O35,"PR") -> 0 | Q35: =COUNTIF(L35:O35,"AB") -> 0 | R35: =P35+Q35 -> 0 | W35: =COUNTIF(S35:V35,"PR") -> 0 | X35: =COUNTIF(S35:V35,"AB") -> 0 | Y35: =W35+X35 -> 0 | Z35: =K35+R35+Y35 -> 0 | AA35: =SUM(I35,P35,W35) -> 0 | AB35: =AA35/Z35*100 -> #DIV/0! | AH35: =COUNTIF(AD35:AG35,"PR") -> 0 | AI35: =COUNTIF(AD35:AG35,"AB") -> 0 | AJ35: =AH35+AI35 -> 0 | AP35: =COUNTIF(AK35:AO35,"PR") -> 0 | AQ35: =COUNTIF(AK35:AO35,"AB") -> 0 | AR35: =AP35+AQ35 -> 0 | AW35: =COUNTIF(AS35:AV35,"PR") -> 0 | AX35: =COUNTIF(AS35:AV35,"AB") -> 0 | AY35: =AW35+AX35 -> 0 | AZ35: =AJ35+AR35+AY35 -> 0 | BA35: =SUM(AH35,AP35,AW35) -> 0 | BB35: =BA35/AZ35*100 -> #DIV/0! | BG35: =COUNTIF(BC35:BF35,"PR") -> 0 | BH35: =COUNTIF(BC35:BF35,"AB") -> 0 | BI35: =BG35+BH35 -> 0 | BO35: =COUNTIF(BJ35:BN35,"PR") -> 0 | BP35: =COUNTIF(BJ35:BN35,"AB") -> 0 | BQ35: =BO35+BP35 -> 0 | BV35: =COUNTIF(BR35:BU35,"PR") -> 0 | BW35: =COUNTIF(BR35:BU35,"AB") -> 0 | BX35: =BV35+BW35 -> 0 | BY35: =BI35+BQ35+BX35 -> 0 | BZ35: =SUM(BG35,BO35,BV35) -> 0 | CA35: =BZ35/BY35*100 -> #DIV/0! | CH35: =COUNTIF(CC35:CG35,"PR") -> 0 | CI35: =COUNTIF(CC35:CG35,"AB") -> 0 | CJ35: =CH35+CI35 -> 0 | CO35: =COUNTIF(CK35:CN35,"PR") -> 0 | CP35: =COUNTIF(CK35:CN35,"AB") -> 0 | CQ35: =CO35+CP35 -> 0 | CV35: =COUNTIF(CR35:CU35,"PR") -> 0 | CW35: =COUNTIF(CR35:CU35,"AB") -> 0 | CX35: =CV35+CW35 -> 0 | CY35: =CH35+CO35+CV35 -> 0 | CZ35: =SUM(CF35,#REF!,CT35) -> #REF! | DA35: =CZ35/CY35*100 -> #REF!
I36: =SUM(I24:I35) -> 8 | K36: =SUM(K24:K35) -> 21 | P36: =SUM(P24:P35) -> 0 | R36: =SUM(R24:R35) -> 0 | W36: =SUM(W24:W35) -> 0 | Y36: =SUM(Y24:Y35) -> 0 | Z36: =SUM(Z31:Z35) -> 0 | AH36: =SUM(AH24:AH35) -> 0 | AJ36: =SUM(AJ24:AJ35) -> 0 | AP36: =SUM(AP24:AP35) -> 0 | AR36: =SUM(AR24:AR35) -> 0 | AW36: =SUM(AW24:AW35) -> 0 | AY36: =SUM(AY24:AY35) -> 0 | AZ36: =SUM(AZ31:AZ35) -> 0 | BG36: =SUM(BG24:BG35) -> 0 | BI36: =SUM(BI24:BI35) -> 0 | BO36: =SUM(BO24:BO35) -> 0 | BQ36: =SUM(BQ24:BQ35) -> 0 | BV36: =SUM(BV24:BV35) -> 0 | BX36: =SUM(BX24:BX35) -> 0 | BY36: =SUM(BY31:BY35) -> 0 | CH36: =SUM(CH24:CH35) -> 0 | CJ36: =SUM(CJ24:CJ35) -> 0 | CO36: =SUM(CO24:CO35) -> 0 | CQ36: =SUM(CQ24:CQ35) -> 0 | CV36: =SUM(CV24:CV35) -> 0 | CX36: =SUM(CX24:CX35) -> 0 | CY36: =SUM(CY31:CY35) -> 0
B37: Semi-Consistent
I38: =COUNTIF(D38:H38,"PR") -> 0 | J38: =COUNTIF(D38:H38,"AB") -> 0 | K38: =I38+J38 -> 0 | P38: =COUNTIF(L38:O38,"PR") -> 0 | Q38: =COUNTIF(L38:O38,"AB") -> 0 | R38: =P38+Q38 -> 0 | W38: =COUNTIF(S38:V38,"PR") -> 0 | X38: =COUNTIF(S38:V38,"AB") -> 0 | Y38: =W38+X38 -> 0 | Z38: =K38+R38+Y38 -> 0 | AA38: =SUM(I38,P38,W38) -> 0 | AB38: =AA38/Z38*100 -> #DIV/0! | AH38: =COUNTIF(AD38:AG38,"PR") -> 0 | AI38: =COUNTIF(AD38:AG38,"AB") -> 0 | AJ38: =AH38+AI38 -> 0 | AP38: =COUNTIF(AK38:AO38,"PR") -> 0 | AQ38: =COUNTIF(AK38:AO38,"AB") -> 0 | AR38: =AP38+AQ38 -> 0 | AW38: =COUNTIF(AS38:AV38,"PR") -> 0 | AX38: =COUNTIF(AS38:AV38,"AB") -> 0 | AY38: =AW38+AX38 -> 0 | AZ38: =AJ38+AR38+AY38 -> 0 | BA38: =SUM(AH38,AP38,AW38) -> 0 | BB38: =BA38/AZ38*100 -> #DIV/0! | BG38: =COUNTIF(BC38:BF38,"PR") -> 0 | BH38: =COUNTIF(BC38:BF38,"AB") -> 0 | BI38: =BG38+BH38 -> 0 | BO38: =COUNTIF(BJ38:BN38,"PR") -> 0 | BP38: =COUNTIF(BJ38:BN38,"AB") -> 0 | BQ38: =BO38+BP38 -> 0 | BV38: =COUNTIF(BR38:BU38,"PR") -> 0 | BW38: =COUNTIF(BR38:BU38,"AB") -> 0 | BX38: =BV38+BW38 -> 0 | BY38: =BI38+BQ38+BX38 -> 0 | BZ38: =SUM(BG38,BO38,BV38) -> 0 | CA38: =BZ38/BY38*100 -> #DIV/0! | CH38: =COUNTIF(CC38:CG38,"PR") -> 0 | CI38: =COUNTIF(CC38:CG38,"AB") -> 0 | CJ38: =CH38+CI38 -> 0 | CO38: =COUNTIF(CK38:CN38,"PR") -> 0 | CP38: =COUNTIF(CK38:CN38,"AB") -> 0 | CQ38: =CO38+CP38 -> 0 | CV38: =COUNTIF(CR38:CU38,"PR") -> 0 | CW38: =COUNTIF(CR38:CU38,"AB") -> 0 | CX38: =CV38+CW38 -> 0 | CY38: =CH38+CO38+CV38 -> 0 | CZ38: =SUM(CF38,#REF!,CT38) -> #REF! | DA38: =CZ38/CY38*100 -> #REF!
I39: =COUNTIF(D39:H39,"PR") -> 0 | J39: =COUNTIF(D39:H39,"AB") -> 0 | K39: =I39+J39 -> 0 | P39: =COUNTIF(L39:O39,"PR") -> 0 | Q39: =COUNTIF(L39:O39,"AB") -> 0 | R39: =P39+Q39 -> 0 | W39: =COUNTIF(S39:V39,"PR") -> 0 | X39: =COUNTIF(S39:V39,"AB") -> 0 | Y39: =W39+X39 -> 0 | Z39: =K39+R39+Y39 -> 0 | AA39: =SUM(I39,P39,W39) -> 0 | AB39: =AA39/Z39*100 -> #DIV/0! | AH39: =COUNTIF(AD39:AG39,"PR") -> 0 | AI39: =COUNTIF(AD39:AG39,"AB") -> 0 | AJ39: =AH39+AI39 -> 0 | AP39: =COUNTIF(AK39:AO39,"PR") -> 0 | AQ39: =COUNTIF(AK39:AO39,"AB") -> 0 | AR39: =AP39+AQ39 -> 0 | AW39: =COUNTIF(AS39:AV39,"PR") -> 0 | AX39: =COUNTIF(AS39:AV39,"AB") -> 0 | AY39: =AW39+AX39 -> 0 | AZ39: =AJ39+AR39+AY39 -> 0 | BA39: =SUM(AH39,AP39,AW39) -> 0 | BB39: =BA39/AZ39*100 -> #DIV/0! | BG39: =COUNTIF(BC39:BF39,"PR") -> 0 | BH39: =COUNTIF(BC39:BF39,"AB") -> 0 | BI39: =BG39+BH39 -> 0 | BO39: =COUNTIF(BJ39:BN39,"PR") -> 0 | BP39: =COUNTIF(BJ39:BN39,"AB") -> 0 | BQ39: =BO39+BP39 -> 0 | BV39: =COUNTIF(BR39:BU39,"PR") -> 0 | BW39: =COUNTIF(BR39:BU39,"AB") -> 0 | BX39: =BV39+BW39 -> 0 | BY39: =BI39+BQ39+BX39 -> 0 | BZ39: =SUM(BG39,BO39,BV39) -> 0 | CA39: =BZ39/BY39*100 -> #DIV/0! | CH39: =COUNTIF(CC39:CG39,"PR") -> 0 | CI39: =COUNTIF(CC39:CG39,"AB") -> 0 | CJ39: =CH39+CI39 -> 0 | CO39: =COUNTIF(CK39:CN39,"PR") -> 0 | CP39: =COUNTIF(CK39:CN39,"AB") -> 0 | CQ39: =CO39+CP39 -> 0 | CV39: =COUNTIF(CR39:CU39,"PR") -> 0 | CW39: =COUNTIF(CR39:CU39,"AB") -> 0 | CX39: =CV39+CW39 -> 0 | CY39: =CH39+CO39+CV39 -> 0 | CZ39: =SUM(CF39,#REF!,CT39) -> #REF! | DA39: =CZ39/CY39*100 -> #REF!
I40: =COUNTIF(D40:H40,"PR") -> 0 | J40: =COUNTIF(D40:H40,"AB") -> 0 | K40: =I40+J40 -> 0 | P40: =COUNTIF(L40:O40,"PR") -> 0 | Q40: =COUNTIF(L40:O40,"AB") -> 0 | R40: =P40+Q40 -> 0 | W40: =COUNTIF(S40:V40,"PR") -> 0 | X40: =COUNTIF(S40:V40,"AB") -> 0 | Y40: =W40+X40 -> 0 | Z40: =K40+R40+Y40 -> 0 | AA40: =SUM(I40,P40,W40) -> 0 | AB40: =AA40/Z40*100 -> #DIV/0! | AH40: =COUNTIF(AD40:AG40,"PR") -> 0 | AI40: =COUNTIF(AD40:AG40,"AB") -> 0 | AJ40: =AH40+AI40 -> 0 | AP40: =COUNTIF(AK40:AO40,"PR") -> 0 | AQ40: =COUNTIF(AK40:AO40,"AB") -> 0 | AR40: =AP40+AQ40 -> 0 | AW40: =COUNTIF(AS40:AV40,"PR") -> 0 | AX40: =COUNTIF(AS40:AV40,"AB") -> 0 | AY40: =AW40+AX40 -> 0 | AZ40: =AJ40+AR40+AY40 -> 0 | BA40: =SUM(AH40,AP40,AW40) -> 0 | BB40: =BA40/AZ40*100 -> #DIV/0! | BG40: =COUNTIF(BC40:BF40,"PR") -> 0 | BH40: =COUNTIF(BC40:BF40,"AB") -> 0 | BI40: =BG40+BH40 -> 0 | BO40: =COUNTIF(BJ40:BN40,"PR") -> 0 | BP40: =COUNTIF(BJ40:BN40,"AB") -> 0 | BQ40: =BO40+BP40 -> 0 | BV40: =COUNTIF(BR40:BU40,"PR") -> 0 | BW40: =COUNTIF(BR40:BU40,"AB") -> 0 | BX40: =BV40+BW40 -> 0 | BY40: =BI40+BQ40+BX40 -> 0 | BZ40: =SUM(BG40,BO40,BV40) -> 0 | CA40: =BZ40/BY40*100 -> #DIV/0! | CH40: =COUNTIF(CC40:CG40,"PR") -> 0 | CI40: =COUNTIF(CC40:CG40,"AB") -> 0 | CJ40: =CH40+CI40 -> 0 | CO40: =COUNTIF(CK40:CN40,"PR") -> 0 | CP40: =COUNTIF(CK40:CN40,"AB") -> 0 | CQ40: =CO40+CP40 -> 0 | CV40: =COUNTIF(CR40:CU40,"PR") -> 0 | CW40: =COUNTIF(CR40:CU40,"AB") -> 0 | CX40: =CV40+CW40 -> 0 | CY40: =CH40+CO40+CV40 -> 0 | CZ40: =SUM(CF40,#REF!,CT40) -> #REF! | DA40: =CZ40/CY40*100 -> #REF!
I41: =COUNTIF(D41:H41,"PR") -> 0 | J41: =COUNTIF(D41:H41,"AB") -> 0 | K41: =I41+J41 -> 0 | P41: =COUNTIF(L41:O41,"PR") -> 0 | Q41: =COUNTIF(L41:O41,"AB") -> 0 | R41: =P41+Q41 -> 0 | W41: =COUNTIF(S41:V41,"PR") -> 0 | X41: =COUNTIF(S41:V41,"AB") -> 0 | Y41: =W41+X41 -> 0 | Z41: =K41+R41+Y41 -> 0 | AA41: =SUM(I41,P41,W41) -> 0 | AB41: =AA41/Z41*100 -> #DIV/0! | AH41: =COUNTIF(AD41:AG41,"PR") -> 0 | AI41: =COUNTIF(AD41:AG41,"AB") -> 0 | AJ41: =AH41+AI41 -> 0 | AP41: =COUNTIF(AK41:AO41,"PR") -> 0 | AQ41: =COUNTIF(AK41:AO41,"AB") -> 0 | AR41: =AP41+AQ41 -> 0 | AW41: =COUNTIF(AS41:AV41,"PR") -> 0 | AX41: =COUNTIF(AS41:AV41,"AB") -> 0 | AY41: =AW41+AX41 -> 0 | AZ41: =AJ41+AR41+AY41 -> 0 | BA41: =SUM(AH41,AP41,AW41) -> 0 | BB41: =BA41/AZ41*100 -> #DIV/0! | BG41: =COUNTIF(BC41:BF41,"PR") -> 0 | BH41: =COUNTIF(BC41:BF41,"AB") -> 0 | BI41: =BG41+BH41 -> 0 | BO41: =COUNTIF(BJ41:BN41,"PR") -> 0 | BP41: =COUNTIF(BJ41:BN41,"AB") -> 0 | BQ41: =BO41+BP41 -> 0 | BV41: =COUNTIF(BR41:BU41,"PR") -> 0 | BW41: =COUNTIF(BR41:BU41,"AB") -> 0 | BX41: =BV41+BW41 -> 0 | BY41: =BI41+BQ41+BX41 -> 0 | BZ41: =SUM(BG41,BO41,BV41) -> 0 | CA41: =BZ41/BY41*100 -> #DIV/0! | CH41: =COUNTIF(CC41:CG41,"PR") -> 0 | CI41: =COUNTIF(CC41:CG41,"AB") -> 0 | CJ41: =CH41+CI41 -> 0 | CO41: =COUNTIF(CK41:CN41,"PR") -> 0 | CP41: =COUNTIF(CK41:CN41,"AB") -> 0 | CQ41: =CO41+CP41 -> 0 | CV41: =COUNTIF(CR41:CU41,"PR") -> 0 | CW41: =COUNTIF(CR41:CU41,"AB") -> 0 | CX41: =CV41+CW41 -> 0 | CY41: =CH41+CO41+CV41 -> 0 | CZ41: =SUM(CF41,#REF!,CT41) -> #REF! | DA41: =CZ41/CY41*100 -> #REF!
...

Sheet Pal REPORTING DATA
B2: JAN | C2: MEA% | D2: FEB | E2: MEA% | F2: MAR | G2: MEA% | H2: QEA | I2: QEA% | J2: APR | K2: MEA% | L2: MAY | M2: MEA% | N2: JUN | O2: MEA% | P2: QEA | Q2: QEA% | R2: JUL | S2: MEA% | T2: AUG | U2: MEA% | V2: SEP | W2: MEA% | X2: QEA | Y2: QEA% | Z2: OCT | AA2: MEA% | AB2: NOV | AC2: MEA% | AD2: DEC | AE2: MEA% | AF2: QEA | AG2: QEA% | AH2: YRLY | AI2: YEA%
A3: EA | B3: ='Pal Group'!I352 -> 35 | C3: =B4/B3*100 -> 51.428571 | D3: ='Pal Group'!P352 -> 0 | E3: =D4/D3*100 -> #DIV/0! | F3: ='Pal Group'!W352 -> 0 | G3: =F4/F3*100 -> #REF! | H3: =B3+D3+F3 -> 35 | I3: =H4/H3*100 -> #REF! | J3: ='Pal Group'!AH352 -> 0 | K3: =J4/J3*100 -> #DIV/0! | L3: ='Pal Group'!AP352 -> 0 | M3: =L4/L3*100 -> #DIV/0! | N3: ='Pal Group'!AW352 -> 0 | O3: =N4/N3*100 -> #REF! | P3: =J3+L3+N3 -> 0 | Q3: =P4/P3*100 -> #REF! | R3: ='Pal Group'!BG352 -> 0 | S3: =R4/R3*100 -> #DIV/0! | T3: ='Pal Group'!BO352 -> 0 | U3: =T4/T3*100 -> #DIV/0! | V3: ='Pal Group'!BV352 -> 0 | W3: =V4/V3*100 -> #DIV/0! | X3: =R3+T3+V3 -> 0 | Y3: =X4/X3*100 -> #DIV/0! | Z3: ='Pal Group'!CH352 -> 0 | AA3: =Z4/Z3*100 -> #DIV/0! | AB3: ='Pal Group'!CO352 -> 0 | AC3: =AB4/AB3*100 -> #REF! | AD3: ='Pal Group'!CV352 -> 0 | AE3: =AD4/AD3*100 -> #DIV/0! | AF3: =Z3+AB3+AD3 -> 0 | AG3: =AF4/AF3*100 -> #REF! | AH3: =B3+D3+F3+J3+L3+N3+R3+T3+V3+Z3+AB3+AD3 -> 35 | AI3: =AH4/AH3*100 -> #REF!
A4: AA | B4: ='Pal Group'!D353 -> 18 | D4: ='Pal Group'!L353 -> 0 | F4: ='Pal Group'!S353 -> #REF! | H4: =B4+D4+F4 -> #REF! | J4: ='Pal Group'!AD353 -> 0 | L4: ='Pal Group'!AK353 -> 0 | N4: ='Pal Group'!AS353 -> #REF! | P4: =J4+L4+N4 -> #REF! | R4: ='Pal Group'!BC353 -> 0 | T4: ='Pal Group'!BJ353 -> 0 | V4: ='Pal Group'!BR353 -> 0 | X4: =R4+T4+V4 -> 0 | Z4: ='Pal Group'!CC353 -> 0 | AB4: ='Pal Group'!CK353 -> #REF! | AD4: ='Pal Group'!CR353 -> 0 | AF4: =Z4+AB4+AD4 -> #REF! | AH4: =B4+D4+F4+J4+L4+N4+R4+T4+V4+Z4+AB4+AD4 -> #REF!
A5: EA | B5: ='Pal Group'!K13 -> 9 | C5: =B6/B5*100 -> 88.888889 | D5: ='Pal Group'!R13 -> 0 | E5: =D6/D5*100 -> #DIV/0! | F5: ='Pal Group'!Y13 -> 0 | G5: =F6/F5*100 -> #DIV/0! | H5: =B5+D5+F5 -> 9 | I5: =H6/H5*100 -> 88.888889 | J5: ='Pal Group'!AJ13 -> 0 | K5: =J6/J5*100 -> #DIV/0! | L5: ='Pal Group'!AR13 -> 0 | M5: =L6/L5*100 -> #DIV/0! | N5: ='Pal Group'!AY13 -> 0 | O5: =N6/N5*100 -> #DIV/0! | P5: =J5+L5+N5 -> 0 | Q5: =P6/P5*100 -> #DIV/0! | R5: ='Pal Group'!BI13 -> 0 | S5: =R6/R5*100 -> #DIV/0! | T5: ='Pal Group'!BQ13 -> 0 | U5: =T6/T5*100 -> #DIV/0! | V5: ='Pal Group'!BX13 -> 0 | W5: =V6/V5*100 -> #DIV/0! | X5: =R5+T5+V5 -> 0 | Y5: =X6/X5*100 -> #DIV/0! | Z5: ='Pal Group'!CJ13 -> 0 | AA5: =Z6/Z5*100 -> #DIV/0! | AB5: ='Pal Group'!CQ13 -> 0 | AC5: =AB6/AB5*100 -> #DIV/0! | AD5: ='Pal Group'!CX13 -> 0 | AE5: =AD6/AD5*100 -> #DIV/0! | AF5: =Z5+AB5+AD5 -> 0 | AG5: =AF6/AF5*100 -> #DIV/0! | AH5: =B5+D5+F5+J5+L5+N5+R5+T5+V5+Z5+AB5+AD5 -> 9 | AI5: =AH6/AH5*100 -> 88.888889
A6: LEADERS | B6: ='Pal Group'!I13 -> 8 | D6: ='Pal Group'!P13 -> 0 | F6: ='Pal Group'!W13 -> 0 | H6: =B6+D6+F6 -> 8 | J6: ='Pal Group'!AH13 -> 0 | L6: ='Pal Group'!AP13 -> 0 | N6: ='Pal Group'!AP13 -> 0 | P6: =J6+L6+N6 -> 0 | R6: ='Pal Group'!BG13 -> 0 | T6: ='Pal Group'!BO13 -> 0 | V6: ='Pal Group'!BV13 -> 0 | X6: =R6+T6+V6 -> 0 | Z6: ='Pal Group'!CH13 -> 0 | AB6: ='Pal Group'!CO13 -> 0 | AD6: ='Pal Group'!CV13 -> 0 | AF6: =Z6+AB6+AD6 -> 0 | AH6: =B6+D6+F6+J6+L6+N6+R6+T6+V6+Z6+AB6+AD6 -> 8
A7: EA | B7: ='Pal Group'!K22 -> 21 | C7: =B8/B7*100 -> 71.428571 | D7: ='Pal Group'!R22 -> 0 | E7: =D8/D7*100 -> #DIV/0! | F7: ='Pal Group'!Y22 -> 0 | G7: =F8/F7*100 -> #DIV/0! | H7: =B7+D7+F7 -> 21 | I7: =H8/H7*100 -> 71.428571 | J7: ='Pal Group'!AJ22 -> 0 | K7: =J8/J7*100 -> #DIV/0! | L7: ='Pal Group'!AR22 -> 0 | M7: =L8/L7*100 -> #DIV/0! | N7: ='Pal Group'!AY22 -> 0 | O7: =N8/N7*100 -> #DIV/0! | P7: =J7+L7+N7 -> 0 | Q7: =P8/P7*100 -> #DIV/0! | R7: ='Pal Group'!BI22 -> 0 | S7: =R8/R7*100 -> #DIV/0! | T7: ='Pal Group'!BQ22 -> 0 | U7: =T8/T7*100 -> #DIV/0! | V7: ='Pal Group'!BX22 -> 0 | W7: =V8/V7*100 -> #DIV/0! | X7: =R7+T7+V7 -> 0 | Y7: =X8/X7*100 -> #DIV/0! | Z7: ='Pal Group'!CJ22 -> 0 | AA7: =Z8/Z7*100 -> #DIV/0! | AB7: ='Pal Group'!CQ22 -> 0 | AC7: =AB8/AB7*100 -> #DIV/0! | AD7: ='Pal Group'!CQ22 -> 0 | AE7: =AD8/AD7*100 -> #DIV/0! | AF7: =Z7+AB7+AD7 -> 0 | AG7: =AF8/AF7*100 -> #DIV/0! | AH7: =B7+D7+F7+J7+L7+N7+R7+T7+V7+Z7+AB7+AD7 -> 21 | AI7: =AH8/AH7*100 -> 71.428571
A8: INTENSE | B8: ='Pal Group'!I22 -> 15 | D8: ='Pal Group'!P22 -> 0 | F8: ='Pal Group'!W22 -> 0 | H8: =B8+D8+F8 -> 15 | J8: ='Pal Group'!AH22 -> 0 | L8: ='Pal Group'!AP22 -> 0 | N8: ='Pal Group'!AW22 -> 0 | P8: =J8+L8+N8 -> 0 | R8: ='Pal Group'!BG22 -> 0 | T8: ='Pal Group'!BO22 -> 0 | V8: ='Pal Group'!BV22 -> 0 | X8: =R8+T8+V8 -> 0 | Z8: ='Pal Group'!CH22 -> 0 | AB8: ='Pal Group'!CO22 -> 0 | AD8: ='Pal Group'!CV22 -> 0 | AF8: =Z8+AB8+AD8 -> 0 | AH8: =B8+D8+F8+J8+L8+N8+R8+T8+V8+Z8+AB8+AD8 -> 15
A9: EA | B9: ='Pal Group'!K36 -> 21 | C9: =B10/B9*100 -> 38.095238 | D9: ='Pal Group'!R36 -> 0 | E9: =D10/D9*100 -> #DIV/0! | F9: ='Pal Group'!Y36 -> 0 | G9: =F10/F9*100 -> #DIV/0! | H9: =B9+D9+F9 -> 21 | I9: =H10/H9*100 -> 38.095238 | J9: ='Pal Group'!AJ36 -> 0 | K9: =J10/J9*100 -> #DIV/0! | L9: ='Pal Group'!AR36 -> 0 | M9: =L10/L9*100 -> #DIV/0! | N9: ='Pal Group'!AY36 -> 0 | O9: =N10/N9*100 -> #DIV/0! | P9: =J9+L9+N9 -> 0 | Q9: =P10/P9*100 -> #DIV/0! | R9: ='Pal Group'!BI36 -> 0 | S9: =R10/R9*100 -> #DIV/0! | T9: ='Pal Group'!BQ36 -> 0 | U9: =T10/T9*100 -> #DIV/0! | V9: ='Pal Group'!BX36 -> 0 | W9: =V10/V9*100 -> #DIV/0! | X9: =R9+T9+V9 -> 0 | Y9: =X10/X9*100 -> #DIV/0! | Z9: ='Pal Group'!CJ36 -> 0 | AA9: =Z10/Z9*100 -> #DIV/0! | AB9: ='Pal Group'!CQ36 -> 0 | AC9: =AB10/AB9*100 -> #DIV/0! | AD9: ='Pal Group'!CX36 -> 0 | AE9: =AD10/AD9*100 -> #DIV/0! | AF9: =Z9+AB9+AD9 -> 0 | AG9: =AF10/AF9*100 -> #DIV/0! | AH9: =B9+D9+F9+J9+L9+N9+R9+T9+V9+Z9+AB9+AD9 -> 21 | AI9: =AH10/AH9*100 -> 38.095238
A10: CONSISTENT | B10: ='Pal Group'!I36 -> 8 | D10: ='Pal Group'!P36 -> 0 | F10: ='Pal Group'!W36 -> 0 | H10: =B10+D10+F10 -> 8 | J10: ='Pal Group'!AH36 -> 0 | L10: ='Pal Group'!AP36 -> 0 | N10: ='Pal Group'!AW36 -> 0 | P10: =J10+L10+N10 -> 0 | R10: ='Pal Group'!BG36 -> 0 | T10: ='Pal Group'!BO36 -> 0 | V10: ='Pal Group'!BV36 -> 0 | X10: =R10+T10+V10 -> 0 | Z10: ='Pal Group'!CH36 -> 0 | AB10: ='Pal Group'!CO36 -> 0 | AD10: ='Pal Group'!CV36 -> 0 | AF10: =Z10+AB10+AD10 -> 0 | AH10: =B10+D10+F10+J10+L10+N10+R10+T10+V10+Z10+AB10+AD10 -> 8
A11: EA | B11: ='Pal Group'!K138 -> 0 | C11: =B12/B11*100 -> #DIV/0! | D11: ='Pal Group'!R138 -> 0 | E11: =D12/D11*100 -> #DIV/0! | F11: ='Pal Group'!Y138 -> 0 | G11: =F12/F11*100 -> #DIV/0! | H11: =B11+D11+F11 -> 0 | I11: =H12/H11*100 -> #DIV/0! | J11: ='Pal Group'!AJ138 -> 0 | K11: =J12/J11*100 -> #DIV/0! | L11: ='Pal Group'!AR138 -> 0 | M11: =L12/L11*100 -> #DIV/0! | N11: ='Pal Group'!AY138 -> 0 | O11: =N12/N11*100 -> #DIV/0! | P11: =J11+L11+N11 -> 0 | Q11: =P12/P11*100 -> #DIV/0! | R11: ='Pal Group'!BI138 -> 0 | S11: =R12/R11*100 -> #DIV/0! | T11: ='Pal Group'!BQ138 -> 0 | U11: =T12/T11*100 -> #DIV/0! | V11: ='Pal Group'!BX138 -> 0 | W11: =V12/V11*100 -> #DIV/0! | X11: =R11+T11+V11 -> 0 | Y11: =X12/X11*100 -> #DIV/0! | Z11: ='Pal Group'!CJ138 -> 0 | AA11: =Z12/Z11*100 -> #DIV/0! | AB11: ='Pal Group'!CQ138 -> 0 | AC11: =AB12/AB11*100 -> #DIV/0! | AD11: ='Pal Group'!CX138 -> 0 | AE11: =AD12/AD11*100 -> #DIV/0! | AF11: =Z11+AB11+AD11 -> 0 | AG11: =AF12/AF11*100 -> #DIV/0! | AH11: =B11+D11+F11+J11+L11+N11+R11+T11+V11+Z11+AB11+AD11 -> 0 | AI11: =AH12/AH11*100 -> #DIV/0!
A12: SEMI-CONSISTENT | B12: ='Pal Group'!I138 -> 0 | D12: ='Pal Group'!P138 -> 0 | F12: ='Pal Group'!W138 -> 0 | H12: =B12+D12+F12 -> 0 | J12: ='Pal Group'!AH138 -> 0 | L12: ='Pal Group'!AP138 -> 0 | N12: ='Pal Group'!AW138 -> 0 | P12: =J12+L12+N12 -> 0 | R12: ='Pal Group'!BG138 -> 0 | T12: ='Pal Group'!BO138 -> 0 | V12: ='Pal Group'!BV138 -> 0 | X12: =R12+T12+V12 -> 0 | Z12: ='Pal Group'!CH138 -> 0 | AB12: ='Pal Group'!CO138 -> 0 | AD12: ='Pal Group'!CV138 -> 0 | AF12: =Z12+AB12+AD12 -> 0 | AH12: =B12+D12+F12+J12+L12+N12+R12+T12+V12+Z12+AB12+AD12 -> 0
A13: EA | B13: ='Pal Group'!K241 -> 0 | C13: =B14/B13*100 -> #DIV/0! | D13: ='Pal Group'!R241 -> 0 | E13: =D14/D13*100 -> #DIV/0! | F13: ='Pal Group'!Y241 -> 0 | G13: =F14/F13*100 -> #DIV/0! | H13: =B13+D13+F13 -> 0 | I13: =H14/H13*100 -> #DIV/0! | J13: ='Pal Group'!AJ241 -> 0 | K13: =J14/J13*100 -> #DIV/0! | L13: ='Pal Group'!AR241 -> 0 | M13: =L14/L13*100 -> #DIV/0! | N13: ='Pal Group'!AY241 -> 0 | O13: =N14/N13*100 -> #DIV/0! | P13: =J13+L13+N13 -> 0 | Q13: =P14/P13*100 -> #DIV/0! | R13: ='Pal Group'!BI241 -> 0 | S13: =R14/R13*100 -> #DIV/0! | T13: ='Pal Group'!BQ241 -> 0 | U13: =T14/T13*100 -> #DIV/0! | V13: ='Pal Group'!BX241 -> 0 | W13: =V14/V13*100 -> #DIV/0! | X13: =R13+T13+V13 -> 0 | Y13: =X14/X13*100 -> #DIV/0! | Z13: ='Pal Group'!CJ241 -> 0 | AA13: =Z14/Z13*100 -> #DIV/0! | AB13: ='Pal Group'!CQ241 -> 0 | AC13: =AB14/AB13*100 -> #DIV/0! | AD13: ='Pal Group'!CX241 -> 0 | AE13: =AD14/AD13*100 -> #DIV/0! | AF13: =Z13+AB13+AD13 -> 0 | AG13: =AF14/AF13*100 -> #DIV/0! | AH13: =B13+D13+F13+J13+L13+N13+R13+T13+V13+Z13+AB13+AD13 -> 0 | AI13: =AH14/AH13*100 -> #DIV/0!
A14: INCONSISTENT | B14: ='Pal Group'!I241 -> 0 | D14: ='Pal Group'!P241 -> 0 | F14: ='Pal Group'!W241 -> 0 | H14: =B14+D14+F14 -> 0 | J14: ='Pal Group'!AH241 -> 0 | L14: ='Pal Group'!AP241 -> 0 | N14: ='Pal Group'!AW241 -> 0 | P14: =J14+L14+N14 -> 0 | R14: ='Pal Group'!BG241 -> 0 | T14: ='Pal Group'!BO241 -> 0 | V14: ='Pal Group'!BV241 -> 0 | X14: =R14+T14+V14 -> 0 | Z14: ='Pal Group'!CH241 -> 0 | AB14: ='Pal Group'!CO241 -> 0 | AD14: ='Pal Group'!CV241 -> 0 | AF14: =Z14+AB14+AD14 -> 0 | AH14: =B14+D14+F14+J14+L14+N14+R14+T14+V14+Z14+AB14+AD14 -> 0
A15: WEEKLY AVERAGE | B15: ='Pal Group'!D354 -> 4.5 | D15: ='Pal Group'!L354 -> 0 | F15: ='Pal Group'!S354 -> #REF! | J15: ='Pal Group'!AD354 -> 0 | L15: ='Pal Group'!AK354 -> 0 | N15: ='Pal Group'!AS354 -> #REF! | R15: ='Pal Group'!BC354 -> 0 | T15: ='Pal Group'!BJ354 -> 0 | V15: ='Pal Group'!BR354 -> 0 | Z15: ='Pal Group'!CC354 -> 0 | AB15: ='Pal Group'!CK354 -> #REF! | AD15: ='Pal Group'!CR354 -> 0 | AH15: =SUM(B15:AD15)/12 -> #REF!
A16: QTRLY AVERAGE | H16: =Computation!AA3 -> 1.5 | P16: =Computation!AB3 -> #ERROR! | X16: =Computation!AC3 -> 0 | AF16: =Computation!AD3 -> 0 | AH16: =SUM(B16:AF16)/4 -> #ERROR!
