Workbook
Name Attended: #REF!

Sheet EMPOWERMENT GROUP
C1: January | K1: February | R1: March | AC1: April | AJ1: May | AR1: June | BB1: July | BI1: August | BQ1: September | CB1: October | CJ1: November | CQ1: December
A3: Members | B3: Contact | C3: Week 1 | D3: Week 2 | E3: Week 3 | F3: Week 4 | G3: Week 5 | K3: Week 6 | L3: Week 7 | M3: Week 8 | N3: Week 9 | R3: Week 10 | S3: Week 11 | T3: Week 12 | U3: Week 13 | AC3: Week 14 | AD3: Week 15 | AE3: Week 16 | AF3: Week 17 | AJ3: Week 18 | AK3: Week 19 | AL3: Week 20 | AM3: Week 21 | AN3: Week 22 | AR3: Week 23 | AS3: Week 24 | AT3: Week 25 | AU3: Week 26 | BB3: Week 27 | BC3: Week 28 | BD3: Week 29 | BE3: Week 30 | BI3: Week 31 | BJ3: Week 32 | BK3: Week 33 | BL3: Week 34 | BM3: Week 35 | BQ3: Week 36 | BR3: Week 37 | BS3: Week 38 | BT3: Week 39 | CB3: Week 40 | CC3: Week 41 | CD3: Week 42 | CE3: Week 43 | CF3: Week 44 | CJ3: Week 45 | CK3: Week 46 | CL3: Week 47 | CM3: Week 48 | CQ3: Week 49 | CR3: Week 50 | CS3: Week 51 | CT3: Week 52
A4: Leaders | H4: Present | I4: Absent | J4: PA | O4: Present | P4: Absent | Q4: PA | V4: Present | W4: Absent | X4: PA | Y4: TOTAL PA | Z4: Qtr Att | AA4: Qtr % | AB4: Comments | AG4: Present | AH4: Absent | AI4: PA | AO4: Present | AP4: Absent | AQ4: PA | AV4: Present | AW4: Absent | AX4: PA | AY4: TOTAL PA | AZ4: Qtr Att | BA4: Qtr % | BF4: Present | BG4: Absent | BH4: PA | BN4: Present | BO4: Absent | BP4: PA | BU4: Present | BV4: Absent | BW4: PA | BX4: TOTAL PA | BY4: Qtr Att | BZ4: Qtr % | CA4: Comments | CG4: Present | CH4: Absent | CI4: PA | CN4: Present | CO4: Absent | CP4: PA | CU4: Present | CV4: Absent | CW4: PA | CX4: TOTAL ATT | CY4: Qtr Att | CZ4: Qtr % | DA4: Comments
H5: =COUNTIF(C5:G5,"PR") -> 0 | I5: =COUNTIF(C5:G5,"AB") -> 0 | J5: =H5+I5 -> 0 | O5: =COUNTIF(K5:N5,"PR") -> 0 | P5: =COUNTIF(K5:N5,"AB") -> 0 | Q5: =O5+P5 -> 0 | V5: =COUNTIF(R5:U5,"PR") -> 0 | W5: =COUNTIF(R5:U5,"AB") -> 0 | X5: =V5+W5 -> 0 | Y5: =J5+Q5+X5 -> 0 | Z5: =SUM(H5,O5,V5) -> 0 | AA5: =Z5/Y5*100 -> #DIV/0! | AG5: =COUNTIF(AC5:AF5,"PR") -> 0 | AH5: =COUNTIF(AC5:AF5,"AB") -> 0 | AI5: =AG5+AH5 -> 0 | AO5: =COUNTIF(AJ5:AN5,"PR") -> 0 | AP5: =COUNTIF(AJ5:AN5,"AB") -> 0 | AQ5: =AO5+AP5 -> 0 | AV5: =COUNTIF(AR5:AU5,"PR") -> 0 | AW5: =COUNTIF(AR5:AU5,"AB") -> 0 | AX5: =AV5+AW5 -> 0 | AY5: =AI5+AQ5+AX5 -> 0 | AZ5: =SUM(AG5,AO5,AV5) -> 0 | BA5: =AZ5/AY5*100 -> #DIV/0! | BF5: =COUNTIF(BB5:BE5,"PR") -> 0 | BG5: =COUNTIF(BB5:BE5,"AB") -> 0 | BH5: =BF5+BG5 -> 0 | BN5: =COUNTIF(BI5:BM5,"PR") -> 0 | BO5: =COUNTIF(BI5:BM5,"AB") -> 0 | BP5: =BN5+BO5 -> 0 | BU5: =COUNTIF(BQ5:BT5,"PR") -> 0 | BV5: =COUNTIF(BQ5:BT5,"AB") -> 0 | BW5: =BU5+BV5 -> 0 | BX5: =BH5+BP5+BW5 -> 0 | BY5: =SUM(BF5,BN5,BU5) -> 0 | BZ5: =BY5/BX5*100 -> #DIV/0! | CG5: =COUNTIF(CB5:CF5,"PR") -> 0 | CH5: =COUNTIF(CB5:CF5,"AB") -> 0 | CI5: =CG5+CH5 -> 0 | CN5: =COUNTIF(CJ5:CM5,"PR") -> 0 | CO5: =COUNTIF(CJ5:CM5,"AB") -> 0 | CP5: =CN5+CO5 -> 0 | CU5: =COUNTIF(CQ5:CT5,"PR") -> 0 | CV5: =COUNTIF(CQ5:CT5,"AB") -> 0 | CW5: =CU5+CV5 -> 0 | CX5: =CG5+CN5+CU5 -> 0 | CY5: =SUM(CE5,#REF!,CS5) -> #REF! | CZ5: =CY5/CX5*100 -> #REF!
H6: =COUNTIF(C6:G6,"PR") -> 0 | I6: =COUNTIF(C6:G6,"AB") -> 0 | J6: =H6+I6 -> 0 | O6: =COUNTIF(K6:N6,"PR") -> 0 | P6: =COUNTIF(K6:N6,"AB") -> 0 | Q6: =O6+P6 -> 0 | V6: =COUNTIF(R6:U6,"PR") -> 0 | W6: =COUNTIF(R6:U6,"AB") -> 0 | X6: =V6+W6 -> 0 | Y6: =J6+Q6+X6 -> 0 | Z6: =SUM(H6,O6,V6) -> 0 | AA6: =Z6/Y6*100 -> #DIV/0! | AG6: =COUNTIF(AC6:AF6,"PR") -> 0 | AH6: =COUNTIF(AC6:AF6,"AB") -> 0 | AI6: =AG6+AH6 -> 0 | AO6: =COUNTIF(AJ6:AN6,"PR") -> 0 | AP6: =COUNTIF(AJ6:AN6,"AB") -> 0 | AQ6: =AO6+AP6 -> 0 | AV6: =COUNTIF(AR6:AU6,"PR") -> 0 | AW6: =COUNTIF(AR6:AU6,"AB") -> 0 | AX6: =AV6+AW6 -> 0 | AY6: =AI6+AQ6+AX6 -> 0 | AZ6: =SUM(AG6,AO6,AV6) -> 0 | BA6: =AZ6/AY6*100 -> #DIV/0! | BF6: =COUNTIF(BB6:BE6,"PR") -> 0 | BG6: =COUNTIF(BB6:BE6,"AB") -> 0 | BH6: =BF6+BG6 -> 0 | BN6: =COUNTIF(BI6:BM6,"PR") -> 0 | BO6: =COUNTIF(BI6:BM6,"AB") -> 0 | BP6: =BN6+BO6 -> 0 | BU6: =COUNTIF(BQ6:BT6,"PR") -> 0 | BV6: =COUNTIF(BQ6:BT6,"AB") -> 0 | BW6: =BU6+BV6 -> 0 | BX6: =BH6+BP6+BW6 -> 0 | BY6: =SUM(BF6,BN6,BU6) -> 0 | BZ6: =BY6/BX6*100 -> #DIV/0! | CG6: =COUNTIF(CB6:CF6,"PR") -> 0 | CH6: =COUNTIF(CB6:CF6,"AB") -> 0 | CI6: =CG6+CH6 -> 0 | CN6: =COUNTIF(CJ6:CM6,"PR") -> 0 | CO6: =COUNTIF(CJ6:CM6,"AB") -> 0 | CP6: =CN6+CO6 -> 0 | CU6: =COUNTIF(CQ6:CT6,"PR") -> 0 | CV6: =COUNTIF(CQ6:CT6,"AB") -> 0 | CW6: =CU6+CV6 -> 0 | CX6: =CG6+CN6+CU6 -> 0 | CY6: =SUM(CE6,#REF!,CS6) -> #REF! | CZ6: =CY6/CX6*100 -> #REF!
H7: =COUNTIF(C7:G7,"PR") -> 0 | I7: =COUNTIF(C7:G7,"AB") -> 0 | J7: =H7+I7 -> 0 | O7: =COUNTIF(K7:N7,"PR") -> 0 | P7: =COUNTIF(K7:N7,"AB") -> 0 | Q7: =O7+P7 -> 0 | V7: =COUNTIF(R7:U7,"PR") -> 0 | W7: =COUNTIF(R7:U7,"AB") -> 0 | X7: =V7+W7 -> 0 | Y7: =J7+Q7+X7 -> 0 | Z7: =SUM(H7,O7,V7) -> 0 | AA7: =Z7/Y7*100 -> #DIV/0! | AG7: =COUNTIF(AC7:AF7,"PR") -> 0 | AH7: =COUNTIF(AC7:AF7,"AB") -> 0 | AI7: =AG7+AH7 -> 0 | AO7: =COUNTIF(AJ7:AN7,"PR") -> 0 | AP7: =COUNTIF(AJ7:AN7,"AB") -> 0 | AQ7: =AO7+AP7 -> 0 | AV7: =COUNTIF(AR7:AU7,"PR") -> 0 | AW7: =COUNTIF(AR7:AU7,"AB") -> 0 | AX7: =AV7+AW7 -> 0 | AY7: =AI7+AQ7+AX7 -> 0 | AZ7: =SUM(AG7,AO7,AV7) -> 0 | BA7: =AZ7/AY7*100 -> #DIV/0! | BF7: =COUNTIF(BB7:BE7,"PR") -> 0 | BG7: =COUNTIF(BB7:BE7,"AB") -> 0 | BH7: =BF7+BG7 -> 0 | BN7: =COUNTIF(BI7:BM7,"PR") -> 0 | BO7: =COUNTIF(BI7:BM7,"AB") -> 0 | BP7: =BN7+BO7 -> 0 | BU7: =COUNTIF(BQ7:BT7,"PR") -> 0 | BV7: =COUNTIF(BQ7:BT7,"AB") -> 0 | BW7: =BU7+BV7 -> 0 | BX7: =BH7+BP7+BW7 -> 0 | BY7: =SUM(BF7,BN7,BU7) -> 0 | BZ7: =BY7/BX7*100 -> #DIV/0! | CG7: =COUNTIF(CB7:CF7,"PR") -> 0 | CH7: =COUNTIF(CB7:CF7,"AB") -> 0 | CI7: =CG7+CH7 -> 0 | CN7: =COUNTIF(CJ7:CM7,"PR") -> 0 | CO7: =COUNTIF(CJ7:CM7,"AB") -> 0 | CP7: =CN7+CO7 -> 0 | CU7: =COUNTIF(CQ7:CT7,"PR") -> 0 | CV7: =COUNTIF(CQ7:CT7,"AB") -> 0 | CW7: =CU7+CV7 -> 0 | CX7: =CG7+CN7+CU7 -> 0 | CY7: =SUM(CE7,#REF!,CS7) -> #REF! | CZ7: =CY7/CX7*100 -> #REF!
H8: =COUNTIF(C8:G8,"PR") -> 0 | I8: =COUNTIF(C8:G8,"AB") -> 0 | J8: =H8+I8 -> 0 | O8: =COUNTIF(K8:N8,"PR") -> 0 | P8: =COUNTIF(K8:N8,"AB") -> 0 | Q8: =O8+P8 -> 0 | V8: =COUNTIF(R8:U8,"PR") -> 0 | W8: =COUNTIF(R8:U8,"AB") -> 0 | X8: =V8+W8 -> 0 | Y8: =J8+Q8+X8 -> 0 | Z8: =SUM(H8,O8,V8) -> 0 | AA8: =Z8/Y8*100 -> #DIV/0! | AG8: =COUNTIF(AC8:AF8,"PR") -> 0 | AH8: =COUNTIF(AC8:AF8,"AB") -> 0 | AI8: =AG8+AH8 -> 0 | AO8: =COUNTIF(AJ8:AN8,"PR") -> 0 | AP8: =COUNTIF(AJ8:AN8,"AB") -> 0 | AQ8: =AO8+AP8 -> 0 | AV8: =COUNTIF(AR8:AU8,"PR") -> 0 | AW8: =COUNTIF(AR8:AU8,"AB") -> 0 | AX8: =AV8+AW8 -> 0 | AY8: =AI8+AQ8+AX8 -> 0 | AZ8: =SUM(AG8,AO8,AV8) -> 0 | BA8: =AZ8/AY8*100 -> #DIV/0! | BF8: =COUNTIF(BB8:BE8,"PR") -> 0 | BG8: =COUNTIF(BB8:BE8,"AB") -> 0 | BH8: =BF8+BG8 -> 0 | BN8: =COUNTIF(BI8:BM8,"PR") -> 0 | BO8: =COUNTIF(BI8:BM8,"AB") -> 0 | BP8: =BN8+BO8 -> 0 | BU8: =COUNTIF(BQ8:BT8,"PR") -> 0 | BV8: =COUNTIF(BQ8:BT8,"AB") -> 0 | BW8: =BU8+BV8 -> 0 | BX8: =BH8+BP8+BW8 -> 0 | BY8: =SUM(BF8,BN8,BU8) -> 0 | BZ8: =BY8/BX8*100 -> #DIV/0! | CG8: =COUNTIF(CB8:CF8,"PR") -> 0 | CH8: =COUNTIF(CB8:CF8,"AB") -> 0 | CI8: =CG8+CH8 -> 0 | CN8: =COUNTIF(CJ8:CM8,"PR") -> 0 | CO8: =COUNTIF(CJ8:CM8,"AB") -> 0 | CP8: =CN8+CO8 -> 0 | CU8: =COUNTIF(CQ8:CT8,"PR") -> 0 | CV8: =COUNTIF(CQ8:CT8,"AB") -> 0 | CW8: =CU8+CV8 -> 0 | CX8: =CG8+CN8+CU8 -> 0 | CY8: =SUM(CE8,#REF!,CS8) -> #REF! | CZ8: =CY8/CX8*100 -> #REF!
H9: =COUNTIF(C9:G9,"PR") -> 0 | I9: =COUNTIF(C9:G9,"AB") -> 0 | J9: =H9+I9 -> 0 | O9: =COUNTIF(K9:N9,"PR") -> 0 | P9: =COUNTIF(K9:N9,"AB") -> 0 | Q9: =O9+P9 -> 0 | V9: =COUNTIF(R9:U9,"PR") -> 0 | W9: =COUNTIF(R9:U9,"AB") -> 0 | X9: =V9+W9 -> 0 | Y9: =J9+Q9+X9 -> 0 | Z9: =SUM(H9,O9,V9) -> 0 | AA9: =Z9/Y9*100 -> #DIV/0! | AG9: =COUNTIF(AC9:AF9,"PR") -> 0 | AH9: =COUNTIF(AC9:AF9,"AB") -> 0 | AI9: =AG9+AH9 -> 0 | AO9: =COUNTIF(AJ9:AN9,"PR") -> 0 | AP9: =COUNTIF(AJ9:AN9,"AB") -> 0 | AQ9: =AO9+AP9 -> 0 | AV9: =COUNTIF(AR9:AU9,"PR") -> 0 | AW9: =COUNTIF(AR9:AU9,"AB") -> 0 | AX9: =AV9+AW9 -> 0 | AY9: =AI9+AQ9+AX9 -> 0 | AZ9: =SUM(AG9,AO9,AV9) -> 0 | BA9: =AZ9/AY9*100 -> #DIV/0! | BF9: =COUNTIF(BB9:BE9,"PR") -> 0 | BG9: =COUNTIF(BB9:BE9,"AB") -> 0 | BH9: =BF9+BG9 -> 0 | BN9: =COUNTIF(BI9:BM9,"PR") -> 0 | BO9: =COUNTIF(BI9:BM9,"AB") -> 0 | BP9: =BN9+BO9 -> 0 | BU9: =COUNTIF(BQ9:BT9,"PR") -> 0 | BV9: =COUNTIF(BQ9:BT9,"AB") -> 0 | BW9: =BU9+BV9 -> 0 | BX9: =BH9+BP9+BW9 -> 0 | BY9: =SUM(BF9,BN9,BU9) -> 0 | BZ9: =BY9/BX9*100 -> #DIV/0! | CG9: =COUNTIF(CB9:CF9,"PR") -> 0 | CH9: =COUNTIF(CB9:CF9,"AB") -> 0 | CI9: =CG9+CH9 -> 0 | CN9: =COUNTIF(CJ9:CM9,"PR") -> 0 | CO9: =COUNTIF(CJ9:CM9,"AB") -> 0 | CP9: =CN9+CO9 -> 0 | CU9: =COUNTIF(CQ9:CT9,"PR") -> 0 | CV9: =COUNTIF(CQ9:CT9,"AB") -> 0 | CW9: =CU9+CV9 -> 0 | CX9: =CG9+CN9+CU9 -> 0 | CY9: =SUM(CE9,#REF!,CS9) -> #REF! | CZ9: =CY9/CX9*100 -> #REF!
H10: =COUNTIF(C10:G10,"PR") -> 0 | I10: =COUNTIF(C10:G10,"AB") -> 0 | J10: =H10+I10 -> 0 | O10: =COUNTIF(K10:N10,"PR") -> 0 | P10: =COUNTIF(K10:N10,"AB") -> 0 | Q10: =O10+P10 -> 0 | V10: =COUNTIF(R10:U10,"PR") -> 0 | W10: =COUNTIF(R10:U10,"AB") -> 0 | X10: =V10+W10 -> 0 | Y10: =J10+Q10+X10 -> 0 | Z10: =SUM(H10,O10,V10) -> 0 | AA10: =Z10/Y10*100 -> #DIV/0! | AG10: =COUNTIF(AC10:AF10,"PR") -> 0 | AH10: =COUNTIF(AC10:AF10,"AB") -> 0 | AI10: =AG10+AH10 -> 0 | AO10: =COUNTIF(AJ10:AN10,"PR") -> 0 | AP10: =COUNTIF(AJ10:AN10,"AB") -> 0 | AQ10: =AO10+AP10 -> 0 | AV10: =COUNTIF(AR10:AU10,"PR") -> 0 | AW10: =COUNTIF(AR10:AU10,"AB") -> 0 | AX10: =AV10+AW10 -> 0 | AY10: =AI10+AQ10+AX10 -> 0 | AZ10: =SUM(AG10,AO10,AV10) -> 0 | BA10: =AZ10/AY10*100 -> #DIV/0! | BF10: =COUNTIF(BB10:BE10,"PR") -> 0 | BG10: =COUNTIF(BB10:BE10,"AB") -> 0 | BH10: =BF10+BG10 -> 0 | BN10: =COUNTIF(BI10:BM10,"PR") -> 0 | BO10: =COUNTIF(BI10:BM10,"AB") -> 0 | BP10: =BN10+BO10 -> 0 | BU10: =COUNTIF(BQ10:BT10,"PR") -> 0 | BV10: =COUNTIF(BQ10:BT10,"AB") -> 0 | BW10: =BU10+BV10 -> 0 | BX10: =BH10+BP10+BW10 -> 0 | BY10: =SUM(BF10,BN10,BU10) -> 0 | BZ10: =BY10/BX10*100 -> #DIV/0! | CG10: =COUNTIF(CB10:CF10,"PR") -> 0 | CH10: =COUNTIF(CB10:CF10,"AB") -> 0 | CI10: =CG10+CH10 -> 0 | CN10: =COUNTIF(CJ10:CM10,"PR") -> 0 | CO10: =COUNTIF(CJ10:CM10,"AB") -> 0 | CP10: =CN10+CO10 -> 0 | CU10: =COUNTIF(CQ10:CT10,"PR") -> 0 | CV10: =COUNTIF(CQ10:CT10,"AB") -> 0 | CW10: =CU10+CV10 -> 0 | CX10: =CG10+CN10+CU10 -> 0 | CY10: =SUM(CE10,#REF!,CS10) -> #REF! | CZ10: =CY10/CX10*100 -> #REF!
H11: =COUNTIF(C11:G11,"PR") -> 0 | I11: =COUNTIF(C11:G11,"AB") -> 0 | J11: =H11+I11 -> 0 | O11: =COUNTIF(K11:N11,"PR") -> 0 | P11: =COUNTIF(K11:N11,"AB") -> 0 | Q11: =O11+P11 -> 0 | V11: =COUNTIF(R11:U11,"PR") -> 0 | W11: =COUNTIF(R11:U11,"AB") -> 0 | X11: =V11+W11 -> 0 | Y11: =J11+Q11+X11 -> 0 | Z11: =SUM(H11,O11,V11) -> 0 | AA11: =Z11/Y11*100 -> #DIV/0! | AG11: =COUNTIF(AC11:AF11,"PR") -> 0 | AH11: =COUNTIF(AC11:AF11,"AB") -> 0 | AI11: =AG11+AH11 -> 0 | AO11: =COUNTIF(AJ11:AN11,"PR") -> 0 | AP11: =COUNTIF(AJ11:AN11,"AB") -> 0 | AQ11: =AO11+AP11 -> 0 | AV11: =COUNTIF(AR11:AU11,"PR") -> 0 | AW11: =COUNTIF(AR11:AU11,"AB") -> 0 | AX11: =AV11+AW11 -> 0 | AY11: =AI11+AQ11+AX11 -> 0 | AZ11: =SUM(AG11,AO11,AV11) -> 0 | BA11: =AZ11/AY11*100 -> #DIV/0! | BF11: =COUNTIF(BB11:BE11,"PR") -> 0 | BG11: =COUNTIF(BB11:BE11,"AB") -> 0 | BH11: =BF11+BG11 -> 0 | BN11: =COUNTIF(BI11:BM11,"PR") -> 0 | BO11: =COUNTIF(BI11:BM11,"AB") -> 0 | BP11: =BN11+BO11 -> 0 | BU11: =COUNTIF(BQ11:BT11,"PR") -> 0 | BV11: =COUNTIF(BQ11:BT11,"AB") -> 0 | BW11: =BU11+BV11 -> 0 | BX11: =BH11+BP11+BW11 -> 0 | BY11: =SUM(BF11,BN11,BU11) -> 0 | BZ11: =BY11/BX11*100 -> #DIV/0! | CG11: =COUNTIF(CB11:CF11,"PR") -> 0 | CH11: =COUNTIF(CB11:CF11,"AB") -> 0 | CI11: =CG11+CH11 -> 0 | CN11: =COUNTIF(CJ11:CM11,"PR") -> 0 | CO11: =COUNTIF(CJ11:CM11,"AB") -> 0 | CP11: =CN11+CO11 -> 0 | CU11: =COUNTIF(CQ11:CT11,"PR") -> 0 | CV11: =COUNTIF(CQ11:CT11,"AB") -> 0 | CW11: =CU11+CV11 -> 0 | CX11: =CG11+CN11+CU11 -> 0 | CY11: =SUM(CE11,#REF!,CS11) -> #REF! | CZ11: =CY11/CX11*100 -> #REF!
H12: =COUNTIF(C12:G12,"PR") -> 0 | I12: =COUNTIF(C12:G12,"AB") -> 0 | J12: =H12+I12 -> 0 | O12: =COUNTIF(K12:N12,"PR") -> 0 | P12: =COUNTIF(K12:N12,"AB") -> 0 | Q12: =O12+P12 -> 0 | V12: =COUNTIF(R12:U12,"PR") -> 0 | W12: =COUNTIF(R12:U12,"AB") -> 0 | X12: =V12+W12 -> 0 | Y12: =J12+Q12+X12 -> 0 | Z12: =SUM(H12,O12,V12) -> 0 | AA12: =Z12/Y12*100 -> #DIV/0! | AG12: =COUNTIF(AC12:AF12,"PR") -> 0 | AH12: =COUNTIF(AC12:AF12,"AB") -> 0 | AI12: =AG12+AH12 -> 0 | AO12: =COUNTIF(AJ12:AN12,"PR") -> 0 | AP12: =COUNTIF(AJ12:AN12,"AB") -> 0 | AQ12: =AO12+AP12 -> 0 | AV12: =COUNTIF(AR12:AU12,"PR") -> 0 | AW12: =COUNTIF(AR12:AU12,"AB") -> 0 | AX12: =AV12+AW12 -> 0 | AY12: =AI12+AQ12+AX12 -> 0 | AZ12: =SUM(AG12,AO12,AV12) -> 0 | BA12: =AZ12/AY12*100 -> #DIV/0! | BF12: =COUNTIF(BB12:BE12,"PR") -> 0 | BG12: =COUNTIF(BB12:BE12,"AB") -> 0 | BH12: =BF12+BG12 -> 0 | BN12: =COUNTIF(BI12:BM12,"PR") -> 0 | BO12: =COUNTIF(BI12:BM12,"AB") -> 0 | BP12: =BN12+BO12 -> 0 | BU12: =COUNTIF(BQ12:BT12,"PR") -> 0 | BV12: =COUNTIF(BQ12:BT12,"AB") -> 0 | BW12: =BU12+BV12 -> 0 | BX12: =BH12+BP12+BW12 -> 0 | BY12: =SUM(BF12,BN12,BU12) -> 0 | BZ12: =BY12/BX12*100 -> #DIV/0! | CG12: =COUNTIF(CB12:CF12,"PR") -> 0 | CH12: =COUNTIF(CB12:CF12,"AB") -> 0 | CI12: =CG12+CH12 -> 0 | CN12: =COUNTIF(CJ12:CM12,"PR") -> 0 | CO12: =COUNTIF(CJ12:CM12,"AB") -> 0 | CP12: =CN12+CO12 -> 0 | CU12: =COUNTIF(CQ12:CT12,"PR") -> 0 | CV12: =COUNTIF(CQ12:CT12,"AB") -> 0 | CW12: =CU12+CV12 -> 0 | CX12: =CG12+CN12+CU12 -> 0 | CY12: =SUM(CE12,#REF!,CS12) -> #REF! | CZ12: =CY12/CX12*100 -> #REF!
H13: =SUM(H5:H12) -> 0 | J13: =SUM(J5:J12) -> 0 | O13: =SUM(O5:O12) -> 0 | Q13: =SUM(Q5:Q12) -> 0 | V13: =SUM(V5:V12) -> 0 | X13: =SUM(X5:X12) -> 0 | Y13: =SUM(Y5:Y12) -> 0 | AG13: =SUM(AG5:AG12) -> 0 | AI13: =SUM(AI5:AI12) -> 0 | AO13: =SUM(AO5:AO12) -> 0 | AQ13: =SUM(AQ5:AQ12) -> 0 | AV13: =SUM(AV5:AV12) -> 0 | AX13: =SUM(AX5:AX12) -> 0 | AY13: =SUM(AY5:AY12) -> 0 | AZ13: =SUM(AG13,AO13,AV13) -> 0 | BF13: =SUM(BF5:BF12) -> 0 | BH13: =SUM(BH5:BH12) -> 0 | BN13: =SUM(BN5:BN12) -> 0 | BP13: =SUM(BP5:BP12) -> 0 | BU13: =SUM(BU5:BU12) -> 0 | BW13: =SUM(BW5:BW12) -> 0 | BX13: =SUM(BX5:BX12) -> 0 | CG13: =SUM(CG5:CG12) -> 0 | CI13: =SUM(CI5:CI12) -> 0 | CN13: =SUM(CN5:CN12) -> 0 | CP13: =SUM(CP5:CP12) -> 0 | CU13: =SUM(CU5:CU12) -> 0 | CW13: =SUM(CW5:CW12) -> 0 | CX13: =SUM(CX5:CX12) -> 0
A14: Intense
H15: =COUNTIF(C15:G15,"PR") -> 0 | I15: =COUNTIF(C15:G15,"AB") -> 0 | J15: =H15+I15 -> 0 | O15: =COUNTIF(K15:N15,"PR") -> 0 | P15: =COUNTIF(K15:N15,"AB") -> 0 | Q15: =O15+P15 -> 0 | V15: =COUNTIF(R15:U15,"PR") -> 0 | W15: =COUNTIF(R15:U15,"AB") -> 0 | X15: =V15+W15 -> 0 | Y15: =J15+Q15+X15 -> 0 | Z15: =SUM(H15,O15,V15) -> 0 | AA15: =Z15/Y15*100 -> #DIV/0! | AG15: =COUNTIF(AC15:AF15,"PR") -> 0 | AH15: =COUNTIF(AC15:AF15,"AB") -> 0 | AI15: =AG15+AH15 -> 0 | AO15: =COUNTIF(AJ15:AN15,"PR") -> 0 | AP15: =COUNTIF(AJ15:AN15,"AB") -> 0 | AQ15: =AO15+AP15 -> 0 | AV15: =COUNTIF(AR15:AU15,"PR") -> 0 | AW15: =COUNTIF(AR15:AU15,"AB") -> 0 | AX15: =AV15+AW15 -> 0 | AY15: =AI15+AQ15+AX15 -> 0 | AZ15: =SUM(AG15,AO15,AV15) -> 0 | BA15: =AZ15/AY15*100 -> #DIV/0! | BF15: =COUNTIF(BB15:BE15,"PR") -> 0 | BG15: =COUNTIF(BB15:BE15,"AB") -> 0 | BH15: =BF15+BG15 -> 0 | BN15: =COUNTIF(BI15:BM15,"PR") -> 0 | BO15: =COUNTIF(BI15:BM15,"AB") -> 0 | BP15: =BN15+BO15 -> 0 | BU15: =COUNTIF(BQ15:BT15,"PR") -> 0 | BV15: =COUNTIF(BQ15:BT15,"AB") -> 0 | BW15: =BU15+BV15 -> 0 | BX15: =BH15+BP15+BW15 -> 0 | BY15: =SUM(BF15,BN15,BU15) -> 0 | BZ15: =BY15/BX15*100 -> #DIV/0! | CG15: =COUNTIF(CB15:CF15,"PR") -> 0 | CH15: =COUNTIF(CB15:CF15,"AB") -> 0 | CI15: =CG15+CH15 -> 0 | CN15: =COUNTIF(CJ15:CM15,"PR") -> 0 | CO15: =COUNTIF(CJ15:CM15,"AB") -> 0 | CP15: =CN15+CO15 -> 0 | CU15: =COUNTIF(CQ15:CT15,"PR") -> 0 | CV15: =COUNTIF(CQ15:CT15,"AB") -> 0 | CW15: =CU15+CV15 -> 0 | CX15: =CG15+CN15+CU15 -> 0 | CY15: =SUM(CE15,#REF!,CS15) -> #REF! | CZ15: =CY15/CX15*100 -> #REF!
H16: =COUNTIF(C16:G16,"PR") -> 0 | I16: =COUNTIF(C16:G16,"AB") -> 0 | J16: =H16+I16 -> 0 | O16: =COUNTIF(K16:N16,"PR") -> 0 | P16: =COUNTIF(K16:N16,"AB") -> 0 | Q16: =O16+P16 -> 0 | V16: =COUNTIF(R16:U16,"PR") -> 0 | W16: =COUNTIF(R16:U16,"AB") -> 0 | X16: =V16+W16 -> 0 | Y16: =J16+Q16+X16 -> 0 | Z16: =SUM(H16,O16,V16) -> 0 | AA16: =Z16/Y16*100 -> #DIV/0! | AG16: =COUNTIF(AC16:AF16,"PR") -> 0 | AH16: =COUNTIF(AC16:AF16,"AB") -> 0 | AI16: =AG16+AH16 -> 0 | AO16: =COUNTIF(AJ16:AN16,"PR") -> 0 | AP16: =COUNTIF(AJ16:AN16,"AB") -> 0 | AQ16: =AO16+AP16 -> 0 | AV16: =COUNTIF(AR16:AU16,"PR") -> 0 | AW16: =COUNTIF(AR16:AU16,"AB") -> 0 | AX16: =AV16+AW16 -> 0 | AY16: =AI16+AQ16+AX16 -> 0 | AZ16: =SUM(AG16,AO16,AV16) -> 0 | BA16: =AZ16/AY16*100 -> #DIV/0! | BF16: =COUNTIF(BB16:BE16,"PR") -> 0 | BG16: =COUNTIF(BB16:BE16,"AB") -> 0 | BH16: =BF16+BG16 -> 0 | BN16: =COUNTIF(BI16:BM16,"PR") -> 0 | BO16: =COUNTIF(BI16:BM16,"AB") -> 0 | BP16: =BN16+BO16 -> 0 | BU16: =COUNTIF(BQ16:BT16,"PR") -> 0 | BV16: =COUNTIF(BQ16:BT16,"AB") -> 0 | BW16: =BU16+BV16 -> 0 | BX16: =BH16+BP16+BW16 -> 0 | BY16: =SUM(BF16,BN16,BU16) -> 0 | BZ16: =BY16/BX16*100 -> #DIV/0! | CG16: =COUNTIF(CB16:CF16,"PR") -> 0 | CH16: =COUNTIF(CB16:CF16,"AB") -> 0 | CI16: =CG16+CH16 -> 0 | CN16: =COUNTIF(CJ16:CM16,"PR") -> 0 | CO16: =COUNTIF(CJ16:CM16,"AB") -> 0 | CP16: =CN16+CO16 -> 0 | CU16: =COUNTIF(CQ16:CT16,"PR") -> 0 | CV16: =COUNTIF(CQ16:CT16,"AB") -> 0 | CW16: =CU16+CV16 -> 0 | CX16: =CG16+CN16+CU16 -> 0 | CY16: =SUM(CE16,#REF!,CS16) -> #REF! | CZ16: =CY16/CX16*100 -> #REF!
H17: =COUNTIF(C17:G17,"PR") -> 0 | I17: =COUNTIF(C17:G17,"AB") -> 0 | J17: =H17+I17 -> 0 | O17: =COUNTIF(K17:N17,"PR") -> 0 | P17: =COUNTIF(K17:N17,"AB") -> 0 | Q17: =O17+P17 -> 0 | V17: =COUNTIF(R17:U17,"PR") -> 0 | W17: =COUNTIF(R17:U17,"AB") -> 0 | X17: =V17+W17 -> 0 | Y17: =J17+Q17+X17 -> 0 | Z17: =SUM(H17,O17,V17) -> 0 | AA17: =Z17/Y17*100 -> #DIV/0! | AG17: =COUNTIF(AC17:AF17,"PR") -> 0 | AH17: =COUNTIF(AC17:AF17,"AB") -> 0 | AI17: =AG17+AH17 -> 0 | AO17: =COUNTIF(AJ17:AN17,"PR") -> 0 | AP17: =COUNTIF(AJ17:AN17,"AB") -> 0 | AQ17: =AO17+AP17 -> 0 | AV17: =COUNTIF(AR17:AU17,"PR") -> 0 | AW17: =COUNTIF(AR17:AU17,"AB") -> 0 | AX17: =AV17+AW17 -> 0 | AY17: =AI17+AQ17+AX17 -> 0 | AZ17: =SUM(AG17,AO17,AV17) -> 0 | BA17: =AZ17/AY17*100 -> #DIV/0! | BF17: =COUNTIF(BB17:BE17,"PR") -> 0 | BG17: =COUNTIF(BB17:BE17,"AB") -> 0 | BH17: =BF17+BG17 -> 0 | BN17: =COUNTIF(BI17:BM17,"PR") -> 0 | BO17: =COUNTIF(BI17:BM17,"AB") -> 0 | BP17: =BN17+BO17 -> 0 | BU17: =COUNTIF(BQ17:BT17,"PR") -> 0 | BV17: =COUNTIF(BQ17:BT17,"AB") -> 0 | BW17: =BU17+BV17 -> 0 | BX17: =BH17+BP17+BW17 -> 0 | BY17: =SUM(BF17,BN17,BU17) -> 0 | BZ17: =BY17/BX17*100 -> #DIV/0! | CG17: =COUNTIF(CB17:CF17,"PR") -> 0 | CH17: =COUNTIF(CB17:CF17,"AB") -> 0 | CI17: =CG17+CH17 -> 0 | CN17: =COUNTIF(CJ17:CM17,"PR") -> 0 | CO17: =COUNTIF(CJ17:CM17,"AB") -> 0 | CP17: =CN17+CO17 -> 0 | CU17: =COUNTIF(CQ17:CT17,"PR") -> 0 | CV17: =COUNTIF(CQ17:CT17,"AB") -> 0 | CW17: =CU17+CV17 -> 0 | CX17: =CG17+CN17+CU17 -> 0 | CY17: =SUM(CE17,#REF!,CS17) -> #REF! | CZ17: =CY17/CX17*100 -> #REF!
H18: =COUNTIF(C18:G18,"PR") -> 0 | I18: =COUNTIF(C18:G18,"AB") -> 0 | J18: =H18+I18 -> 0 | O18: =COUNTIF(K18:N18,"PR") -> 0 | P18: =COUNTIF(K18:N18,"AB") -> 0 | Q18: =O18+P18 -> 0 | V18: =COUNTIF(R18:U18,"PR") -> 0 | W18: =COUNTIF(R18:U18,"AB") -> 0 | X18: =V18+W18 -> 0 | Y18: =J18+Q18+X18 -> 0 | Z18: =SUM(H18,O18,V18) -> 0 | AA18: =Z18/Y18*100 -> #DIV/0! | AG18: =COUNTIF(AC18:AF18,"PR") -> 0 | AH18: =COUNTIF(AC18:AF18,"AB") -> 0 | AI18: =AG18+AH18 -> 0 | AO18: =COUNTIF(AJ18:AN18,"PR") -> 0 | AP18: =COUNTIF(AJ18:AN18,"AB") -> 0 | AQ18: =AO18+AP18 -> 0 | AV18: =COUNTIF(AR18:AU18,"PR") -> 0 | AW18: =COUNTIF(AR18:AU18,"AB") -> 0 | AX18: =AV18+AW18 -> 0 | AY18: =AI18+AQ18+AX18 -> 0 | AZ18: =SUM(AG18,AO18,AV18) -> 0 | BA18: =AZ18/AY18*100 -> #DIV/0! | BF18: =COUNTIF(BB18:BE18,"PR") -> 0 | BG18: =COUNTIF(BB18:BE18,"AB") -> 0 | BH18: =BF18+BG18 -> 0 | BN18: =COUNTIF(BI18:BM18,"PR") -> 0 | BO18: =COUNTIF(BI18:BM18,"AB") -> 0 | BP18: =BN18+BO18 -> 0 | BU18: =COUNTIF(BQ18:BT18,"PR") -> 0 | BV18: =COUNTIF(BQ18:BT18,"AB") -> 0 | BW18: =BU18+BV18 -> 0 | BX18: =BH18+BP18+BW18 -> 0 | BY18: =SUM(BF18,BN18,BU18) -> 0 | BZ18: =BY18/BX18*100 -> #DIV/0! | CG18: =COUNTIF(CB18:CF18,"PR") -> 0 | CH18: =COUNTIF(CB18:CF18,"AB") -> 0 | CI18: =CG18+CH18 -> 0 | CN18: =COUNTIF(CJ18:CM18,"PR") -> 0 | CO18: =COUNTIF(CJ18:CM18,"AB") -> 0 | CP18: =CN18+CO18 -> 0 | CU18: =COUNTIF(CQ18:CT18,"PR") -> 0 | CV18: =COUNTIF(CQ18:CT18,"AB") -> 0 | CW18: =CU18+CV18 -> 0 | CX18: =CG18+CN18+CU18 -> 0 | CY18: =SUM(CE18,#REF!,CS18) -> #REF! | CZ18: =CY18/CX18*100 -> #REF!
H19: =COUNTIF(C19:G19,"PR") -> 0 | I19: =COUNTIF(C19:G19,"AB") -> 0 | J19: =H19+I19 -> 0 | O19: =COUNTIF(K19:N19,"PR") -> 0 | P19: =COUNTIF(K19:N19,"AB") -> 0 | Q19: =O19+P19 -> 0 | V19: =COUNTIF(R19:U19,"PR") -> 0 | W19: =COUNTIF(R19:U19,"AB") -> 0 | X19: =V19+W19 -> 0 | Y19: =J19+Q19+X19 -> 0 | Z19: =SUM(H19,O19,V19) -> 0 | AA19: =Z19/Y19*100 -> #DIV/0! | AG19: =COUNTIF(AC19:AF19,"PR") -> 0 | AH19: =COUNTIF(AC19:AF19,"AB") -> 0 | AI19: =AG19+AH19 -> 0 | AO19: =COUNTIF(AJ19:AN19,"PR") -> 0 | AP19: =COUNTIF(AJ19:AN19,"AB") -> 0 | AQ19: =AO19+AP19 -> 0 | AV19: =COUNTIF(AR19:AU19,"PR") -> 0 | AW19: =COUNTIF(AR19:AU19,"AB") -> 0 | AX19: =AV19+AW19 -> 0 | AY19: =AI19+AQ19+AX19 -> 0 | AZ19: =SUM(AG19,AO19,AV19) -> 0 | BA19: =AZ19/AY19*100 -> #DIV/0! | BF19: =COUNTIF(BB19:BE19,"PR") -> 0 | BG19: =COUNTIF(BB19:BE19,"AB") -> 0 | BH19: =BF19+BG19 -> 0 | BN19: =COUNTIF(BI19:BM19,"PR") -> 0 | BO19: =COUNTIF(BI19:BM19,"AB") -> 0 | BP19: =BN19+BO19 -> 0 | BU19: =COUNTIF(BQ19:BT19,"PR") -> 0 | BV19: =COUNTIF(BQ19:BT19,"AB") -> 0 | BW19: =BU19+BV19 -> 0 | BX19: =BH19+BP19+BW19 -> 0 | BY19: =SUM(BF19,BN19,BU19) -> 0 | BZ19: =BY19/BX19*100 -> #DIV/0! | CG19: =COUNTIF(CB19:CF19,"PR") -> 0 | CH19: =COUNTIF(CB19:CF19,"AB") -> 0 | CI19: =CG19+CH19 -> 0 | CN19: =COUNTIF(CJ19:CM19,"PR") -> 0 | CO19: =COUNTIF(CJ19:CM19,"AB") -> 0 | CP19: =CN19+CO19 -> 0 | CU19: =COUNTIF(CQ19:CT19,"PR") -> 0 | CV19: =COUNTIF(CQ19:CT19,"AB") -> 0 | CW19: =CU19+CV19 -> 0 | CX19: =CG19+CN19+CU19 -> 0 | CY19: =SUM(CE19,#REF!,CS19) -> #REF! | CZ19: =CY19/CX19*100 -> #REF!
H20: =SUM(H15:H19) -> 0 | J20: =SUM(J15:J19) -> 0 | O20: =SUM(O15:O19) -> 0 | Q20: =SUM(Q15:Q19) -> 0 | V20: =SUM(V15:V19) -> 0 | X20: =SUM(X15:X19) -> 0 | Y20: =SUM(Y15:Y19) -> 0 | AG20: =SUM(AG15:AG19) -> 0 | AI20: =SUM(AI15:AI19) -> 0 | AO20: =SUM(AO15:AO19) -> 0 | AQ20: =SUM(AQ15:AQ19) -> 0 | AV20: =SUM(AV15:AV19) -> 0 | AX20: =SUM(AX15:AX19) -> 0 | AY20: =SUM(AY15:AY19) -> 0 | BF20: =SUM(BF15:BF19) -> 0 | BH20: =SUM(BH15:BH19) -> 0 | BN20: =SUM(BN15:BN19) -> 0 | BP20: =SUM(BP15:BP19) -> 0 | BU20: =SUM(BU15:BU19) -> 0 | BW20: =SUM(BW15:BW19) -> 0 | BX20: =SUM(BX15:BX19) -> 0 | CG20: =SUM(CG15:CG19) -> 0 | CI20: =SUM(CI15:CI19) -> 0 | CN20: =SUM(CN15:CN19) -> 0 | CP20: =SUM(CP15:CP19) -> 0 | CU20: =SUM(CU15:CU19) -> 0 | CW20: =SUM(CW15:CW19) -> 0 | CX20: =SUM(CX15:CX19) -> 0
A21: Consistent
H22: =COUNTIF(C22:G22,"PR") -> 0 | I22: =COUNTIF(C22:G22,"AB") -> 0 | J22: =H22+I22 -> 0 | O22: =COUNTIF(K22:N22,"PR") -> 0 | P22: =COUNTIF(K22:N22,"AB") -> 0 | Q22: =O22+P22 -> 0 | V22: =COUNTIF(R22:U22,"PR") -> 0 | W22: =COUNTIF(R22:U22,"AB") -> 0 | X22: =V22+W22 -> 0 | Y22: =J22+Q22+X22 -> 0 | Z22: =SUM(H22,O22,V22) -> 0 | AA22: =Z22/Y22*100 -> #DIV/0! | AG22: =COUNTIF(AC22:AF22,"PR") -> 0 | AH22: =COUNTIF(AC22:AF22,"AB") -> 0 | AI22: =AG22+AH22 -> 0 | AO22: =COUNTIF(AJ22:AN22,"PR") -> 0 | AP22: =COUNTIF(AJ22:AN22,"AB") -> 0 | AQ22: =AO22+AP22 -> 0 | AV22: =COUNTIF(AR22:AU22,"PR") -> 0 | AW22: =COUNTIF(AR22:AU22,"AB") -> 0 | AX22: =AV22+AW22 -> 0 | AY22: =AI22+AQ22+AX22 -> 0 | AZ22: =SUM(AG22,AO22,AV22) -> 0 | BA22: =AZ22/AY22*100 -> #DIV/0! | BF22: =COUNTIF(BB22:BE22,"PR") -> 0 | BG22: =COUNTIF(BB22:BE22,"AB") -> 0 | BH22: =BF22+BG22 -> 0 | BN22: =COUNTIF(BI22:BM22,"PR") -> 0 | BO22: =COUNTIF(BI22:BM22,"AB") -> 0 | BP22: =BN22+BO22 -> 0 | BU22: =COUNTIF(BQ22:BT22,"PR") -> 0 | BV22: =COUNTIF(BQ22:BT22,"AB") -> 0 | BW22: =BU22+BV22 -> 0 | BX22: =BH22+BP22+BW22 -> 0 | BY22: =SUM(BF22,BN22,BU22) -> 0 | BZ22: =BY22/BX22*100 -> #DIV/0! | CG22: =COUNTIF(CB22:CF22,"PR") -> 0 | CH22: =COUNTIF(CB22:CF22,"AB") -> 0 | CI22: =CG22+CH22 -> 0 | CN22: =COUNTIF(CJ22:CM22,"PR") -> 0 | CO22: =COUNTIF(CJ22:CM22,"AB") -> 0 | CP22: =CN22+CO22 -> 0 | CU22: =COUNTIF(CQ22:CT22,"PR") -> 0 | CV22: =COUNTIF(CQ22:CT22,"AB") -> 0 | CW22: =CU22+CV22 -> 0 | CX22: =CG22+CN22+CU22 -> 0 | CY22: =SUM(CE22,#REF!,CS22) -> #REF! | CZ22: =CY22/CX22*100 -> #REF!
H23: =COUNTIF(C23:G23,"PR") -> 0 | I23: =COUNTIF(C23:G23,"AB") -> 0 | J23: =H23+I23 -> 0 | O23: =COUNTIF(K23:N23,"PR") -> 0 | P23: =COUNTIF(K23:N23,"AB") -> 0 | Q23: =O23+P23 -> 0 | V23: =COUNTIF(R23:U23,"PR") -> 0 | W23: =COUNTIF(R23:U23,"AB") -> 0 | X23: =V23+W23 -> 0 | Y23: =J23+Q23+X23 -> 0 | Z23: =SUM(H23,O23,V23) -> 0 | AA23: =Z23/Y23*100 -> #DIV/0! | AG23: =COUNTIF(AC23:AF23,"PR") -> 0 | AH23: =COUNTIF(AC23:AF23,"AB") -> 0 | AI23: =AG23+AH23 -> 0 | AO23: =COUNTIF(AJ23:AN23,"PR") -> 0 | AP23: =COUNTIF(AJ23:AN23,"AB") -> 0 | AQ23: =AO23+AP23 -> 0 | AV23: =COUNTIF(AR23:AU23,"PR") -> 0 | AW23: =COUNTIF(AR23:AU23,"AB") -> 0 | AX23: =AV23+AW23 -> 0 | AY23: =AI23+AQ23+AX23 -> 0 | AZ23: =SUM(AG23,AO23,AV23) -> 0 | BA23: =AZ23/AY23*100 -> #DIV/0! | BF23: =COUNTIF(BB23:BE23,"PR") -> 0 | BG23: =COUNTIF(BB23:BE23,"AB") -> 0 | BH23: =BF23+BG23 -> 0 | BN23: =COUNTIF(BI23:BM23,"PR") -> 0 | BO23: =COUNTIF(BI23:BM23,"AB") -> 0 | BP23: =BN23+BO23 -> 0 | BU23: =COUNTIF(BQ23:BT23,"PR") -> 0 | BV23: =COUNTIF(BQ23:BT23,"AB") -> 0 | BW23: =BU23+BV23 -> 0 | BX23: =BH23+BP23+BW23 -> 0 | BY23: =SUM(BF23,BN23,BU23) -> 0 | BZ23: =BY23/BX23*100 -> #DIV/0! | CG23: =COUNTIF(CB23:CF23,"PR") -> 0 | CH23: =COUNTIF(CB23:CF23,"AB") -> 0 | CI23: =CG23+CH23 -> 0 | CN23: =COUNTIF(CJ23:CM23,"PR") -> 0 | CO23: =COUNTIF(CJ23:CM23,"AB") -> 0 | CP23: =CN23+CO23 -> 0 | CU23: =COUNTIF(CQ23:CT23,"PR") -> 0 | CV23: =COUNTIF(CQ23:CT23,"AB") -> 0 | CW23: =CU23+CV23 -> 0 | CX23: =CG23+CN23+CU23 -> 0 | CY23: =SUM(CE23,#REF!,CS23) -> #REF! | CZ23: =CY23/CX23*100 -> #REF!
H24: =COUNTIF(C24:G24,"PR") -> 0 | I24: =COUNTIF(C24:G24,"AB") -> 0 | J24: =H24+I24 -> 0 | O24: =COUNTIF(K24:N24,"PR") -> 0 | P24: =COUNTIF(K24:N24,"AB") -> 0 | Q24: =O24+P24 -> 0 | V24: =COUNTIF(R24:U24,"PR") -> 0 | W24: =COUNTIF(R24:U24,"AB") -> 0 | X24: =V24+W24 -> 0 | Y24: =J24+Q24+X24 -> 0 | Z24: =SUM(H24,O24,V24) -> 0 | AA24: =Z24/Y24*100 -> #DIV/0! | AG24: =COUNTIF(AC24:AF24,"PR") -> 0 | AH24: =COUNTIF(AC24:AF24,"AB") -> 0 | AI24: =AG24+AH24 -> 0 | AO24: =COUNTIF(AJ24:AN24,"PR") -> 0 | AP24: =COUNTIF(AJ24:AN24,"AB") -> 0 | AQ24: =AO24+AP24 -> 0 | AV24: =COUNTIF(AR24:AU24,"PR") -> 0 | AW24: =COUNTIF(AR24:AU24,"AB") -> 0 | AX24: =AV24+AW24 -> 0 | AY24: =AI24+AQ24+AX24 -> 0 | AZ24: =SUM(AG24,AO24,AV24) -> 0 | BA24: =AZ24/AY24*100 -> #DIV/0! | BF24: =COUNTIF(BB24:BE24,"PR") -> 0 | BG24: =COUNTIF(BB24:BE24,"AB") -> 0 | BH24: =BF24+BG24 -> 0 | BN24: =COUNTIF(BI24:BM24,"PR") -> 0 | BO24: =COUNTIF(BI24:BM24,"AB") -> 0 | BP24: =BN24+BO24 -> 0 | BU24: =COUNTIF(BQ24:BT24,"PR") -> 0 | BV24: =COUNTIF(BQ24:BT24,"AB") -> 0 | BW24: =BU24+BV24 -> 0 | BX24: =BH24+BP24+BW24 -> 0 | BY24: =SUM(BF24,BN24,BU24) -> 0 | BZ24: =BY24/BX24*100 -> #DIV/0! | CG24: =COUNTIF(CB24:CF24,"PR") -> 0 | CH24: =COUNTIF(CB24:CF24,"AB") -> 0 | CI24: =CG24+CH24 -> 0 | CN24: =COUNTIF(CJ24:CM24,"PR") -> 0 | CO24: =COUNTIF(CJ24:CM24,"AB") -> 0 | CP24: =CN24+CO24 -> 0 | CU24: =COUNTIF(CQ24:CT24,"PR") -> 0 | CV24: =COUNTIF(CQ24:CT24,"AB") -> 0 | CW24: =CU24+CV24 -> 0 | CX24: =CG24+CN24+CU24 -> 0 | CY24: =SUM(CE24,#REF!,CS24) -> #REF! | CZ24: =CY24/CX24*100 -> #REF!
H25: =COUNTIF(C25:G25,"PR") -> 0 | I25: =COUNTIF(C25:G25,"AB") -> 0 | J25: =H25+I25 -> 0 | O25: =COUNTIF(K25:N25,"PR") -> 0 | P25: =COUNTIF(K25:N25,"AB") -> 0 | Q25: =O25+P25 -> 0 | V25: =COUNTIF(R25:U25,"PR") -> 0 | W25: =COUNTIF(R25:U25,"AB") -> 0 | X25: =V25+W25 -> 0 | Y25: =J25+Q25+X25 -> 0 | Z25: =SUM(H25,O25,V25) -> 0 | AA25: =Z25/Y25*100 -> #DIV/0! | AG25: =COUNTIF(AC25:AF25,"PR") -> 0 | AH25: =COUNTIF(AC25:AF25,"AB") -> 0 | AI25: =AG25+AH25 -> 0 | AO25: =COUNTIF(AJ25:AN25,"PR") -> 0 | AP25: =COUNTIF(AJ25:AN25,"AB") -> 0 | AQ25: =AO25+AP25 -> 0 | AV25: =COUNTIF(AR25:AU25,"PR") -> 0 | AW25: =COUNTIF(AR25:AU25,"AB") -> 0 | AX25: =AV25+AW25 -> 0 | AY25: =AI25+AQ25+AX25 -> 0 | AZ25: =SUM(AG25,AO25,AV25) -> 0 | BA25: =AZ25/AY25*100 -> #DIV/0! | BF25: =COUNTIF(BB25:BE25,"PR") -> 0 | BG25: =COUNTIF(BB25:BE25,"AB") -> 0 | BH25: =BF25+BG25 -> 0 | BN25: =COUNTIF(BI25:BM25,"PR") -> 0 | BO25: =COUNTIF(BI25:BM25,"AB") -> 0 | BP25: =BN25+BO25 -> 0 | BU25: =COUNTIF(BQ25:BT25,"PR") -> 0 | BV25: =COUNTIF(BQ25:BT25,"AB") -> 0 | BW25: =BU25+BV25 -> 0 | BX25: =BH25+BP25+BW25 -> 0 | BY25: =SUM(BF25,BN25,BU25) -> 0 | BZ25: =BY25/BX25*100 -> #DIV/0! | CG25: =COUNTIF(CB25:CF25,"PR") -> 0 | CH25: =COUNTIF(CB25:CF25,"AB") -> 0 | CI25: =CG25+CH25 -> 0 | CN25: =COUNTIF(CJ25:CM25,"PR") -> 0 | CO25: =COUNTIF(CJ25:CM25,"AB") -> 0 | CP25: =CN25+CO25 -> 0 | CU25: =COUNTIF(CQ25:CT25,"PR") -> 0 | CV25: =COUNTIF(CQ25:CT25,"AB") -> 0 | CW25: =CU25+CV25 -> 0 | CX25: =CG25+CN25+CU25 -> 0 | CY25: =SUM(CE25,#REF!,CS25) -> #REF! | CZ25: =CY25/CX25*100 -> #REF!
H26: =COUNTIF(C26:G26,"PR") -> 0 | I26: =COUNTIF(C26:G26,"AB") -> 0 | J26: =H26+I26 -> 0 | O26: =COUNTIF(K26:N26,"PR") -> 0 | P26: =COUNTIF(K26:N26,"AB") -> 0 | Q26: =O26+P26 -> 0 | V26: =COUNTIF(R26:U26,"PR") -> 0 | W26: =COUNTIF(R26:U26,"AB") -> 0 | X26: =V26+W26 -> 0 | Y26: =J26+Q26+X26 -> 0 | Z26: =SUM(H26,O26,V26) -> 0 | AA26: =Z26/Y26*100 -> #DIV/0! | AG26: =COUNTIF(AC26:AF26,"PR") -> 0 | AH26: =COUNTIF(AC26:AF26,"AB") -> 0 | AI26: =AG26+AH26 -> 0 | AO26: =COUNTIF(AJ26:AN26,"PR") -> 0 | AP26: =COUNTIF(AJ26:AN26,"AB") -> 0 | AQ26: =AO26+AP26 -> 0 | AV26: =COUNTIF(AR26:AU26,"PR") -> 0 | AW26: =COUNTIF(AR26:AU26,"AB") -> 0 | AX26: =AV26+AW26 -> 0 | AY26: =AI26+AQ26+AX26 -> 0 | AZ26: =SUM(AG26,AO26,AV26) -> 0 | BA26: =AZ26/AY26*100 -> #DIV/0! | BF26: =COUNTIF(BB26:BE26,"PR") -> 0 | BG26: =COUNTIF(BB26:BE26,"AB") -> 0 | BH26: =BF26+BG26 -> 0 | BN26: =COUNTIF(BI26:BM26,"PR") -> 0 | BO26: =COUNTIF(BI26:BM26,"AB") -> 0 | BP26: =BN26+BO26 -> 0 | BU26: =COUNTIF(BQ26:BT26,"PR") -> 0 | BV26: =COUNTIF(BQ26:BT26,"AB") -> 0 | BW26: =BU26+BV26 -> 0 | BX26: =BH26+BP26+BW26 -> 0 | BY26: =SUM(BF26,BN26,BU26) -> 0 | BZ26: =BY26/BX26*100 -> #DIV/0! | CG26: =COUNTIF(CB26:CF26,"PR") -> 0 | CH26: =COUNTIF(CB26:CF26,"AB") -> 0 | CI26: =CG26+CH26 -> 0 | CN26: =COUNTIF(CJ26:CM26,"PR") -> 0 | CO26: =COUNTIF(CJ26:CM26,"AB") -> 0 | CP26: =CN26+CO26 -> 0 | CU26: =COUNTIF(CQ26:CT26,"PR") -> 0 | CV26: =COUNTIF(CQ26:CT26,"AB") -> 0 | CW26: =CU26+CV26 -> 0 | CX26: =CG26+CN26+CU26 -> 0 | CY26: =SUM(CE26,#REF!,CS26) -> #REF! | CZ26: =CY26/CX26*100 -> #REF!
H27: =COUNTIF(C27:G27,"PR") -> 0 | I27: =COUNTIF(C27:G27,"AB") -> 0 | J27: =H27+I27 -> 0 | O27: =COUNTIF(K27:N27,"PR") -> 0 | P27: =COUNTIF(K27:N27,"AB") -> 0 | Q27: =O27+P27 -> 0 | V27: =COUNTIF(R27:U27,"PR") -> 0 | W27: =COUNTIF(R27:U27,"AB") -> 0 | X27: =V27+W27 -> 0 | Y27: =J27+Q27+X27 -> 0 | Z27: =SUM(H27,O27,V27) -> 0 | AA27: =Z27/Y27*100 -> #DIV/0! | AG27: =COUNTIF(AC27:AF27,"PR") -> 0 | AH27: =COUNTIF(AC27:AF27,"AB") -> 0 | AI27: =AG27+AH27 -> 0 | AO27: =COUNTIF(AJ27:AN27,"PR") -> 0 | AP27: =COUNTIF(AJ27:AN27,"AB") -> 0 | AQ27: =AO27+AP27 -> 0 | AV27: =COUNTIF(AR27:AU27,"PR") -> 0 | AW27: =COUNTIF(AR27:AU27,"AB") -> 0 | AX27: =AV27+AW27 -> 0 | AY27: =AI27+AQ27+AX27 -> 0 | AZ27: =SUM(AG27,AO27,AV27) -> 0 | BA27: =AZ27/AY27*100 -> #DIV/0! | BF27: =COUNTIF(BB27:BE27,"PR") -> 0 | BG27: =COUNTIF(BB27:BE27,"AB") -> 0 | BH27: =BF27+BG27 -> 0 | BN27: =COUNTIF(BI27:BM27,"PR") -> 0 | BO27: =COUNTIF(BI27:BM27,"AB") -> 0 | BP27: =BN27+BO27 -> 0 | BU27: =COUNTIF(BQ27:BT27,"PR") -> 0 | BV27: =COUNTIF(BQ27:BT27,"AB") -> 0 | BW27: =BU27+BV27 -> 0 | BX27: =BH27+BP27+BW27 -> 0 | BY27: =SUM(BF27,BN27,BU27) -> 0 | BZ27: =BY27/BX27*100 -> #DIV/0! | CG27: =COUNTIF(CB27:CF27,"PR") -> 0 | CH27: =COUNTIF(CB27:CF27,"AB") -> 0 | CI27: =CG27+CH27 -> 0 | CN27: =COUNTIF(CJ27:CM27,"PR") -> 0 | CO27: =COUNTIF(CJ27:CM27,"AB") -> 0 | CP27: =CN27+CO27 -> 0 | CU27: =COUNTIF(CQ27:CT27,"PR") -> 0 | CV27: =COUNTIF(CQ27:CT27,"AB") -> 0 | CW27: =CU27+CV27 -> 0 | CX27: =CG27+CN27+CU27 -> 0 | CY27: =SUM(CE27,#REF!,CS27) -> #REF! | CZ27: =CY27/CX27*100 -> #REF!
H28: =COUNTIF(C28:G28,"PR") -> 0 | I28: =COUNTIF(C28:G28,"AB") -> 0 | J28: =H28+I28 -> 0 | O28: =COUNTIF(K28:N28,"PR") -> 0 | P28: =COUNTIF(K28:N28,"AB") -> 0 | Q28: =O28+P28 -> 0 | V28: =COUNTIF(R28:U28,"PR") -> 0 | W28: =COUNTIF(R28:U28,"AB") -> 0 | X28: =V28+W28 -> 0 | Y28: =J28+Q28+X28 -> 0 | Z28: =SUM(H28,O28,V28) -> 0 | AA28: =Z28/Y28*100 -> #DIV/0! | AG28: =COUNTIF(AC28:AF28,"PR") -> 0 | AH28: =COUNTIF(AC28:AF28,"AB") -> 0 | AI28: =AG28+AH28 -> 0 | AO28: =COUNTIF(AJ28:AN28,"PR") -> 0 | AP28: =COUNTIF(AJ28:AN28,"AB") -> 0 | AQ28: =AO28+AP28 -> 0 | AV28: =COUNTIF(AR28:AU28,"PR") -> 0 | AW28: =COUNTIF(AR28:AU28,"AB") -> 0 | AX28: =AV28+AW28 -> 0 | AY28: =AI28+AQ28+AX28 -> 0 | AZ28: =SUM(AG28,AO28,AV28) -> 0 | BA28: =AZ28/AY28*100 -> #DIV/0! | BF28: =COUNTIF(BB28:BE28,"PR") -> 0 | BG28: =COUNTIF(BB28:BE28,"AB") -> 0 | BH28: =BF28+BG28 -> 0 | BN28: =COUNTIF(BI28:BM28,"PR") -> 0 | BO28: =COUNTIF(BI28:BM28,"AB") -> 0 | BP28: =BN28+BO28 -> 0 | BU28: =COUNTIF(BQ28:BT28,"PR") -> 0 | BV28: =COUNTIF(BQ28:BT28,"AB") -> 0 | BW28: =BU28+BV28 -> 0 | BX28: =BH28+BP28+BW28 -> 0 | BY28: =SUM(BF28,BN28,BU28) -> 0 | BZ28: =BY28/BX28*100 -> #DIV/0! | CG28: =COUNTIF(CB28:CF28,"PR") -> 0 | CH28: =COUNTIF(CB28:CF28,"AB") -> 0 | CI28: =CG28+CH28 -> 0 | CN28: =COUNTIF(CJ28:CM28,"PR") -> 0 | CO28: =COUNTIF(CJ28:CM28,"AB") -> 0 | CP28: =CN28+CO28 -> 0 | CU28: =COUNTIF(CQ28:CT28,"PR") -> 0 | CV28: =COUNTIF(CQ28:CT28,"AB") -> 0 | CW28: =CU28+CV28 -> 0 | CX28: =CG28+CN28+CU28 -> 0 | CY28: =SUM(CE28,#REF!,CS28) -> #REF! | CZ28: =CY28/CX28*100 -> #REF!
H29: =COUNTIF(C29:G29,"PR") -> 0 | I29: =COUNTIF(C29:G29,"AB") -> 0 | J29: =H29+I29 -> 0 | O29: =COUNTIF(K29:N29,"PR") -> 0 | P29: =COUNTIF(K29:N29,"AB") -> 0 | Q29: =O29+P29 -> 0 | V29: =COUNTIF(R29:U29,"PR") -> 0 | W29: =COUNTIF(R29:U29,"AB") -> 0 | X29: =V29+W29 -> 0 | Y29: =J29+Q29+X29 -> 0 | Z29: =SUM(H29,O29,V29) -> 0 | AA29: =Z29/Y29*100 -> #DIV/0! | AG29: =COUNTIF(AC29:AF29,"PR") -> 0 | AH29: =COUNTIF(AC29:AF29,"AB") -> 0 | AI29: =AG29+AH29 -> 0 | AO29: =COUNTIF(AJ29:AN29,"PR") -> 0 | AP29: =COUNTIF(AJ29:AN29,"AB") -> 0 | AQ29: =AO29+AP29 -> 0 | AV29: =COUNTIF(AR29:AU29,"PR") -> 0 | AW29: =COUNTIF(AR29:AU29,"AB") -> 0 | AX29: =AV29+AW29 -> 0 | AY29: =AI29+AQ29+AX29 -> 0 | AZ29: =SUM(AG29,AO29,AV29) -> 0 | BA29: =AZ29/AY29*100 -> #DIV/0! | BF29: =COUNTIF(BB29:BE29,"PR") -> 0 | BG29: =COUNTIF(BB29:BE29,"AB") -> 0 | BH29: =BF29+BG29 -> 0 | BN29: =COUNTIF(BI29:BM29,"PR") -> 0 | BO29: =COUNTIF(BI29:BM29,"AB") -> 0 | BP29: =BN29+BO29 -> 0 | BU29: =COUNTIF(BQ29:BT29,"PR") -> 0 | BV29: =COUNTIF(BQ29:BT29,"AB") -> 0 | BW29: =BU29+BV29 -> 0 | BX29: =BH29+BP29+BW29 -> 0 | BY29: =SUM(BF29,BN29,BU29) -> 0 | BZ29: =BY29/BX29*100 -> #DIV/0! | CG29: =COUNTIF(CB29:CF29,"PR") -> 0 | CH29: =COUNTIF(CB29:CF29,"AB") -> 0 | CI29: =CG29+CH29 -> 0 | CN29: =COUNTIF(CJ29:CM29,"PR") -> 0 | CO29: =COUNTIF(CJ29:CM29,"AB") -> 0 | CP29: =CN29+CO29 -> 0 | CU29: =COUNTIF(CQ29:CT29,"PR") -> 0 | CV29: =COUNTIF(CQ29:CT29,"AB") -> 0 | CW29: =CU29+CV29 -> 0 | CX29: =CG29+CN29+CU29 -> 0 | CY29: =SUM(CE29,#REF!,CS29) -> #REF! | CZ29: =CY29/CX29*100 -> #REF!
H30: =COUNTIF(C30:G30,"PR") -> 0 | I30: =COUNTIF(C30:G30,"AB") -> 0 | J30: =H30+I30 -> 0 | O30: =COUNTIF(K30:N30,"PR") -> 0 | P30: =COUNTIF(K30:N30,"AB") -> 0 | Q30: =O30+P30 -> 0 | V30: =COUNTIF(R30:U30,"PR") -> 0 | W30: =COUNTIF(R30:U30,"AB") -> 0 | X30: =V30+W30 -> 0 | Y30: =J30+Q30+X30 -> 0 | Z30: =SUM(H30,O30,V30) -> 0 | AA30: =Z30/Y30*100 -> #DIV/0! | AG30: =COUNTIF(AC30:AF30,"PR") -> 0 | AH30: =COUNTIF(AC30:AF30,"AB") -> 0 | AI30: =AG30+AH30 -> 0 | AO30: =COUNTIF(AJ30:AN30,"PR") -> 0 | AP30: =COUNTIF(AJ30:AN30,"AB") -> 0 | AQ30: =AO30+AP30 -> 0 | AV30: =COUNTIF(AR30:AU30,"PR") -> 0 | AW30: =COUNTIF(AR30:AU30,"AB") -> 0 | AX30: =AV30+AW30 -> 0 | AY30: =AI30+AQ30+AX30 -> 0 | AZ30: =SUM(AG30,AO30,AV30) -> 0 | BA30: =AZ30/AY30*100 -> #DIV/0! | BF30: =COUNTIF(BB30:BE30,"PR") -> 0 | BG30: =COUNTIF(BB30:BE30,"AB") -> 0 | BH30: =BF30+BG30 -> 0 | BN30: =COUNTIF(BI30:BM30,"PR") -> 0 | BO30: =COUNTIF(BI30:BM30,"AB") -> 0 | BP30: =BN30+BO30 -> 0 | BU30: =COUNTIF(BQ30:BT30,"PR") -> 0 | BV30: =COUNTIF(BQ30:BT30,"AB") -> 0 | BW30: =BU30+BV30 -> 0 | BX30: =BH30+BP30+BW30 -> 0 | BY30: =SUM(BF30,BN30,BU30) -> 0 | BZ30: =BY30/BX30*100 -> #DIV/0! | CG30: =COUNTIF(CB30:CF30,"PR") -> 0 | CH30: =COUNTIF(CB30:CF30,"AB") -> 0 | CI30: =CG30+CH30 -> 0 | CN30: =COUNTIF(CJ30:CM30,"PR") -> 0 | CO30: =COUNTIF(CJ30:CM30,"AB") -> 0 | CP30: =CN30+CO30 -> 0 | CU30: =COUNTIF(CQ30:CT30,"PR") -> 0 | CV30: =COUNTIF(CQ30:CT30,"AB") -> 0 | CW30: =CU30+CV30 -> 0 | CX30: =CG30+CN30+CU30 -> 0 | CY30: =SUM(CE30,#REF!,CS30) -> #REF! | CZ30: =CY30/CX30*100 -> #REF!
H31: =COUNTIF(C31:G31,"PR") -> 0 | I31: =COUNTIF(C31:G31,"AB") -> 0 | J31: =H31+I31 -> 0 | O31: =COUNTIF(K31:N31,"PR") -> 0 | P31: =COUNTIF(K31:N31,"AB") -> 0 | Q31: =O31+P31 -> 0 | V31: =COUNTIF(R31:U31,"PR") -> 0 | W31: =COUNTIF(R31:U31,"AB") -> 0 | X31: =V31+W31 -> 0 | Y31: =J31+Q31+X31 -> 0 | Z31: =SUM(H31,O31,V31) -> 0 | AA31: =Z31/Y31*100 -> #DIV/0! | AG31: =COUNTIF(AC31:AF31,"PR") -> 0 | AH31: =COUNTIF(AC31:AF31,"AB") -> 0 | AI31: =AG31+AH31 -> 0 | AO31: =COUNTIF(AJ31:AN31,"PR") -> 0 | AP31: =COUNTIF(AJ31:AN31,"AB") -> 0 | AQ31: =AO31+AP31 -> 0 | AV31: =COUNTIF(AR31:AU31,"PR") -> 0 | AW31: =COUNTIF(AR31:AU31,"AB") -> 0 | AX31: =AV31+AW31 -> 0 | AY31: =AI31+AQ31+AX31 -> 0 | AZ31: =SUM(AG31,AO31,AV31) -> 0 | BA31: =AZ31/AY31*100 -> #DIV/0! | BF31: =COUNTIF(BB31:BE31,"PR") -> 0 | BG31: =COUNTIF(BB31:BE31,"AB") -> 0 | BH31: =BF31+BG31 -> 0 | BN31: =COUNTIF(BI31:BM31,"PR") -> 0 | BO31: =COUNTIF(BI31:BM31,"AB") -> 0 | BP31: =BN31+BO31 -> 0 | BU31: =COUNTIF(BQ31:BT31,"PR") -> 0 | BV31: =COUNTIF(BQ31:BT31,"AB") -> 0 | BW31: =BU31+BV31 -> 0 | BX31: =BH31+BP31+BW31 -> 0 | BY31: =SUM(BF31,BN31,BU31) -> 0 | BZ31: =BY31/BX31*100 -> #DIV/0! | CG31: =COUNTIF(CB31:CF31,"PR") -> 0 | CH31: =COUNTIF(CB31:CF31,"AB") -> 0 | CI31: =CG31+CH31 -> 0 | CN31: =COUNTIF(CJ31:CM31,"PR") -> 0 | CO31: =COUNTIF(CJ31:CM31,"AB") -> 0 | CP31: =CN31+CO31 -> 0 | CU31: =COUNTIF(CQ31:CT31,"PR") -> 0 | CV31: =COUNTIF(CQ31:CT31,"AB") -> 0 | CW31: =CU31+CV31 -> 0 | CX31: =CG31+CN31+CU31 -> 0 | CY31: =SUM(CE31,#REF!,CS31) -> #REF! | CZ31: =CY31/CX31*100 -> #REF!
H32: =COUNTIF(C32:G32,"PR") -> 0 | I32: =COUNTIF(C32:G32,"AB") -> 0 | J32: =H32+I32 -> 0 | O32: =COUNTIF(K32:N32,"PR") -> 0 | P32: =COUNTIF(K32:N32,"AB") -> 0 | Q32: =O32+P32 -> 0 | V32: =COUNTIF(R32:U32,"PR") -> 0 | W32: =COUNTIF(R32:U32,"AB") -> 0 | X32: =V32+W32 -> 0 | Y32: =J32+Q32+X32 -> 0 | Z32: =SUM(H32,O32,V32) -> 0 | AA32: =Z32/Y32*100 -> #DIV/0! | AG32: =COUNTIF(AC32:AF32,"PR") -> 0 | AH32: =COUNTIF(AC32:AF32,"AB") -> 0 | AI32: =AG32+AH32 -> 0 | AO32: =COUNTIF(AJ32:AN32,"PR") -> 0 | AP32: =COUNTIF(AJ32:AN32,"AB") -> 0 | AQ32: =AO32+AP32 -> 0 | AV32: =COUNTIF(AR32:AU32,"PR") -> 0 | AW32: =COUNTIF(AR32:AU32,"AB") -> 0 | AX32: =AV32+AW32 -> 0 | AY32: =AI32+AQ32+AX32 -> 0 | AZ32: =SUM(AG32,AO32,AV32) -> 0 | BA32: =AZ32/AY32*100 -> #DIV/0! | BF32: =COUNTIF(BB32:BE32,"PR") -> 0 | BG32: =COUNTIF(BB32:BE32,"AB") -> 0 | BH32: =BF32+BG32 -> 0 | BN32: =COUNTIF(BI32:BM32,"PR") -> 0 | BO32: =COUNTIF(BI32:BM32,"AB") -> 0 | BP32: =BN32+BO32 -> 0 | BU32: =COUNTIF(BQ32:BT32,"PR") -> 0 | BV32: =COUNTIF(BQ32:BT32,"AB") -> 0 | BW32: =BU32+BV32 -> 0 | BX32: =BH32+BP32+BW32 -> 0 | BY32: =SUM(BF32,BN32,BU32) -> 0 | BZ32: =BY32/BX32*100 -> #DIV/0! | CG32: =COUNTIF(CB32:CF32,"PR") -> 0 | CH32: =COUNTIF(CB32:CF32,"AB") -> 0 | CI32: =CG32+CH32 -> 0 | CN32: =COUNTIF(CJ32:CM32,"PR") -> 0 | CO32: =COUNTIF(CJ32:CM32,"AB") -> 0 | CP32: =CN32+CO32 -> 0 | CU32: =COUNTIF(CQ32:CT32,"PR") -> 0 | CV32: =COUNTIF(CQ32:CT32,"AB") -> 0 | CW32: =CU32+CV32 -> 0 | CX32: =CG32+CN32+CU32 -> 0 | CY32: =SUM(CE32,#REF!,CS32) -> #REF! | CZ32: =CY32/CX32*100 -> #REF!
H33: =COUNTIF(C33:G33,"PR") -> 0 | I33: =COUNTIF(C33:G33,"AB") -> 0 | J33: =H33+I33 -> 0 | O33: =COUNTIF(K33:N33,"PR") -> 0 | P33: =COUNTIF(K33:N33,"AB") -> 0 | Q33: =O33+P33 -> 0 | V33: =COUNTIF(R33:U33,"PR") -> 0 | W33: =COUNTIF(R33:U33,"AB") -> 0 | X33: =V33+W33 -> 0 | Y33: =J33+Q33+X33 -> 0 | Z33: =SUM(H33,O33,V33) -> 0 | AA33: =Z33/Y33*100 -> #DIV/0! | AG33: =COUNTIF(AC33:AF33,"PR") -> 0 | AH33: =COUNTIF(AC33:AF33,"AB") -> 0 | AI33: =AG33+AH33 -> 0 | AO33: =COUNTIF(AJ33:AN33,"PR") -> 0 | AP33: =COUNTIF(AJ33:AN33,"AB") -> 0 | AQ33: =AO33+AP33 -> 0 | AV33: =COUNTIF(AR33:AU33,"PR") -> 0 | AW33: =COUNTIF(AR33:AU33,"AB") -> 0 | AX33: =AV33+AW33 -> 0 | AY33: =AI33+AQ33+AX33 -> 0 | AZ33: =SUM(AG33,AO33,AV33) -> 0 | BA33: =AZ33/AY33*100 -> #DIV/0! | BF33: =COUNTIF(BB33:BE33,"PR") -> 0 | BG33: =COUNTIF(BB33:BE33,"AB") -> 0 | BH33: =BF33+BG33 -> 0 | BN33: =COUNTIF(BI33:BM33,"PR") -> 0 | BO33: =COUNTIF(BI33:BM33,"AB") -> 0 | BP33: =BN33+BO33 -> 0 | BU33: =COUNTIF(BQ33:BT33,"PR") -> 0 | BV33: =COUNTIF(BQ33:BT33,"AB") -> 0 | BW33: =BU33+BV33 -> 0 | BX33: =BH33+BP33+BW33 -> 0 | BY33: =SUM(BF33,BN33,BU33) -> 0 | BZ33: =BY33/BX33*100 -> #DIV/0! | CG33: =COUNTIF(CB33:CF33,"PR") -> 0 | CH33: =COUNTIF(CB33:CF33,"AB") -> 0 | CI33: =CG33+CH33 -> 0 | CN33: =COUNTIF(CJ33:CM33,"PR") -> 0 | CO33: =COUNTIF(CJ33:CM33,"AB") -> 0 | CP33: =CN33+CO33 -> 0 | CU33: =COUNTIF(CQ33:CT33,"PR") -> 0 | CV33: =COUNTIF(CQ33:CT33,"AB") -> 0 | CW33: =CU33+CV33 -> 0 | CX33: =CG33+CN33+CU33 -> 0 | CY33: =SUM(CE33,#REF!,CS33) -> #REF! | CZ33: =CY33/CX33*100 -> #REF!
H34: =COUNTIF(C34:G34,"PR") -> 0 | I34: =COUNTIF(C34:G34,"AB") -> 0 | J34: =H34+I34 -> 0 | O34: =COUNTIF(K34:N34,"PR") -> 0 | P34: =COUNTIF(K34:N34,"AB") -> 0 | Q34: =O34+P34 -> 0 | V34: =COUNTIF(R34:U34,"PR") -> 0 | W34: =COUNTIF(R34:U34,"AB") -> 0 | X34: =V34+W34 -> 0 | Y34: =J34+Q34+X34 -> 0 | Z34: =SUM(H34,O34,V34) -> 0 | AA34: =Z34/Y34*100 -> #DIV/0! | AG34: =COUNTIF(AC34:AF34,"PR") -> 0 | AH34: =COUNTIF(AC34:AF34,"AB") -> 0 | AI34: =AG34+AH34 -> 0 | AO34: =COUNTIF(AJ34:AN34,"PR") -> 0 | AP34: =COUNTIF(AJ34:AN34,"AB") -> 0 | AQ34: =AO34+AP34 -> 0 | AV34: =COUNTIF(AR34:AU34,"PR") -> 0 | AW34: =COUNTIF(AR34:AU34,"AB") -> 0 | AX34: =AV34+AW34 -> 0 | AY34: =AI34+AQ34+AX34 -> 0 | AZ34: =SUM(AG34,AO34,AV34) -> 0 | BA34: =AZ34/AY34*100 -> #DIV/0! | BF34: =COUNTIF(BB34:BE34,"PR") -> 0 | BG34: =COUNTIF(BB34:BE34,"AB") -> 0 | BH34: =BF34+BG34 -> 0 | BN34: =COUNTIF(BI34:BM34,"PR") -> 0 | BO34: =COUNTIF(BI34:BM34,"AB") -> 0 | BP34: =BN34+BO34 -> 0 | BU34: =COUNTIF(BQ34:BT34,"PR") -> 0 | BV34: =COUNTIF(BQ34:BT34,"AB") -> 0 | BW34: =BU34+BV34 -> 0 | BX34: =BH34+BP34+BW34 -> 0 | BY34: =SUM(BF34,BN34,BU34) -> 0 | BZ34: =BY34/BX34*100 -> #DIV/0! | CG34: =COUNTIF(CB34:CF34,"PR") -> 0 | CH34: =COUNTIF(CB34:CF34,"AB") -> 0 | CI34: =CG34+CH34 -> 0 | CN34: =COUNTIF(CJ34:CM34,"PR") -> 0 | CO34: =COUNTIF(CJ34:CM34,"AB") -> 0 | CP34: =CN34+CO34 -> 0 | CU34: =COUNTIF(CQ34:CT34,"PR") -> 0 | CV34: =COUNTIF(CQ34:CT34,"AB") -> 0 | CW34: =CU34+CV34 -> 0 | CX34: =CG34+CN34+CU34 -> 0 | CY34: =SUM(CE34,#REF!,CS34) -> #REF! | CZ34: =CY34/CX34*100 -> #REF!
H35: =SUM(H22:H34) -> 0 | J35: =SUM(J22:J34) -> 0 | O35: =SUM(O22:O34) -> 0 | Q35: =SUM(Q22:Q34) -> 0 | V35: =SUM(V22:V34) -> 0 | X35: =SUM(X22:X34) -> 0 | Y35: =SUM(Y30:Y34) -> 0 | AG35: =SUM(AG22:AG34) -> 0 | AI35: =SUM(AI22:AI34) -> 0 | AO35: =SUM(AO22:AO34) -> 0 | AQ35: =SUM(AQ22:AQ34) -> 0 | AV35: =SUM(AV22:AV34) -> 0 | AX35: =SUM(AX22:AX34) -> 0 | AY35: =SUM(AY30:AY34) -> 0 | BF35: =SUM(BF22:BF34) -> 0 | BH35: =SUM(BH22:BH34) -> 0 | BN35: =SUM(BN22:BN34) -> 0 | BP35: =SUM(BP22:BP34) -> 0 | BU35: =SUM(BU22:BU34) -> 0 | BW35: =SUM(BW22:BW34) -> 0 | BX35: =SUM(BX30:BX34) -> 0 | CG35: =SUM(CG22:CG34) -> 0 | CI35: =SUM(CI22:CI34) -> 0 | CN35: =SUM(CN22:CN34) -> 0 | CP35: =SUM(CP22:CP34) -> 0 | CU35: =SUM(CU22:CU34) -> 0 | CW35: =SUM(CW22:CW34) -> 0 | CX35: =SUM(CX30:CX34) -> 0
A36: Semi-Consistent
H37: =COUNTIF(C37:G37,"PR") -> 0 | I37: =COUNTIF(C37:G37,"AB") -> 0 | J37: =H37+I37 -> 0 | O37: =COUNTIF(K37:N37,"PR") -> 0 | P37: =COUNTIF(K37:N37,"AB") -> 0 | Q37: =O37+P37 -> 0 | V37: =COUNTIF(R37:U37,"PR") -> 0 | W37: =COUNTIF(R37:U37,"AB") -> 0 | X37: =V37+W37 -> 0 | Y37: =J37+Q37+X37 -> 0 | Z37: =SUM(H37,O37,V37) -> 0 | AA37: =Z37/Y37*100 -> #DIV/0! | AG37: =COUNTIF(AC37:AF37,"PR") -> 0 | AH37: =COUNTIF(AC37:AF37,"AB") -> 0 | AI37: =AG37+AH37 -> 0 | AO37: =COUNTIF(AJ37:AN37,"PR") -> 0 | AP37: =COUNTIF(AJ37:AN37,"AB") -> 0 | AQ37: =AO37+AP37 -> 0 | AV37: =COUNTIF(AR37:AU37,"PR") -> 0 | AW37: =COUNTIF(AR37:AU37,"AB") -> 0 | AX37: =AV37+AW37 -> 0 | AY37: =AI37+AQ37+AX37 -> 0 | AZ37: =SUM(AG37,AO37,AV37) -> 0 | BA37: =AZ37/AY37*100 -> #DIV/0! | BF37: =COUNTIF(BB37:BE37,"PR") -> 0 | BG37: =COUNTIF(BB37:BE37,"AB") -> 0 | BH37: =BF37+BG37 -> 0 | BN37: =COUNTIF(BI37:BM37,"PR") -> 0 | BO37: =COUNTIF(BI37:BM37,"AB") -> 0 | BP37: =BN37+BO37 -> 0 | BU37: =COUNTIF(BQ37:BT37,"PR") -> 0 | BV37: =COUNTIF(BQ37:BT37,"AB") -> 0 | BW37: =BU37+BV37 -> 0 | BX37: =BH37+BP37+BW37 -> 0 | BY37: =SUM(BF37,BN37,BU37) -> 0 | BZ37: =BY37/BX37*100 -> #DIV/0! | CG37: =COUNTIF(CB37:CF37,"PR") -> 0 | CH37: =COUNTIF(CB37:CF37,"AB") -> 0 | CI37: =CG37+CH37 -> 0 | CN37: =COUNTIF(CJ37:CM37,"PR") -> 0 | CO37: =COUNTIF(CJ37:CM37,"AB") -> 0 | CP37: =CN37+CO37 -> 0 | CU37: =COUNTIF(CQ37:CT37,"PR") -> 0 | CV37: =COUNTIF(CQ37:CT37,"AB") -> 0 | CW37: =CU37+CV37 -> 0 | CX37: =CG37+CN37+CU37 -> 0 | CY37: =SUM(CE37,#REF!,CS37) -> #REF! | CZ37: =CY37/CX37*100 -> #REF!
H38: =COUNTIF(C38:G38,"PR") -> 0 | I38: =COUNTIF(C38:G38,"AB") -> 0 | J38: =H38+I38 -> 0 | O38: =COUNTIF(K38:N38,"PR") -> 0 | P38: =COUNTIF(K38:N38,"AB") -> 0 | Q38: =O38+P38 -> 0 | V38: =COUNTIF(R38:U38,"PR") -> 0 | W38: =COUNTIF(R38:U38,"AB") -> 0 | X38: =V38+W38 -> 0 | Y38: =J38+Q38+X38 -> 0 | Z38: =SUM(H38,O38,V38) -> 0 | AA38: =Z38/Y38*100 -> #DIV/0! | AG38: =COUNTIF(AC38:AF38,"PR") -> 0 | AH38: =COUNTIF(AC38:AF38,"AB") -> 0 | AI38: =AG38+AH38 -> 0 | AO38: =COUNTIF(AJ38:AN38,"PR") -> 0 | AP38: =COUNTIF(AJ38:AN38,"AB") -> 0 | AQ38: =AO38+AP38 -> 0 | AV38: =COUNTIF(AR38:AU38,"PR") -> 0 | AW38: =COUNTIF(AR38:AU38,"AB") -> 0 | AX38: =AV38+AW38 -> 0 | AY38: =AI38+AQ38+AX38 -> 0 | AZ38: =SUM(AG38,AO38,AV38) -> 0 | BA38: =AZ38/AY38*100 -> #DIV/0! | BF38: =COUNTIF(BB38:BE38,"PR") -> 0 | BG38: =COUNTIF(BB38:BE38,"AB") -> 0 | BH38: =BF38+BG38 -> 0 | BN38: =COUNTIF(BI38:BM38,"PR") -> 0 | BO38: =COUNTIF(BI38:BM38,"AB") -> 0 | BP38: =BN38+BO38 -> 0 | BU38: =COUNTIF(BQ38:BT38,"PR") -> 0 | BV38: =COUNTIF(BQ38:BT38,"AB") -> 0 | BW38: =BU38+BV38 -> 0 | BX38: =BH38+BP38+BW38 -> 0 | BY38: =SUM(BF38,BN38,BU38) -> 0 | BZ38: =BY38/BX38*100 -> #DIV/0! | CG38: =COUNTIF(CB38:CF38,"PR") -> 0 | CH38: =COUNTIF(CB38:CF38,"AB") -> 0 | CI38: =CG38+CH38 -> 0 | CN38: =COUNTIF(CJ38:CM38,"PR") -> 0 | CO38: =COUNTIF(CJ38:CM38,"AB") -> 0 | CP38: =CN38+CO38 -> 0 | CU38: =COUNTIF(CQ38:CT38,"PR") -> 0 | CV38: =COUNTIF(CQ38:CT38,"AB") -> 0 | CW38: =CU38+CV38 -> 0 | CX38: =CG38+CN38+CU38 -> 0 | CY38: =SUM(CE38,#REF!,CS38) -> #REF! | CZ38: =CY38/CX38*100 -> #REF!
H39: =COUNTIF(C39:G39,"PR") -> 0 | I39: =COUNTIF(C39:G39,"AB") -> 0 | J39: =H39+I39 -> 0 | O39: =COUNTIF(K39:N39,"PR") -> 0 | P39: =COUNTIF(K39:N39,"AB") -> 0 | Q39: =O39+P39 -> 0 | V39: =COUNTIF(R39:U39,"PR") -> 0 | W39: =COUNTIF(R39:U39,"AB") -> 0 | X39: =V39+W39 -> 0 | Y39: =J39+Q39+X39 -> 0 | Z39: =SUM(H39,O39,V39) -> 0 | AA39: =Z39/Y39*100 -> #DIV/0! | AG39: =COUNTIF(AC39:AF39,"PR") -> 0 | AH39: =COUNTIF(AC39:AF39,"AB") -> 0 | AI39: =AG39+AH39 -> 0 | AO39: =COUNTIF(AJ39:AN39,"PR") -> 0 | AP39: =COUNTIF(AJ39:AN39,"AB") -> 0 | AQ39: =AO39+AP39 -> 0 | AV39: =COUNTIF(AR39:AU39,"PR") -> 0 | AW39: =COUNTIF(AR39:AU39,"AB") -> 0 | AX39: =AV39+AW39 -> 0 | AY39: =AI39+AQ39+AX39 -> 0 | AZ39: =SUM(AG39,AO39,AV39) -> 0 | BA39: =AZ39/AY39*100 -> #DIV/0! | BF39: =COUNTIF(BB39:BE39,"PR") -> 0 | BG39: =COUNTIF(BB39:BE39,"AB") -> 0 | BH39: =BF39+BG39 -> 0 | BN39: =COUNTIF(BI39:BM39,"PR") -> 0 | BO39: =COUNTIF(BI39:BM39,"AB") -> 0 | BP39: =BN39+BO39 -> 0 | BU39: =COUNTIF(BQ39:BT39,"PR") -> 0 | BV39: =COUNTIF(BQ39:BT39,"AB") -> 0 | BW39: =BU39+BV39 -> 0 | BX39: =BH39+BP39+BW39 -> 0 | BY39: =SUM(BF39,BN39,BU39) -> 0 | BZ39: =BY39/BX39*100 -> #DIV/0! | CG39: =COUNTIF(CB39:CF39,"PR") -> 0 | CH39: =COUNTIF(CB39:CF39,"AB") -> 0 | CI39: =CG39+CH39 -> 0 | CN39: =COUNTIF(CJ39:CM39,"PR") -> 0 | CO39: =COUNTIF(CJ39:CM39,"AB") -> 0 | CP39: =CN39+CO39 -> 0 | CU39: =COUNTIF(CQ39:CT39,"PR") -> 0 | CV39: =COUNTIF(CQ39:CT39,"AB") -> 0 | CW39: =CU39+CV39 -> 0 | CX39: =CG39+CN39+CU39 -> 0 | CY39: =SUM(CE39,#REF!,CS39) -> #REF! | CZ39: =CY39/CX39*100 -> #REF!
H40: =COUNTIF(C40:G40,"PR") -> 0 | I40: =COUNTIF(C40:G40,"AB") -> 0 | J40: =H40+I40 -> 0 | O40: =COUNTIF(K40:N40,"PR") -> 0 | P40: =COUNTIF(K40:N40,"AB") -> 0 | Q40: =O40+P40 -> 0 | V40: =COUNTIF(R40:U40,"PR") -> 0 | W40: =COUNTIF(R40:U40,"AB") -> 0 | X40: =V40+W40 -> 0 | Y40: =J40+Q40+X40 -> 0 | Z40: =SUM(H40,O40,V40) -> 0 | AA40: =Z40/Y40*100 -> #DIV/0! | AG40: =COUNTIF(AC40:AF40,"PR") -> 0 | AH40: =COUNTIF(AC40:AF40,"AB") -> 0 | AI40: =AG40+AH40 -> 0 | AO40: =COUNTIF(AJ40:AN40,"PR") -> 0 | AP40: =COUNTIF(AJ40:AN40,"AB") -> 0 | AQ40: =AO40+AP40 -> 0 | AV40: =COUNTIF(AR40:AU40,"PR") -> 0 | AW40: =COUNTIF(AR40:AU40,"AB") -> 0 | AX40: =AV40+AW40 -> 0 | AY40: =AI40+AQ40+AX40 -> 0 | AZ40: =SUM(AG40,AO40,AV40) -> 0 | BA40: =AZ40/AY40*100 -> #DIV/0! | BF40: =COUNTIF(BB40:BE40,"PR") -> 0 | BG40: =COUNTIF(BB40:BE40,"AB") -> 0 | BH40: =BF40+BG40 -> 0 | BN40: =COUNTIF(BI40:BM40,"PR") -> 0 | BO40: =COUNTIF(BI40:BM40,"AB") -> 0 | BP40: =BN40+BO40 -> 0 | BU40: =COUNTIF(BQ40:BT40,"PR") -> 0 | BV40: =COUNTIF(BQ40:BT40,"AB") -> 0 | BW40: =BU40+BV40 -> 0 | BX40: =BH40+BP40+BW40 -> 0 | BY40: =SUM(BF40,BN40,BU40) -> 0 | BZ40: =BY40/BX40*100 -> #DIV/0! | CG40: =COUNTIF(CB40:CF40,"PR") -> 0 | CH40: =COUNTIF(CB40:CF40,"AB") -> 0 | CI40: =CG40+CH40 -> 0 | CN40: =COUNTIF(CJ40:CM40,"PR") -> 0 | CO40: =COUNTIF(CJ40:CM40,"AB") -> 0 | CP40: =CN40+CO40 -> 0 | CU40: =COUNTIF(CQ40:CT40,"PR") -> 0 | CV40: =COUNTIF(CQ40:CT40,"AB") -> 0 | CW40: =CU40+CV40 -> 0 | CX40: =CG40+CN40+CU40 -> 0 | CY40: =SUM(CE40,#REF!,CS40) -> #REF! | CZ40: =CY40/CX40*100 -> #REF!
H41: =COUNTIF(C41:G41,"PR") -> 0 | I41: =COUNTIF(C41:G41,"AB") -> 0 | J41: =H41+I41 -> 0 | O41: =COUNTIF(K41:N41,"PR") -> 0 | P41: =COUNTIF(K41:N41,"AB") -> 0 | Q41: =O41+P41 -> 0 | V41: =COUNTIF(R41:U41,"PR") -> 0 | W41: =COUNTIF(R41:U41,"AB") -> 0 | X41: =V41+W41 -> 0 | Y41: =J41+Q41+X41 -> 0 | Z41: =SUM(H41,O41,V41) -> 0 | AA41: =Z41/Y41*100 -> #DIV/0! | AG41: =COUNTIF(AC41:AF41,"PR") -> 0 | AH41: =COUNTIF(AC41:AF41,"AB") -> 0 | AI41: =AG41+AH41 -> 0 | AO41: =COUNTIF(AJ41:AN41,"PR") -> 0 | AP41: =COUNTIF(AJ41:AN41,"AB") -> 0 | AQ41: =AO41+AP41 -> 0 | AV41: =COUNTIF(AR41:AU41,"PR") -> 0 | AW41: =COUNTIF(AR41:AU41,"AB") -> 0 | AX41: =AV41+AW41 -> 0 | AY41: =AI41+AQ41+AX41 -> 0 | AZ41: =SUM(AG41,AO41,AV41) -> 0 | BA41: =AZ41/AY41*100 -> #DIV/0! | BF41: =COUNTIF(BB41:BE41,"PR") -> 0 | BG41: =COUNTIF(BB41:BE41,"AB") -> 0 | BH41: =BF41+BG41 -> 0 | BN41: =COUNTIF(BI41:BM41,"PR") -> 0 | BO41: =COUNTIF(BI41:BM41,"AB") -> 0 | BP41: =BN41+BO41 -> 0 | BU41: =COUNTIF(BQ41:BT41,"PR") -> 0 | BV41: =COUNTIF(BQ41:BT41,"AB") -> 0 | BW41: =BU41+BV41 -> 0 | BX41: =BH41+BP41+BW41 -> 0 | BY41: =SUM(BF41,BN41,BU41) -> 0 | BZ41: =BY41/BX41*100 -> #DIV/0! | CG41: =COUNTIF(CB41:CF41,"PR") -> 0 | CH41: =COUNTIF(CB41:CF41,"AB") -> 0 | CI41: =CG41+CH41 -> 0 | CN41: =COUNTIF(CJ41:CM41,"PR") -> 0 | CO41: =COUNTIF(CJ41:CM41,"AB") -> 0 | CP41: =CN41+CO41 -> 0 | CU41: =COUNTIF(CQ41:CT41,"PR") -> 0 | CV41: =COUNTIF(CQ41:CT41,"AB") -> 0 | CW41: =CU41+CV41 -> 0 | CX41: =CG41+CN41+CU41 -> 0 | CY41: =SUM(CE41,#REF!,CS41) -> #REF! | CZ41: =CY41/CX41*100 -> #REF!
...

Sheet REPORTING DATA
B2: JAN | C2: MEA% | D2: FEB | E2: MEA% | F2: MAR | G2: MEA% | H2: QEA | I2: QEA% | J2: APR | K2: MEA% | L2: MAY | M2: MEA% | N2: JUN | O2: MEA% | P2: QEA | Q2: QEA% | R2: JUL | S2: MEA% | T2: AUG | U2: MEA% | V2: SEP | W2: MEA% | X2: QEA | Y2: QEA% | Z2: OCT | AA2: MEA% | AB2: NOV | AC2: MEA% | AD2: DEC | AE2: MEA% | AF2: QEA | AG2: QEA% | AH2: YRLY | AI2: YEA%
A3: EA | B3: ='EMPOWERMENT GROUP'!H351 -> 0 | C3: =B4/B3*100 -> #DIV/0! | D3: ='EMPOWERMENT GROUP'!O351 -> 0 | E3: =D4/D3*100 -> #DIV/0! | F3: ='EMPOWERMENT GROUP'!V351 -> 0 | G3: =F4/F3*100 -> #REF! | H3: =B3+D3+F3 -> 0 | I3: =H4/H3*100 -> #REF! | J3: ='EMPOWERMENT GROUP'!AG351 -> 0 | K3: =J4/J3*100 -> #DIV/0! | L3: ='EMPOWERMENT GROUP'!AO351 -> 0 | M3: =L4/L3*100 -> #DIV/0! | N3: ='EMPOWERMENT GROUP'!AV351 -> 0 | O3: =N4/N3*100 -> #REF! | P3: =J3+L3+N3 -> 0 | Q3: =P4/P3*100 -> #REF! | R3: ='EMPOWERMENT GROUP'!BF351 -> 0 | S3: =R4/R3*100 -> #DIV/0! | T3: ='EMPOWERMENT GROUP'!BN351 -> 0 | U3: =T4/T3*100 -> #DIV/0! | V3: ='EMPOWERMENT GROUP'!BU351 -> 0 | W3: =V4/V3*100 -> #DIV/0! | X3: =R3+T3+V3 -> 0 | Y3: =X4/X3*100 -> #DIV/0! | Z3: ='EMPOWERMENT GROUP'!CG351 -> 0 | AA3: =Z4/Z3*100 -> #DIV/0! | AB3: ='EMPOWERMENT GROUP'!CN351 -> 0 | AC3: =AB4/AB3*100 -> #REF! | AD3: ='EMPOWERMENT GROUP'!CU351 -> 0 | AE3: =AD4/AD3*100 -> #DIV/0! | AF3: =Z3+AB3+AD3 -> 0 | AG3: =AF4/AF3*100 -> #REF! | AH3: =B3+D3+F3+J3+L3+N3+R3+T3+V3+Z3+AB3+AD3 -> 0 | AI3: =AH4/AH3*100 -> #REF!
A4: AA | B4: ='EMPOWERMENT GROUP'!C352 -> 0 | D4: ='EMPOWERMENT GROUP'!K352 -> 0 | F4: ='EMPOWERMENT GROUP'!R352 -> #REF! | H4: =B4+D4+F4 -> #REF! | J4: ='EMPOWERMENT GROUP'!AC352 -> 0 | L4: ='EMPOWERMENT GROUP'!AJ352 -> 0 | N4: ='EMPOWERMENT GROUP'!AR352 -> #REF! | P4: =J4+L4+N4 -> #REF! | R4: ='EMPOWERMENT GROUP'!BB352 -> 0 | T4: ='EMPOWERMENT GROUP'!BI352 -> 0 | V4: ='EMPOWERMENT GROUP'!BQ352 -> 0 | X4: =R4+T4+V4 -> 0 | Z4: ='EMPOWERMENT GROUP'!CB352 -> 0 | AB4: ='EMPOWERMENT GROUP'!CJ352 -> #REF! | AD4: ='EMPOWERMENT GROUP'!CQ352 -> 0 | AF4: =Z4+AB4+AD4 -> #REF! | AH4: =B4+D4+F4+J4+L4+N4+R4+T4+V4+Z4+AB4+AD4 -> #REF!
A5: EA | B5: ='EMPOWERMENT GROUP'!J13 -> 0 | C5: =B6/B5*100 -> #DIV/0! | D5: ='EMPOWERMENT GROUP'!Q13 -> 0 | E5: =D6/D5*100 -> #DIV/0! | F5: ='EMPOWERMENT GROUP'!X13 -> 0 | G5: =F6/F5*100 -> #DIV/0! | H5: =B5+D5+F5 -> 0 | I5: =H6/H5*100 -> #DIV/0! | J5: ='EMPOWERMENT GROUP'!AI13 -> 0 | K5: =J6/J5*100 -> #DIV/0! | L5: ='EMPOWERMENT GROUP'!AQ13 -> 0 | M5: =L6/L5*100 -> #DIV/0! | N5: ='EMPOWERMENT GROUP'!AX13 -> 0 | O5: =N6/N5*100 -> #DIV/0! | P5: =J5+L5+N5 -> 0 | Q5: =P6/P5*100 -> #DIV/0! | R5: ='EMPOWERMENT GROUP'!BH13 -> 0 | S5: =R6/R5*100 -> #DIV/0! | T5: ='EMPOWERMENT GROUP'!BP13 -> 0 | U5: =T6/T5*100 -> #DIV/0! | V5: ='EMPOWERMENT GROUP'!BW13 -> 0 | W5: =V6/V5*100 -> #DIV/0! | X5: =R5+T5+V5 -> 0 | Y5: =X6/X5*100 -> #DIV/0! | Z5: ='EMPOWERMENT GROUP'!CI13 -> 0 | AA5: =Z6/Z5*100 -> #DIV/0! | AB5: ='EMPOWERMENT GROUP'!CP13 -> 0 | AC5: =AB6/AB5*100 -> #DIV/0! | AD5: ='EMPOWERMENT GROUP'!CW13 -> 0 | AE5: =AD6/AD5*100 -> #DIV/0! | AF5: =Z5+AB5+AD5 -> 0 | AG5: =AF6/AF5*100 -> #DIV/0! | AH5: =B5+D5+F5+J5+L5+N5+R5+T5+V5+Z5+AB5+AD5 -> 0 | AI5: =AH6/AH5*100 -> #DIV/0!
A6: LEADERS | B6: ='EMPOWERMENT GROUP'!H13 -> 0 | D6: ='EMPOWERMENT GROUP'!O13 -> 0 | F6: ='EMPOWERMENT GROUP'!V13 -> 0 | H6: =B6+D6+F6 -> 0 | J6: ='EMPOWERMENT GROUP'!AG13 -> 0 | L6: ='EMPOWERMENT GROUP'!AO13 -> 0 | N6: ='EMPOWERMENT GROUP'!AO13 -> 0 | P6: =J6+L6+N6 -> 0 | R6: ='EMPOWERMENT GROUP'!BF13 -> 0 | T6: ='EMPOWERMENT GROUP'!BN13 -> 0 | V6: ='EMPOWERMENT GROUP'!BU13 -> 0 | X6: =R6+T6+V6 -> 0 | Z6: ='EMPOWERMENT GROUP'!CG13 -> 0 | AB6: ='EMPOWERMENT GROUP'!CN13 -> 0 | AD6: ='EMPOWERMENT GROUP'!CU13 -> 0 | AF6: =Z6+AB6+AD6 -> 0 | AH6: =B6+D6+F6+J6+L6+N6+R6+T6+V6+Z6+AB6+AD6 -> 0
A7: EA | B7: ='EMPOWERMENT GROUP'!J20 -> 0 | C7: =B8/B7*100 -> #DIV/0! | D7: ='EMPOWERMENT GROUP'!Q20 -> 0 | E7: =D8/D7*100 -> #DIV/0! | F7: ='EMPOWERMENT GROUP'!X20 -> 0 | G7: =F8/F7*100 -> #DIV/0! | H7: =B7+D7+F7 -> 0 | I7: =H8/H7*100 -> #DIV/0! | J7: ='EMPOWERMENT GROUP'!AI20 -> 0 | K7: =J8/J7*100 -> #DIV/0! | L7: ='EMPOWERMENT GROUP'!AQ20 -> 0 | M7: =L8/L7*100 -> #DIV/0! | N7: ='EMPOWERMENT GROUP'!AX20 -> 0 | O7: =N8/N7*100 -> #DIV/0! | P7: =J7+L7+N7 -> 0 | Q7: =P8/P7*100 -> #DIV/0! | R7: ='EMPOWERMENT GROUP'!BH20 -> 0 | S7: =R8/R7*100 -> #DIV/0! | T7: ='EMPOWERMENT GROUP'!BP20 -> 0 | U7: =T8/T7*100 -> #DIV/0! | V7: ='EMPOWERMENT GROUP'!BW20 -> 0 | W7: =V8/V7*100 -> #DIV/0! | X7: =R7+T7+V7 -> 0 | Y7: =X8/X7*100 -> #DIV/0! | Z7: ='EMPOWERMENT GROUP'!CI20 -> 0 | AA7: =Z8/Z7*100 -> #DIV/0! | AB7: ='EMPOWERMENT GROUP'!CP20 -> 0 | AC7: =AB8/AB7*100 -> #DIV/0! | AD7: ='EMPOWERMENT GROUP'!CP20 -> 0 | AE7: =AD8/AD7*100 -> #DIV/0! | AF7: =Z7+AB7+AD7 -> 0 | AG7: =AF8/AF7*100 -> #DIV/0! | AH7: =B7+D7+F7+J7+L7+N7+R7+T7+V7+Z7+AB7+AD7 -> 0 | AI7: =AH8/AH7*100 -> #DIV/0!
A8: INTENSE | B8: ='EMPOWERMENT GROUP'!H20 -> 0 | D8: ='EMPOWERMENT GROUP'!O20 -> 0 | F8: ='EMPOWERMENT GROUP'!V20 -> 0 | H8: =B8+D8+F8 -> 0 | J8: ='EMPOWERMENT GROUP'!AG20 -> 0 | L8: ='EMPOWERMENT GROUP'!AO20 -> 0 | N8: ='EMPOWERMENT GROUP'!AV20 -> 0 | P8: =J8+L8+N8 -> 0 | R8: ='EMPOWERMENT GROUP'!BF20 -> 0 | T8: ='EMPOWERMENT GROUP'!BN20 -> 0 | V8: ='EMPOWERMENT GROUP'!BU20 -> 0 | X8: =R8+T8+V8 -> 0 | Z8: ='EMPOWERMENT GROUP'!CG20 -> 0 | AB8: ='EMPOWERMENT GROUP'!CN20 -> 0 | AD8: ='EMPOWERMENT GROUP'!CU20 -> 0 | AF8: =Z8+AB8+AD8 -> 0 | AH8: =B8+D8+F8+J8+L8+N8+R8+T8+V8+Z8+AB8+AD8 -> 0
A9: EA | B9: ='EMPOWERMENT GROUP'!J35 -> 0 | C9: =B10/B9*100 -> #DIV/0! | D9: ='EMPOWERMENT GROUP'!Q35 -> 0 | E9: =D10/D9*100 -> #DIV/0! | F9: ='EMPOWERMENT GROUP'!X35 -> 0 | G9: =F10/F9*100 -> #DIV/0! | H9: =B9+D9+F9 -> 0 | I9: =H10/H9*100 -> #DIV/0! | J9: ='EMPOWERMENT GROUP'!AI35 -> 0 | K9: =J10/J9*100 -> #DIV/0! | L9: ='EMPOWERMENT GROUP'!AQ35 -> 0 | M9: =L10/L9*100 -> #DIV/0! | N9: ='EMPOWERMENT GROUP'!AX35 -> 0 | O9: =N10/N9*100 -> #DIV/0! | P9: =J9+L9+N9 -> 0 | Q9: =P10/P9*100 -> #DIV/0! | R9: ='EMPOWERMENT GROUP'!BH35 -> 0 | S9: =R10/R9*100 -> #DIV/0! | T9: ='EMPOWERMENT GROUP'!BP35 -> 0 | U9: =T10/T9*100 -> #DIV/0! | V9: ='EMPOWERMENT GROUP'!BW35 -> 0 | W9: =V10/V9*100 -> #DIV/0! | X9: =R9+T9+V9 -> 0 | Y9: =X10/X9*100 -> #DIV/0! | Z9: ='EMPOWERMENT GROUP'!CI35 -> 0 | AA9: =Z10/Z9*100 -> #DIV/0! | AB9: ='EMPOWERMENT GROUP'!CP35 -> 0 | AC9: =AB10/AB9*100 -> #DIV/0! | AD9: ='EMPOWERMENT GROUP'!CW35 -> 0 | AE9: =AD10/AD9*100 -> #DIV/0! | AF9: =Z9+AB9+AD9 -> 0 | AG9: =AF10/AF9*100 -> #DIV/0! | AH9: =B9+D9+F9+J9+L9+N9+R9+T9+V9+Z9+AB9+AD9 -> 0 | AI9: =AH10/AH9*100 -> #DIV/0!
A10: CONSISTENT | B10: ='EMPOWERMENT GROUP'!H35 -> 0 | D10: ='EMPOWERMENT GROUP'!O35 -> 0 | F10: ='EMPOWERMENT GROUP'!V35 -> 0 | H10: =B10+D10+F10 -> 0 | J10: ='EMPOWERMENT GROUP'!AG35 -> 0 | L10: ='EMPOWERMENT GROUP'!AO35 -> 0 | N10: ='EMPOWERMENT GROUP'!AV35 -> 0 | P10: =J10+L10+N10 -> 0 | R10: ='EMPOWERMENT GROUP'!BF35 -> 0 | T10: ='EMPOWERMENT GROUP'!BN35 -> 0 | V10: ='EMPOWERMENT GROUP'!BU35 -> 0 | X10: =R10+T10+V10 -> 0 | Z10: ='EMPOWERMENT GROUP'!CG35 -> 0 | AB10: ='EMPOWERMENT GROUP'!CN35 -> 0 | AD10: ='EMPOWERMENT GROUP'!CU35 -> 0 | AF10: =Z10+AB10+AD10 -> 0 | AH10: =B10+D10+F10+J10+L10+N10+R10+T10+V10+Z10+AB10+AD10 -> 0
A11: EA | B11: ='EMPOWERMENT GROUP'!J137 -> 0 | C11: =B12/B11*100 -> #DIV/0! | D11: ='EMPOWERMENT GROUP'!Q137 -> 0 | E11: =D12/D11*100 -> #DIV/0! | F11: ='EMPOWERMENT GROUP'!X137 -> 0 | G11: =F12/F11*100 -> #DIV/0! | H11: =B11+D11+F11 -> 0 | I11: =H12/H11*100 -> #DIV/0! | J11: ='EMPOWERMENT GROUP'!AI137 -> 0 | K11: =J12/J11*100 -> #DIV/0! | L11: ='EMPOWERMENT GROUP'!AQ137 -> 0 | M11: =L12/L11*100 -> #DIV/0! | N11: ='EMPOWERMENT GROUP'!AX137 -> 0 | O11: =N12/N11*100 -> #DIV/0! | P11: =J11+L11+N11 -> 0 | Q11: =P12/P11*100 -> #DIV/0! | R11: ='EMPOWERMENT GROUP'!BH137 -> 0 | S11: =R12/R11*100 -> #DIV/0! | T11: ='EMPOWERMENT GROUP'!BP137 -> 0 | U11: =T12/T11*100 -> #DIV/0! | V11: ='EMPOWERMENT GROUP'!BW137 -> 0 | W11: =V12/V11*100 -> #DIV/0! | X11: =R11+T11+V11 -> 0 | Y11: =X12/X11*100 -> #DIV/0! | Z11: ='EMPOWERMENT GROUP'!CI137 -> 0 | AA11: =Z12/Z11*100 -> #DIV/0! | AB11: ='EMPOWERMENT GROUP'!CP137 -> 0 | AC11: =AB12/AB11*100 -> #DIV/0! | AD11: ='EMPOWERMENT GROUP'!CW137 -> 0 | AE11: =AD12/AD11*100 -> #DIV/0! | AF11: =Z11+AB11+AD11 -> 0 | AG11: =AF12/AF11*100 -> #DIV/0! | AH11: =B11+D11+F11+J11+L11+N11+R11+T11+V11+Z11+AB11+AD11 -> 0 | AI11: =AH12/AH11*100 -> #DIV/0!
